Workbook
Name ActionStatus: [1]Settings!$A$2:$A$3
Name Author: 'Cover sheet'!$D$10
Name Author_Dept: 'Cover sheet'!$D$11
Name Date: 'Cover sheet'!$D$12
Name Document_Name: 'Cover sheet'!$D$4
Name Excel_BuiltIn_Print_Area_1_1: #REF!
Name Excel_BuiltIn_Print_Area_1_1: #REF!
Name Excel_BuiltIn_Print_Area_1_1: #REF!
Name Excel_builtin_print_area_1_2: #REF!
Name Excel_builtin_print_area_1_2: #REF!
Name ProductFailureRate: 'Block Failure Rate'!#REF!
Name ProductFailureRate: 'Block Failure Rate'!#REF!
Name Project_Name: 'Cover sheet'!$D$9
Name ReviewStatus: [1]Settings!$C$2:$C$4
Name SMX: Table3['#]
Name SMX: Table3['#]
Name SMX: Table3['#]
Name SMY: Table3['#]
Name SMY: Table3['#]
Name Status: 'Cover sheet'!$D$8
Name Status: #REF!
Name Status: #REF!
Name Status: #REF!
Name Status1: #REF!
Name Status1: #REF!
Name Status1: #REF!
Name Tlifetime: Metrics_summary!$C$10

Sheet Cover sheet
B1: FS6500_FS1b_Dynamic_FMEDA
B3: Document references:
B4: Document Name | D4: FS6500_FS1b_Dynamic_FMEDA
B5: Part Numbers covered | D5: All part numbers listed in MC33FS6500-MC33FS4500 datasheet
B6: Silicon Version | D6: N84R
B7: Document Version | D7: V1.3
B8: Status | D8: Reviewed
B9: Project Name | D9: FS6500
B10: Author / UID | D10: Maxime CLAIRET
B11: Author’s dept | D11: Advance Analog Automotive
B12: Date (mm/dd/yyyy) | D12: 42982
B14: Reviewer / Approver List:
C15: Name | D15: User ID | E15: Function | F15: Approval date (mm/dd/yyyy)
B17: Reviewer 1 | C17: Philippe Mounier | D17: TTT534 | E17: System Architecte | F17: 42614
B18: Reviewer 2 | C18: Pierre Turpin | D18: R23671 | E18: Design Leader | F18: 42608
B19: Reviewer 3 | C19: Jean-Philippe Meunier | D19: R49478 | E19: System Architecte | F19: 42614
B20: Reviewer 4 | C20: Valerie Bernon | D20: R40959 | E20: Functional Safety Manager | F20: 42608
B21: Approver 1 | C21: Franck Guillen | D21: R38682 | E21: Project Manager | F21: 42614
B23: NXP CONFIDENTIAL PROPRIETARY
B24: All Rights Reserved. Presence of copyright notice is not an acknowledgement of publication.

Sheet Change History
B2: Change History
B3: Version | C3: Date | D3: Author | E3: Changes description
B4: 0.1 | C4: 42280 | D4: Maxime CLAIRET | E4: - Initial version
B5: 0.2 | C5: 42311 | D5: Maxime CLAIRET | E5: - Add FMEDA_PWRUP - All block die size increased by +5% to take into account new pad ring
B6: 0.3 | C6: 03/27/2015 | D6: Maxime CLAIRET | E6: - Update to 53 FIT with RTH(ja)=30°C/W - Reintroduce IO_4/5 External IC error monitoring - Add Metrics summary sheet - Correct PMHF formula
B7: 0.4 | C7: 42190 | D7: Maxime CLAIRET | E7: - Update/Correction following first review meeting
B8: 0.5 | C8: 42041 | D8: Maxime CLAIRET | E8: - Correction of PMHF calculation
B9: 0.6 | C9: 42069 | D9: Maxime CLAIRET | E9: - Correct "." decimal issue in block failure rate sheet - Align traceability to Safety Concept - Align FIT rate number to Failure rate evaluation report
B10: 0.7 | C10: 42499 | D10: Maxime CLAIRET | E10: - Update with Safety Manual tag traceability
B11: 1.0 | C11: 42608 | D11: Maxime CLAIRET | E11: - Verification review
B12: 1.1 | C12: 42639 | D12: Maxime CLAIRET | E12: - Update traceability vs Safety Context and Concept following ISO26262 assessment
B13: 1.2 | C13: 42676 | D13: Maxime CLAIRET | E13: - Add easy FS1b selection in "Safety Mechanisms"sheet
B14: 1.3 | C14: 42982 | D14: Maxime CLAIRET | E14: - Update FS1b selection in "Safety Mechanisms"sheet - Add IO_45 External IC Error monitoring selection in "Safety Mechanisms"sheet
B18: Related Documents
B19: N° | D19: Revision | E19: Title
B20: U1 | D20: 1.3 | E20: 1 - Safety Context (DOORS)
B21: U2 | D21: 1.3 | E21: 2 - Safety Concept (DOORS)
B22: U3 | D22: 2.0 | E22: doc_FS6500_Failure_Rate_Evaluation

Sheet User guide
B3: The Dynamic FMEDA consists of a single xlsx file having several sheets and it provides the Failure Mode Effect and Diagnostics Analysis (FMEDA) with the ISO26262 Metrics calculation.
B4: This particular User Guide sheet describes the definition of each spreadsheet located in this document.
B5: The Dynamic FMEDA is an example of the result of the safety analysis performed for the context of use of the PowerSBCLIN using the mission profile described below and when applying all recommendations and assumptions mentioned in the associated safety manual.
B9: Mission profile
B26: Block Failure Rate
B28: The table defines the list of the Function Block partitioning of the FS65_FS45 product family.
B29: For each Function Block the failure rate is calculated.
B30: The Block reference for each function block is extracted from the device internal block diagram (refer to the left figure below)
B31: A generic application example is also provided to ease the understanding (refer to teh right figure below)
B32: The total failure rate of the die is calculated with the IEC62380 TR Standard Model (refer to Failure Rate Evaluation document) and distributed per function based on their representative die size
B34: Block | C34: Function | D34: % | E34: Quality failure rate | F34: Block Failure Rate | G34: Total Function Failure Rate
A35: Eg: | B35: Vcore Analog Reference #1 Charge Pump Power Management state machine | C35: Vcore | D35: ='Block Failure Rate'!D4 -> 0.16701097 | E35: 1.86 | F35: 1.86 | G35: ='Block Failure Rate'!E4 -> 8.9517883
B37: Internal Block Diagram | H37: Generic Application Example | M37: FS65 pin out
B88: Safety Functions
B90: The table defines the list of the Safety Functions which are indicated in the FMEDA and can violate a safety goal in case of failure.
B91: The Safety Function is described and illustrated with an example when the safety goal associated is violated.
B92: The Safety Goals are defined in the Safety Concept.
B94: Safety Concept Requirement | C94: Mode | D94: Technical ssumption considered as violating the safety goal | G94: Example | H94: Safety Mechanism | I94: SPF/LF
A95: Eg: | B95: ='Safety Functions'!A4 -> FS6500_SAF37 | C95: ='Safety Functions'!C4 -> Operation mode | D95: ='Safety Functions'!D4 -> The failure modes considered for a voltage regulator (linear or DCDC converter) is the “over-voltage” and the “under-voltage” | G95: ='Safety Functions'!E4 -> An over voltage at Vcore Pin not detected could involved a MCU damage leading abnormal behavior leading the violation of system safety goals | H95: ='Safety Functions'!F4 -> SM1, SM2, SM3 | I95: ='Safety Functions'!G4 -> SPF
B100: Safety Mechanisms
B102: The table defines the list of the Safety Mechanism which are implemented and available for the diagnostic of the failure modes.
B103: The SMx are Safety Mechanism at device level while SMAx are Safety Mechanism at application level.
B104: The Safety Mechanism available is described, referenced to ISO26262 Part5 AnnexD.
B105: According to the ISO26262 Part5 AnnexD the level of Diagnostic Coverage is reported (High, Medium, Low) as well as the percentage of Diagnostic Coverage.
B107: # | C107: Safety mechanism | D107: § ISO 26262 | E107: Level of Diagnostic coverage | F107: Used? | G107: Level of Diagnostic coverage | H107: Used? | I107: DC (%)
A108: Eg: | B108: ='Safety Mechanisms'!A3 -> SM1 | C108: ='Safety Mechanisms'!B3 -> Voltage supervisor (Monitoring of voltage) Overvoltage detection | D108: ='Safety Mechanisms'!C3 -> D.2.8.2 | E108: High | F108: Yes | G108: ='Safety Mechanisms'!D3 -> High | H108: ='Safety Mechanisms'!E3 -> Yes | I108: ='Safety Mechanisms'!F3 -> 0.99
B112: Extract from Part5 Annex D:
B122: FMEDA
B124: The method to perform the FMEDA is the one described in the ISO26262 Part5 Annex F.
B126: The product propose 3 modes of operation:
B127: POWER UP
B128: OPERATION
B129: LPOFF (equivalent to a sleep mode)
B130: See below for the Simplified state diagram extracted from the Datasheet.
B132: In POWER UP and LPOFF modes, the product is in Safe State by default. Most of the Failures have no direct impact. Since all the power supplies are OFF in LPOFF, this mode is not analyzed.
B134: Refer to FMEDA_OP sheet for the OPERATION mode and FMEDA_PWRUP for power up mode.
B136: Simplified State Diagram from Datasheet
B184: FMEDA additional comments
... B204: - Reactivation (or Stuck-at) of the Debug mode function (The watchdog is inhibited, DeepFailSafe state not available) => It is a Latent fault, it will be detected at the next startup thru LBIST/ABIST sequences

Sheet Simplified Functional Block
C4: Simplified Functional Blocks
C6: 1.1 Main high level functions
C7: · Switching Mode Power Supply (SMPS) dedicated to MCU core supply from 1.2V to 5V range selectable thru external resistor bridge. (Vcore Regulation)
C9: · Vcore external resistor bridge monitoring thru FCRBM (FB_Core monitoring)
C11: · Flexible SMPS pre-regulator allowing Non-inverting Buck-Boost or Standard Buck Configuration. Overall device efficiency improvement. (Buck/Boost selection) | S11: The FIT of external resistors is not taken into account in the FMEDA.
C13: · 5V / 3.3V Linear voltage regulator dedicated to MCU I/Os supply with external PNP transistor detection. (VCCA Regulation; Hw Config Selection, Hw config VCCA pnp detect)
C15: · 5V / 3.3V Linear voltage regulator dedicated to auxiliary functions or sensor supply (5V tracking Vcca). (Vaux Regulation, Hw Config Selection)
C17: · Enhanced Main state Machine for Power Management featuring. (Power Management State machine)
C19: · Multiple IOs interface for FCCU MCU monitoring, Vcore resistor bridge monitoring and wake-up. (IOs interface, I/Os - MCU error monitoring, I/Os - Wake-up, FCRBM)
C21: · Dedicated Voltage Supervisor for Vcore, VCCA, VAUX, CAN 5V, dedicated Internal Analog References and Internal Logic supplies. (Voltage Supervisor (UV and/or OV))
C23: · Enhanced Safety block with dedicated watchdog, SPI and Fail Safe outputs. (Fail Safe machine, SPI, Watchdog, Fail Safe Outputs Drivers)
C25: · Configurable digital I/Os used for cross-checking or MCU interface thru SPI registers. (I/Os Interfaces)
C27: · MUX output terminal for device internal analog signal monitoring and power supply monitoring. (AMUX)
C29: · ISO11898 high speed CAN FD interface compatibility for baud rates of 40kb/s to 2Mb/s. (CAN Phy & CAN_5V)
C31: · LIN Interface (LIN Phy)
C33: · Debug hardware mode featuring. ( Debug)
B37: Vcore Regulation Example
B70: Fonctional Block | C70: Embedded Blocks | D70: Die Size | E70: % | F70: Block Failure Rate
B71: Vcore Regulation | C71: Analog Reference #1, Charge Pump Power Management state machine | D71: . | E71: ='Block Failure Rate'!D4 -> 0.16701097 | F71: ='Block Failure Rate'!E4 -> 8.9517883
B73: # | C73: Safety Requirements/Goal
B74: SR0001 | C74: The FS6500 shall supply the MCU within the specified range ( Safety Context/SRS document)
B76: # | C76: Safety Mechanism | D76: § ISO 26262 | E76: Level of Diagnostic coverage | F76: DC (%)
B77: SM1 | C77: Voltage supervisor (Monitoring of voltage) Overvoltage detection | D77: D.2.8.2 | E77: High | F77: 0.99 | H77: All Failure mechanisms create an UnderVoltage or Over Voltage detected by the Voltage Supervisor and then enable the SM#1 or SM#2 safety mechanism.
B78: SM2 | C78: Voltage supervisor (Monitoring of voltage) Under voltage detection | D78: D.2.8.2 | E78: High | F78: 0.99
B80: # | C80: Failure Mechanism | D80: Safety mechanism
B81: FM1 | C81: Overvoltage | D81: SM1
B82: FM2 | C82: Under voltage | D82: SM2
B83: FM3 | C83: Drift on external resistor bridge | D83: SM3
B84: FM4 | C84: Voltage oscillation | D84: SM1&SM2
B85: FM5 | C85: Power spikes | D85: SM1&SM2
B86: FM6 | C86: Drift | D86: SM1&SM2
B87: FM7 | C87: FB_core pin shorted to Gnd | D87: SM2
B88: FM8 | C88: FB_core pin shorted to High | D88: SM1
B89: FM9 | C89: FB_core pin open | D89: SM2
B90: FM10 | C90: FB_core pin shorted to adjacent pin "comp_core" | D90: SM3
B91: FM11 | C91: FB_core pin shorted to adjacent pin "HW_select" | D91: SM3
... B95: FM218 | C95: 5 other Pins linked to Vcore regulation block shorted to adjacent | D95: SM1&SM2

Sheet Block Failure Rate
A1: Failure Rate from [U3]
A3: Function | B3: Block | C3: Die Size | D3: % | E3: Function failure rate | F3: Failure mode classification and justification
A4: Vcore | B4: Vcore regulation SMPS Analog Reference #1, Charge Pump Power Management state machine (including Test Mode) | C4: 2.587 | D4: =Table1[[#This Row],[Die Size]]/Table1[[#Totals],[Die Size]] -> 0.16701097 | E4: =Table1[[#Totals],[Function failure rate]]*Table1[[#This Row],[%]] -> 8.9517883 | F4: Single point Fault Direct violation of the safety goal.
A5: Vpre | B5: Vpre regulation SMPS Analog Reference #1, Charge Pump Power Management state machine | C5: 3.622 | D5: =Table1[[#This Row],[Die Size]]/Table1[[#Totals],[Die Size]] -> 0.23382828 | E5: =Table1[[#Totals],[Function failure rate]]*Table1[[#This Row],[%]] -> 12.533196 | F5: Single point Fault Direct violation of the safety goal.
A6: Vcca | B6: Vcca regulation linear Power Management State Machine Analog reference #1 | C6: 0.69 | D6: =Table1[[#This Row],[Die Size]]/Table1[[#Totals],[Die Size]] -> 0.044544868 | E6: =Table1[[#Totals],[Function failure rate]]*Table1[[#This Row],[%]] -> 2.3876049 | F6: Single point Fault Direct violation of the safety goal.
A7: Vaux | B7: Vaux regulation linear Power Management state machine Analog Reference #1 | C7: 0.69 | D7: =Table1[[#This Row],[Die Size]]/Table1[[#Totals],[Die Size]] -> 0.044544868 | E7: =Table1[[#Totals],[Function failure rate]]*Table1[[#This Row],[%]] -> 2.3876049 | F7: Single point Fault Direct violation of the safety goal.
A8: Voltage supervisor and FS bias | B8: Voltage supervisor, FS bias Analog Reference 2, Fail Safe State Machine | C8: 0.978 | D8: =Table1[[#This Row],[Die Size]]/Table1[[#Totals],[Die Size]] -> 0.063137508 | E8: =Table1[[#Totals],[Function failure rate]]*Table1[[#This Row],[%]] -> 3.3841704 | F8: Latent Fault Part of the safety mechanism and can't involved violation of the safety goal as a single point fault.
A9: Hardware configuration - Select | B9: Hardware configuration - Select Power Management State Machine, Fail Safe State Machine | C9: 0.081 | D9: =Table1[[#This Row],[Die Size]]/Table1[[#Totals],[Die Size]] -> 0.0052291801 | E9: =Table1[[#Totals],[Function failure rate]]*Table1[[#This Row],[%]] -> 0.28028405 | F9: Single point Fault Direct violation of the safety goal.
A10: Hardware configuration - buck/boost | B10: Hardware configuration - buck/boost Power Management State Machine | C10: 0.021 | D10: =Table1[[#This Row],[Die Size]]/Table1[[#Totals],[Die Size]] -> 0.0013557134 | E10: =Table1[[#Totals],[Function failure rate]]*Table1[[#This Row],[%]] -> 0.072666236 | F10: Single point Fault 1 failure mode can have a direct violation of the safety goal. Latent Fault 5 failure modes are Part of the safety mechanism and can't involved violation of the safety goal as a single point fault.
A11: Hardware configuration - Vcca_PNP detection | B11: Hardware configuration - Vcca_PNP detection Power Management State Machine | C11: 0.041 | D11: =Table1[[#This Row],[Die Size]]/Table1[[#Totals],[Die Size]] -> 0.0026468689 | E11: =Table1[[#Totals],[Function failure rate]]*Table1[[#This Row],[%]] -> 0.14187218 | F11: Single point Fault Direct violation of the safety goal.
A12: Fail Safe outputs - RSTb | B12: Fail Safe outputs - RSTb Fail Safe State Machine | C12: 0.367 | D12: =Table1[[#This Row],[Die Size]]/Table1[[#Totals],[Die Size]] -> 0.023692705 | E12: =Table1[[#Totals],[Function failure rate]]*Table1[[#This Row],[%]] -> 1.269929 | F12: Latent Fault Part of the safety mechanism and can't involved violation of the safety goal as a single point fault.
A13: Fail Safe outputs - FS0b | B13: Fail Safe outputs - FS0b Fail Safe State Machine | C13: 0.367 | D13: =Table1[[#This Row],[Die Size]]/Table1[[#Totals],[Die Size]] -> 0.023692705 | E13: =Table1[[#Totals],[Function failure rate]]*Table1[[#This Row],[%]] -> 1.269929 | F13: Latent Fault Part of the safety mechanism and can't involved violation of the safety goal as a single point fault.
A14: Fail Safe outputs - FS1b | B14: Fail Safe outputs - FS1b VPU_FS circuit Fail Safe State Machine | C14: 0.387 | D14: =Table1[[#This Row],[Die Size]]/Table1[[#Totals],[Die Size]] -> 0.024983861 | E14: =Table1[[#Totals],[Function failure rate]]*Table1[[#This Row],[%]] -> 1.3391349 | F14: Latent Fault Part of the safety mechanism and can't involved violation of the safety goal as a single point fault.
A15: Long Duration Timer - LDT | B15: Power Management State Machine | C15: 0.11 | D15: =Table1[[#This Row],[Die Size]]/Table1[[#Totals],[Die Size]] -> 0.0071013557 | E15: =Table1[[#Totals],[Function failure rate]]*Table1[[#This Row],[%]] -> 0.38063267 | F15: Not safety related. Long Duration Timer does not impact the service functions, All other safety mechanism and reactions remain functional.
... A27: Debug | B27: Debug | C27: 0.062 | D27: =Table1[[#This Row],[Die Size]]/Table1[[#Totals],[Die Size]] -> 0.0040025823 | E27: =Table1[[#Totals],[Function failure rate]]*Table1[[#This Row],[%]] -> 0.21453841 | F27: Latent Fault Debug mode activation does not impact the service functions. WD monitoring and Deep Fail Safe are disable. All other safety mechanism and reactions remain functional.
A28: Test Mode for Power Management State Machine | B28: Power Management State Machine | C28: - | D28: - | E28: - | F28: Latent Fault Fit included in PowerManagement State Machine repartition
A29: Test Mode for Fail Safe State Machine | B29: Fail Safe State Machine | C29: - | D29: - | E29: - | F29: Latent Fault Fit included in Fail Safe State Machine repartition
A30: Fuse 1 | B30: Power Management State Machine | C30: - | D30: - | E30: - | F30: Single Point fault Fit included in Power Management State Machine repartition
A31: Fuse 2 | B31: Fail Safe State Machine (Clock) Voltage supervisor (Bandgap) | C31: - | D31: - | E31: - | F31: Latent Fault Fit included in Fail Safe State Machine repartition
A32: EDC for Power Management State Machine | B32: Power Management State Machine | C32: - | D32: - | E32: - | F32: Single Point fault Fit included in Power Management State Machine repartition
A33: EDC for Fail Safe State Machine | B33: Fail Safe State Machine | C33: - | D33: - | E33: - | F33: Latent Fault Fit included in Fail Safe State Machine repartition
A34: Total | C34: =SUBTOTAL(109,Table1[Die Size]) -> 15.49 | D34: =SUBTOTAL(109,Table1[%]) -> 1 | E34: =E36 -> 53.6
E36: 53.6

Sheet System Assumptions
A1: System Assumptions from [U1]
A3: System Assumptions | B3: Assumptions | C3: Safety Manual Tag
A4: FS6500_SCX_117 | B4: The FS65_FS45 devices are used in application for which the “driving cycle” (i.e. the time of operation without a Power On Reset of the Fail Safe Machine) is 12 hours | C4: SMR_04
A5: FS6500_SCX_124 | B5: Simultaneous pin disconnections (i.e. pin lift on the PCB) are restricted to 1. | C5: SMR_12
A6: FS6500_SCX_155 | B6: Short-circuit between PCB track is NOT considered | C6: SMR_14
A7: FS6500_SCX_156 | B7: External component disconnection is NOT considered | C7: SMR_15

Sheet Safety Functions
A1: Safety Functions from [U2]
A3: Safety Concept Requirement | B3: Safety Goal | C3: Mode | D3: Technical assumption considered as violating the safety goal | E3: Example | F3: Safety Mechanism | G3: SPF/LF | H3: Safety Manual Tag
A4: FS6500_SAF37 | B4: SC0006 | C4: Operation mode | D4: The failure modes considered for a voltage regulator (linear or DCDC converter) is the “over-voltage” and the “under-voltage” | E4: An over voltage at Vcore Pin not detected could involved a MCU damage leading abnormal behavior leading the violation of system safety goals | F4: SM1, SM2, SM3 | G4: SPF | H4: TSR_02, TSR_03, TSR_04
A5: FS6500_SAF90 | B5: SC0015 | C5: Operation mode | D5: The failure mode considered for the windowed watchdog is the impossibility to detect the MCU malfunction in the Fault Tolerant Time Interval | E5: A time out issue could lead to the violation of system safety goals | F5: SM4 | G5: LF | H5: TSR_05, TSR_06, TSR_07
A6: FS6500_SAF110 | B6: SC0019 | C6: Operation mode | D6: The failure mode to be considered for the MCU error output monitoring is the impossibility to detect MCU malfunction | E6: A FCCU fault not detected could lead to the violation of system safety goals | F6: SM6 | G6: LF | H6: TSR_08, TSR_09
A7: FS6500_SAF131 | B7: SC0038 | C7: Operation mode | D7: The failure mode to be considered for the Fail Safe outputs pins (FS0b and FS1b) is the “stuck-at” | E7: Fail safe output stucked as high level (active low) could lead to the violation of the system safety goals | F7: SM5, SMA2, SMA3 | G7: LF | H7: TSR_12
A8: FS6500_SAF139 | B8: SC0104 | C8: Operation mode | D8: The failure mode to be considered for the FS1b pins is the impossibility to guarantee and achieved the delay between the two Fail Safe outputs (FS0b and FS1b) | E8: FS1b activated before FS0b could lead to the violation of the system safety goals (when FS1b configured in tdelay mode) | F8: SM9 | G8: LF | H8: TSR_12
A9: FS6500_SAF184 | B9: SC0108 | C9: Operation mode | D9: The failure mode to be considered for the external IC error monitoring is the impossibility to bring the system in fail safe state when a safety function error (other than MCU) is reported and not handled by MCU itself. | E9: External IC error not detected could lead to the violation of the system safety goals | F9: SM10, SMA5 | G9: LF | H9: TSR_10, TSR_11
A10: FS6500_SAF181 | B10: SC0106 | C10: Power up mode | D10: Power Up mode is defined as state between Fail Safe logic POR and Reset release. In this mode, the device is in Safe State by default (RSTb, FS0b and FS1b are asserted Low) | E10: - | F10: - | G10: - | H10: -
A11: FS6500_SAF182 | B11: SC0107 | C11: LPOFF mode | D11: Low Power OFF mode is defined as state where all power supplies are turned OFF, and Fail Safe logic is unpowered. In this mode, the device is in Safe State by default (RSTb, FS0b and FS1b are asserted Low). | E11: - | F11: - | G11: - | H11: -

Sheet Safety Mechanisms
A1: # | B1: Safety mechanism | C1: § ISO 26262 | D1: Level of Diagnostic coverage | E1: Used? | F1: DC (%) | G1: Safety Manual Tag | H1: Comment
A2: - | B2: Not applicable | C2: - | D2: - | E2: - | F2: =IF(Table3[[#This Row],[Used?]]="Yes",IF(Table3[[#This Row],[Level of Diagnostic coverage]]="High",0.99, IF(Table3[[#This Row],[Level of Diagnostic coverage]]="Medium",0.9, IF(Table3[[#This Row],[Level of Diagnostic coverage]]="Low",0.6, 0))),0) -> 0
A3: SM1 | B3: Voltage supervisor (Monitoring of voltage) Overvoltage detection | C3: D.2.8.2 | D3: High | E3: Yes | F3: =IF(Table3[[#This Row],[Used?]]="Yes",IF(Table3[[#This Row],[Level of Diagnostic coverage]]="High",0.99, IF(Table3[[#This Row],[Level of Diagnostic coverage]]="Medium",0.9, IF(Table3[[#This Row],[Level of Diagnostic coverage]]="Low",0.6, 0))),0) -> 0.99 | G3: SMR_19 SMR_22 SMR_24
A4: SM2 | B4: Voltage supervisor (Monitoring of voltage) Undervoltage detection | C4: D.2.8.2 | D4: High | E4: Yes | F4: =IF(Table3[[#This Row],[Used?]]="Yes",IF(Table3[[#This Row],[Level of Diagnostic coverage]]="High",0.99, IF(Table3[[#This Row],[Level of Diagnostic coverage]]="Medium",0.9, IF(Table3[[#This Row],[Level of Diagnostic coverage]]="Low",0.6, 0))),0) -> 0.99 | G4: SMR_19 SMR_22 SMR_24
A5: SM1&SM2 | B5: Voltage supervisor (Monitoring of voltage) | C5: D.2.8.2 | D5: High | E5: Yes | F5: =IF(Table3[[#This Row],[Used?]]="Yes",IF(Table3[[#This Row],[Level of Diagnostic coverage]]="High",0.99, IF(Table3[[#This Row],[Level of Diagnostic coverage]]="Medium",0.9, IF(Table3[[#This Row],[Level of Diagnostic coverage]]="Low",0.6, 0))),0) -> 0.99 | G5: SMR_19 SMR_22 SMR_24
A6: SM3 | B6: FB_core monitoring (Monitoring of voltage) Overvoltage and Undervoltage detections | C6: D.2.8.2 | D6: High | E6: Yes | F6: =IF(Table3[[#This Row],[Used?]]="Yes",IF(Table3[[#This Row],[Level of Diagnostic coverage]]="High",0.99, IF(Table3[[#This Row],[Level of Diagnostic coverage]]="Medium",0.9, IF(Table3[[#This Row],[Level of Diagnostic coverage]]="Low",0.6, 0))),0) -> 0.99 | G6: SMR_20
A7: SM4 | B7: Watchdog | C7: D.2.7.6, D.2.7.7, D.2.7.8 | D7: High | E7: Yes | F7: =IF(Table3[[#This Row],[Used?]]="Yes",IF(Table3[[#This Row],[Level of Diagnostic coverage]]="High",0.99, IF(Table3[[#This Row],[Level of Diagnostic coverage]]="Medium",0.9, IF(Table3[[#This Row],[Level of Diagnostic coverage]]="Low",0.6, 0))),0) -> 0.99 | G7: SMR_29
A8: SM5 | B8: Voltage supervisor (Monitoring of output voltage) logical level | C8: D.2.6.4 | D8: High | E8: Yes | F8: =IF(Table3[[#This Row],[Used?]]="Yes",IF(Table3[[#This Row],[Level of Diagnostic coverage]]="High",0.99, IF(Table3[[#This Row],[Level of Diagnostic coverage]]="Medium",0.9, IF(Table3[[#This Row],[Level of Diagnostic coverage]]="Low",0.6, 0))),0) -> 0.99 | G8: Chapter 5.6.1 Chapter 5.7.3
A9: SM6 | B9: Input comparison/voting | C9: D.2.6.5 | D9: High | E9: Yes | F9: =IF(Table3[[#This Row],[Used?]]="Yes",IF(Table3[[#This Row],[Level of Diagnostic coverage]]="High",0.99, IF(Table3[[#This Row],[Level of Diagnostic coverage]]="Medium",0.9, IF(Table3[[#This Row],[Level of Diagnostic coverage]]="Low",0.6, 0))),0) -> 0.99 | G9: SMR_26 SMR_27
A10: SM7 | B10: Majority voter (triplication) | C10: D.2.1.3 | D10: High | E10: Yes | F10: =IF(Table3[[#This Row],[Used?]]="Yes",IF(Table3[[#This Row],[Level of Diagnostic coverage]]="High",0.99, IF(Table3[[#This Row],[Level of Diagnostic coverage]]="Medium",0.9, IF(Table3[[#This Row],[Level of Diagnostic coverage]]="Low",0.6, 0))),0) -> 0.99 | G10: SMR_30
A11: SM8 | B11: Error Detection Correction Code (EDC) | C11: D.2.4.1 | D11: Low | E11: Yes | F11: =IF(Table3[[#This Row],[Used?]]="Yes",IF(Table3[[#This Row],[Level of Diagnostic coverage]]="High",0.99, IF(Table3[[#This Row],[Level of Diagnostic coverage]]="Medium",0.9, IF(Table3[[#This Row],[Level of Diagnostic coverage]]="Low",0.6, 0))),0) -> 0.6 | G11: SMR_16
A12: SM9 | B12: HW redundancy (FS1b back up delay) | C12: D.2.3.6 | D12: High | E12: Yes | F12: =IF(Table3[[#This Row],[Used?]]="Yes",IF(Table3[[#This Row],[Level of Diagnostic coverage]]="High",0.99, IF(Table3[[#This Row],[Level of Diagnostic coverage]]="Medium",0.9, IF(Table3[[#This Row],[Level of Diagnostic coverage]]="Low",0.6, 0))),0) -> 0.99 | G12: SMR_37 | H12: Select Yes for Part number with FS1b Select No for Part number without FS1b
A13: SM10 | B13: Information redundancy / Frame counter / Timeout monitoring | C13: D.2.7.6, D.2.7.7, D.2.7.8 | D13: High | E13: Yes | F13: =IF(Table3[[#This Row],[Used?]]="Yes",IF(Table3[[#This Row],[Level of Diagnostic coverage]]="High",0.99, IF(Table3[[#This Row],[Level of Diagnostic coverage]]="Medium",0.9, IF(Table3[[#This Row],[Level of Diagnostic coverage]]="Low",0.6, 0))),0) -> 0.99 | G13: SMR_28 | H13: Select Yes if IO_45 External IC Error monitoring is used Select No if IO_45 External IC Error monitoring is not used
A14: SMA1 | B14: Read HW_Config SPI register and extract Vcca_HW, Vaux_HW, LS_detect, DBG_HW and DFS_HW1/2 configuration bits to compare with expected values before releasing Fail Safe path | C14: - | D14: High | E14: Yes | F14: =IF(Table3[[#This Row],[Used?]]="Yes",IF(Table3[[#This Row],[Level of Diagnostic coverage]]="High",0.99, IF(Table3[[#This Row],[Level of Diagnostic coverage]]="Medium",0.9, IF(Table3[[#This Row],[Level of Diagnostic coverage]]="Low",0.6, 0))),0) -> 0.99 | G14: Vcca_HW -> SMR_21 Vaux_HW -> SMR_23 LS_detect -> SMR_17 DBG_HW -> SMR_41 DFS_HW1/2 -> SMR_40
A15: SMA2 | B15: Software FS0b request to verify the good activation of FS0b before starting the application | C15: - | D15: High | E15: Yes | F15: =IF(Table3[[#This Row],[Used?]]="Yes",IF(Table3[[#This Row],[Level of Diagnostic coverage]]="High",0.99, IF(Table3[[#This Row],[Level of Diagnostic coverage]]="Medium",0.9, IF(Table3[[#This Row],[Level of Diagnostic coverage]]="Low",0.6, 0))),0) -> 0.99 | G15: SMR_32
A16: SMA3 | B16: Software FS1b request to verify the good activation of FS1b before starting the application | C16: - | D16: High | E16: Yes | F16: =IF(Table3[[#This Row],[Used?]]="Yes",IF(Table3[[#This Row],[Level of Diagnostic coverage]]="High",0.99, IF(Table3[[#This Row],[Level of Diagnostic coverage]]="Medium",0.9, IF(Table3[[#This Row],[Level of Diagnostic coverage]]="Low",0.6, 0))),0) -> 0.99 | G16: SMR_35 | H16: Select Yes for Part number with FS1b Select No for Part number without FS1b
A17: SMA4 | B17: Verification of external Rpd/Cpd components connected to VPU_FS to guarantee FS1b back up delay | C17: - | D17: High | E17: Yes | F17: =IF(Table3[[#This Row],[Used?]]="Yes",IF(Table3[[#This Row],[Level of Diagnostic coverage]]="High",0.99, IF(Table3[[#This Row],[Level of Diagnostic coverage]]="Medium",0.9, IF(Table3[[#This Row],[Level of Diagnostic coverage]]="Low",0.6, 0))),0) -> 0.99 | G17: SMR_37 | H17: Select Yes for Part number with FS1b Select No for Part number without FS1b
A18: SMA5 | B18: Verify the good activation of FS0b before starting the application with IO_4/5 configured safety critical | C18: - | D18: High | E18: Yes | F18: =IF(Table3[[#This Row],[Used?]]="Yes",IF(Table3[[#This Row],[Level of Diagnostic coverage]]="High",0.99, IF(Table3[[#This Row],[Level of Diagnostic coverage]]="Medium",0.9, IF(Table3[[#This Row],[Level of Diagnostic coverage]]="Low",0.6, 0))),0) -> 0.99 | G18: SMR_28 | H18: Select Yes if IO_45 External IC Error monitoring is used Select No if IO_45 External IC Error monitoring is not used
A19: ABIST & LBIST | B19: Analog and Logical BuitIn Self Test | C19: - | D19: Low | E19: Yes | F19: =IF(Table3[[#This Row],[Used?]]="Yes",IF(Table3[[#This Row],[Level of Diagnostic coverage]]="High",0.99, IF(Table3[[#This Row],[Level of Diagnostic coverage]]="Medium",0.9, IF(Table3[[#This Row],[Level of Diagnostic coverage]]="Low",0.6, 0))),0) -> 0.6 | G19: LBIST & ABIST1 -> SMR_38 ABIST2 -> SMR_39

Sheet FMEDA_OP
O1: SPFM = | P1: =1-Table2[[#Totals],[Residual of single point fault failure rate/FIT]]/Table2[[#Totals],[λSR]] -> 0.99323435 | U1: LFM = | V1: =1-(Table2[[#Totals],[Latent multiple point fault failure rate/FIT]]/((Table2[[#Totals],[λSR]])-Table2[[#Totals],[Residual of single point fault failure rate/FIT]])) -> 0.96881438
A2: # | B2: Function | C2: Function Description | D2: Product pins linked to Block (PinFMEA Link) | E2: Block identification linked to block | F2: λ | G2: Failure mode | H2: Failure mode that has the potential to violate the safety goal in absence of safety mechanism? | I2: Safety Requirement Violated | J2: Failure rate distribution | K2: Failure mode rate | L2: Applicable Safety mechanism | M2: Safety Mechanism(s) allowing to prevent the failure mode from violating the safety goals | N2: §ISO 26262 | O2: Failure mode coverage wrt. violation of safety goals | P2: Residual of single point fault failure rate/FIT | Q2: Failure mode that may lead to the violation of safety goals in combination with an independent failure of another block ? | R2: Safety Requirement Violated (Latent) | S2: Detection means ? Safety mechanism(s) allowing to prevent the failure mode from being latent ? | T2: Safety Mechanism(s) allowing to prevent the latent failure mode from violating the safety goals | U2: Failure mode coverage with respect to latent failures | V2: Latent multiple point fault failure rate/FIT | W2: Comments | X2: SR | Y2: λSR
A3: FM1 | B3: Vcore | C3: MCU core Supply | D3: FB_CORE Comp_core Vcore_sns VSW_core Boot_core Vpre DGND | E3: Analog Reference #1 Charge Pump Power Management state machine | F3: =VLOOKUP(Table2[Function], Table1[], 5, FALSE) -> 8.9517883 | G3: Overvoltage | H3: Yes | I3: SC0006 | J3: 0.098 | K3: =Table2[[#This Row],[λ]]*Table2[[#This Row],[Failure rate distribution]] -> 0.87727525 | L3: SM1 | M3: =VLOOKUP(Table2[[#This Row],[Applicable Safety mechanism]],Table3[],2,FALSE) -> Voltage supervisor (Monitoring of voltage) Overvoltage detection | N3: =VLOOKUP(Table2[[#This Row],[Applicable Safety mechanism]], Table3[], 3,FALSE) -> D.2.8.2 | O3: =VLOOKUP(Table2[[#This Row],[Applicable Safety mechanism]], Table3[], 6,FALSE) -> 0.99 | P3: =IF(Table2[[#This Row],[Failure mode that has the potential to violate the safety goal in absence of safety mechanism?]]="Yes", Table2[[#This Row],[Failure mode rate]]*(1-Table2[[#This Row],[Failure mode coverage wrt. violation of safety goals]]), 0) -> 0.0087727525 | Q3: No | V3: =IF(Table2[[#This Row],[Failure mode that may lead to the violation of safety goals in combination with an independent failure of another block ?]]="Yes",(1-Table2[[#This Row],[Failure mode coverage with respect to latent failures]])*Table2[[#This Row],[Failure mode rate]], 0) -> 0 | X3: Yes | Y3: =IF(Table2[[#This Row],[SR]]="Yes",Table2[[#This Row],[λ]], 0) -> 8.9517883
A4: FM2 | B4: Vcore | C4: MCU core Supply | F4: =VLOOKUP(Table2[Function], Table1[], 5, FALSE) -> 8.9517883 | G4: Under voltage | H4: Yes | I4: SC0006 | J4: 0.098 | K4: =Table2[[#This Row],[λ]]*Table2[[#This Row],[Failure rate distribution]] -> 0.87727525 | L4: SM2 | M4: =VLOOKUP(Table2[[#This Row],[Applicable Safety mechanism]],Table3[],2,FALSE) -> Voltage supervisor (Monitoring of voltage) Undervoltage detection | N4: =VLOOKUP(Table2[[#This Row],[Applicable Safety mechanism]], Table3[], 3,FALSE) -> D.2.8.2 | O4: =VLOOKUP(Table2[[#This Row],[Applicable Safety mechanism]], Table3[], 6,FALSE) -> 0.99 | P4: =IF(Table2[[#This Row],[Failure mode that has the potential to violate the safety goal in absence of safety mechanism?]]="Yes", Table2[[#This Row],[Failure mode rate]]*(1-Table2[[#This Row],[Failure mode coverage wrt. violation of safety goals]]), 0) -> 0.0087727525 | Q4: No | V4: =IF(Table2[[#This Row],[Failure mode that may lead to the violation of safety goals in combination with an independent failure of another block ?]]="Yes",(1-Table2[[#This Row],[Failure mode coverage with respect to latent failures]])*Table2[[#This Row],[Failure mode rate]], 0) -> 0 | Y4: =IF(Table2[[#This Row],[SR]]="Yes",Table2[[#This Row],[λ]], 0) -> 0
A5: FM3 | B5: Vcore | C5: MCU core Supply | F5: =VLOOKUP(Table2[Function], Table1[], 5, FALSE) -> 8.9517883 | G5: Drift on external resistor bridge | H5: Yes | I5: SC0006 | J5: 0 | K5: =Table2[[#This Row],[λ]]*Table2[[#This Row],[Failure rate distribution]] -> 0 | L5: SM3 | M5: =VLOOKUP(Table2[[#This Row],[Applicable Safety mechanism]],Table3[],2,FALSE) -> FB_core monitoring (Monitoring of voltage) Overvoltage and Undervoltage detections | N5: =VLOOKUP(Table2[[#This Row],[Applicable Safety mechanism]], Table3[], 3,FALSE) -> D.2.8.2 | O5: =VLOOKUP(Table2[[#This Row],[Applicable Safety mechanism]], Table3[], 6,FALSE) -> 0.99 | P5: =IF(Table2[[#This Row],[Failure mode that has the potential to violate the safety goal in absence of safety mechanism?]]="Yes", Table2[[#This Row],[Failure mode rate]]*(1-Table2[[#This Row],[Failure mode coverage wrt. violation of safety goals]]), 0) -> 0 | Q5: No | V5: =IF(Table2[[#This Row],[Failure mode that may lead to the violation of safety goals in combination with an independent failure of another block ?]]="Yes",(1-Table2[[#This Row],[Failure mode coverage with respect to latent failures]])*Table2[[#This Row],[Failure mode rate]], 0) -> 0 | Y5: =IF(Table2[[#This Row],[SR]]="Yes",Table2[[#This Row],[λ]], 0) -> 0
A6: FM4 | B6: Vcore | C6: MCU core Supply | F6: =VLOOKUP(Table2[Function], Table1[], 5, FALSE) -> 8.9517883 | G6: Voltage oscillation | H6: Yes | I6: SC0006 | J6: 0.098 | K6: =Table2[[#This Row],[λ]]*Table2[[#This Row],[Failure rate distribution]] -> 0.87727525 | L6: SM1&SM2 | M6: =VLOOKUP(Table2[[#This Row],[Applicable Safety mechanism]],Table3[],2,FALSE) -> Voltage supervisor (Monitoring of voltage) | N6: =VLOOKUP(Table2[[#This Row],[Applicable Safety mechanism]], Table3[], 3,FALSE) -> D.2.8.2 | O6: =VLOOKUP(Table2[[#This Row],[Applicable Safety mechanism]], Table3[], 6,FALSE) -> 0.99 | P6: =IF(Table2[[#This Row],[Failure mode that has the potential to violate the safety goal in absence of safety mechanism?]]="Yes", Table2[[#This Row],[Failure mode rate]]*(1-Table2[[#This Row],[Failure mode coverage wrt. violation of safety goals]]), 0) -> 0.0087727525 | Q6: No | V6: =IF(Table2[[#This Row],[Failure mode that may lead to the violation of safety goals in combination with an independent failure of another block ?]]="Yes",(1-Table2[[#This Row],[Failure mode coverage with respect to latent failures]])*Table2[[#This Row],[Failure mode rate]], 0) -> 0 | Y6: =IF(Table2[[#This Row],[SR]]="Yes",Table2[[#This Row],[λ]], 0) -> 0
A7: FM5 | B7: Vcore | C7: MCU core Supply | F7: =VLOOKUP(Table2[Function], Table1[], 5, FALSE) -> 8.9517883 | G7: Power spikes | H7: Yes | I7: SC0006 | J7: 0.098 | K7: =Table2[[#This Row],[λ]]*Table2[[#This Row],[Failure rate distribution]] -> 0.87727525 | L7: SM1&SM2 | M7: =VLOOKUP(Table2[[#This Row],[Applicable Safety mechanism]],Table3[],2,FALSE) -> Voltage supervisor (Monitoring of voltage) | N7: =VLOOKUP(Table2[[#This Row],[Applicable Safety mechanism]], Table3[], 3,FALSE) -> D.2.8.2 | O7: =VLOOKUP(Table2[[#This Row],[Applicable Safety mechanism]], Table3[], 6,FALSE) -> 0.99 | P7: =IF(Table2[[#This Row],[Failure mode that has the potential to violate the safety goal in absence of safety mechanism?]]="Yes", Table2[[#This Row],[Failure mode rate]]*(1-Table2[[#This Row],[Failure mode coverage wrt. violation of safety goals]]), 0) -> 0.0087727525 | Q7: No | V7: =IF(Table2[[#This Row],[Failure mode that may lead to the violation of safety goals in combination with an independent failure of another block ?]]="Yes",(1-Table2[[#This Row],[Failure mode coverage with respect to latent failures]])*Table2[[#This Row],[Failure mode rate]], 0) -> 0 | Y7: =IF(Table2[[#This Row],[SR]]="Yes",Table2[[#This Row],[λ]], 0) -> 0
A8: FM6 | B8: Vcore | C8: MCU core Supply | F8: =VLOOKUP(Table2[Function], Table1[], 5, FALSE) -> 8.9517883 | G8: Drift | H8: Yes | I8: SC0006 | J8: 0.098 | K8: =Table2[[#This Row],[λ]]*Table2[[#This Row],[Failure rate distribution]] -> 0.87727525 | L8: SM1&SM2 | M8: =VLOOKUP(Table2[[#This Row],[Applicable Safety mechanism]],Table3[],2,FALSE) -> Voltage supervisor (Monitoring of voltage) | N8: =VLOOKUP(Table2[[#This Row],[Applicable Safety mechanism]], Table3[], 3,FALSE) -> D.2.8.2 | O8: =VLOOKUP(Table2[[#This Row],[Applicable Safety mechanism]], Table3[], 6,FALSE) -> 0.99 | P8: =IF(Table2[[#This Row],[Failure mode that has the potential to violate the safety goal in absence of safety mechanism?]]="Yes", Table2[[#This Row],[Failure mode rate]]*(1-Table2[[#This Row],[Failure mode coverage wrt. violation of safety goals]]), 0) -> 0.0087727525 | Q8: No | V8: =IF(Table2[[#This Row],[Failure mode that may lead to the violation of safety goals in combination with an independent failure of another block ?]]="Yes",(1-Table2[[#This Row],[Failure mode coverage with respect to latent failures]])*Table2[[#This Row],[Failure mode rate]], 0) -> 0 | Y8: =IF(Table2[[#This Row],[SR]]="Yes",Table2[[#This Row],[λ]], 0) -> 0
A9: FM7 | B9: Vcore | C9: MCU core Supply | F9: =VLOOKUP(Table2[Function], Table1[], 5, FALSE) -> 8.9517883 | G9: FB_core pin shorted to GND | H9: Yes | I9: SC0006 | J9: 0.098 | K9: =Table2[[#This Row],[λ]]*Table2[[#This Row],[Failure rate distribution]] -> 0.87727525 | L9: SM2 | M9: =VLOOKUP(Table2[[#This Row],[Applicable Safety mechanism]],Table3[],2,FALSE) -> Voltage supervisor (Monitoring of voltage) Undervoltage detection | N9: =VLOOKUP(Table2[[#This Row],[Applicable Safety mechanism]], Table3[], 3,FALSE) -> D.2.8.2 | O9: =VLOOKUP(Table2[[#This Row],[Applicable Safety mechanism]], Table3[], 6,FALSE) -> 0.99 | P9: =IF(Table2[[#This Row],[Failure mode that has the potential to violate the safety goal in absence of safety mechanism?]]="Yes", Table2[[#This Row],[Failure mode rate]]*(1-Table2[[#This Row],[Failure mode coverage wrt. violation of safety goals]]), 0) -> 0.0087727525 | Q9: No | V9: =IF(Table2[[#This Row],[Failure mode that may lead to the violation of safety goals in combination with an independent failure of another block ?]]="Yes",(1-Table2[[#This Row],[Failure mode coverage with respect to latent failures]])*Table2[[#This Row],[Failure mode rate]], 0) -> 0 | Y9: =IF(Table2[[#This Row],[SR]]="Yes",Table2[[#This Row],[λ]], 0) -> 0
A10: FM8 | B10: Vcore | C10: MCU core Supply | F10: =VLOOKUP(Table2[Function], Table1[], 5, FALSE) -> 8.9517883 | G10: FB_core pin shorted to High | H10: Yes | I10: SC0006 | J10: 0.098 | K10: =Table2[[#This Row],[λ]]*Table2[[#This Row],[Failure rate distribution]] -> 0.87727525 | L10: SM1 | M10: =VLOOKUP(Table2[[#This Row],[Applicable Safety mechanism]],Table3[],2,FALSE) -> Voltage supervisor (Monitoring of voltage) Overvoltage detection | N10: =VLOOKUP(Table2[[#This Row],[Applicable Safety mechanism]], Table3[], 3,FALSE) -> D.2.8.2 | O10: =VLOOKUP(Table2[[#This Row],[Applicable Safety mechanism]], Table3[], 6,FALSE) -> 0.99 | P10: =IF(Table2[[#This Row],[Failure mode that has the potential to violate the safety goal in absence of safety mechanism?]]="Yes", Table2[[#This Row],[Failure mode rate]]*(1-Table2[[#This Row],[Failure mode coverage wrt. violation of safety goals]]), 0) -> 0.0087727525 | Q10: No | V10: =IF(Table2[[#This Row],[Failure mode that may lead to the violation of safety goals in combination with an independent failure of another block ?]]="Yes",(1-Table2[[#This Row],[Failure mode coverage with respect to latent failures]])*Table2[[#This Row],[Failure mode rate]], 0) -> 0 | Y10: =IF(Table2[[#This Row],[SR]]="Yes",Table2[[#This Row],[λ]], 0) -> 0
A11: FM9 | B11: Vcore | C11: MCU core Supply | F11: =VLOOKUP(Table2[Function], Table1[], 5, FALSE) -> 8.9517883 | G11: FB_core pin open | H11: Yes | I11: SC0006 | J11: 0.098 | K11: =Table2[[#This Row],[λ]]*Table2[[#This Row],[Failure rate distribution]] -> 0.87727525 | L11: SM3 | M11: =VLOOKUP(Table2[[#This Row],[Applicable Safety mechanism]],Table3[],2,FALSE) -> FB_core monitoring (Monitoring of voltage) Overvoltage and Undervoltage detections | N11: =VLOOKUP(Table2[[#This Row],[Applicable Safety mechanism]], Table3[], 3,FALSE) -> D.2.8.2 | O11: =VLOOKUP(Table2[[#This Row],[Applicable Safety mechanism]], Table3[], 6,FALSE) -> 0.99 | P11: =IF(Table2[[#This Row],[Failure mode that has the potential to violate the safety goal in absence of safety mechanism?]]="Yes", Table2[[#This Row],[Failure mode rate]]*(1-Table2[[#This Row],[Failure mode coverage wrt. violation of safety goals]]), 0) -> 0.0087727525 | Q11: No | V11: =IF(Table2[[#This Row],[Failure mode that may lead to the violation of safety goals in combination with an independent failure of another block ?]]="Yes",(1-Table2[[#This Row],[Failure mode coverage with respect to latent failures]])*Table2[[#This Row],[Failure mode rate]], 0) -> 0 | Y11: =IF(Table2[[#This Row],[SR]]="Yes",Table2[[#This Row],[λ]], 0) -> 0
A12: FM10 | B12: Vcore | C12: MCU core Supply | F12: =VLOOKUP(Table2[Function], Table1[], 5, FALSE) -> 8.9517883 | G12: FB_core pin shorted to adjacent pin "comp_core" | H12: Yes | I12: SC0006 | J12: 0.098 | K12: =Table2[[#This Row],[λ]]*Table2[[#This Row],[Failure rate distribution]] -> 0.87727525 | L12: SM3 | M12: =VLOOKUP(Table2[[#This Row],[Applicable Safety mechanism]],Table3[],2,FALSE) -> FB_core monitoring (Monitoring of voltage) Overvoltage and Undervoltage detections | N12: =VLOOKUP(Table2[[#This Row],[Applicable Safety mechanism]], Table3[], 3,FALSE) -> D.2.8.2 | O12: =VLOOKUP(Table2[[#This Row],[Applicable Safety mechanism]], Table3[], 6,FALSE) -> 0.99 | P12: =IF(Table2[[#This Row],[Failure mode that has the potential to violate the safety goal in absence of safety mechanism?]]="Yes", Table2[[#This Row],[Failure mode rate]]*(1-Table2[[#This Row],[Failure mode coverage wrt. violation of safety goals]]), 0) -> 0.0087727525 | Q12: No | V12: =IF(Table2[[#This Row],[Failure mode that may lead to the violation of safety goals in combination with an independent failure of another block ?]]="Yes",(1-Table2[[#This Row],[Failure mode coverage with respect to latent failures]])*Table2[[#This Row],[Failure mode rate]], 0) -> 0 | Y12: =IF(Table2[[#This Row],[SR]]="Yes",Table2[[#This Row],[λ]], 0) -> 0
A13: FM11 | B13: Vcore | C13: MCU core Supply | F13: =VLOOKUP(Table2[Function], Table1[], 5, FALSE) -> 8.9517883 | G13: FB_core pin shorted to adjacent pin "HW_select" | H13: Yes | I13: SC0006 | J13: 0.098 | K13: =Table2[[#This Row],[λ]]*Table2[[#This Row],[Failure rate distribution]] -> 0.87727525 | L13: SM2 | M13: =VLOOKUP(Table2[[#This Row],[Applicable Safety mechanism]],Table3[],2,FALSE) -> Voltage supervisor (Monitoring of voltage) Undervoltage detection | N13: =VLOOKUP(Table2[[#This Row],[Applicable Safety mechanism]], Table3[], 3,FALSE) -> D.2.8.2 | O13: =VLOOKUP(Table2[[#This Row],[Applicable Safety mechanism]], Table3[], 6,FALSE) -> 0.99 | P13: =IF(Table2[[#This Row],[Failure mode that has the potential to violate the safety goal in absence of safety mechanism?]]="Yes", Table2[[#This Row],[Failure mode rate]]*(1-Table2[[#This Row],[Failure mode coverage wrt. violation of safety goals]]), 0) -> 0.0087727525 | Q13: No | V13: =IF(Table2[[#This Row],[Failure mode that may lead to the violation of safety goals in combination with an independent failure of another block ?]]="Yes",(1-Table2[[#This Row],[Failure mode coverage with respect to latent failures]])*Table2[[#This Row],[Failure mode rate]], 0) -> 0 | Y13: =IF(Table2[[#This Row],[SR]]="Yes",Table2[[#This Row],[λ]], 0) -> 0
A14: FM12 | B14: Vcore | C14: MCU core Supply | F14: =VLOOKUP(Table2[Function], Table1[], 5, FALSE) -> 8.9517883 | G14: EDC failure in Power Management State Management | H14: No | I14: - | J14: 0.01 | K14: =Table2[[#This Row],[λ]]*Table2[[#This Row],[Failure rate distribution]] -> 0.089517883 | L14: - | M14: =VLOOKUP(Table2[[#This Row],[Applicable Safety mechanism]],Table3[],2,FALSE) -> Not applicable | N14: =VLOOKUP(Table2[[#This Row],[Applicable Safety mechanism]], Table3[], 3,FALSE) -> - | O14: =VLOOKUP(Table2[[#This Row],[Applicable Safety mechanism]], Table3[], 6,FALSE) -> 0 | P14: =IF(Table2[[#This Row],[Failure mode that has the potential to violate the safety goal in absence of safety mechanism?]]="Yes", Table2[[#This Row],[Failure mode rate]]*(1-Table2[[#This Row],[Failure mode coverage wrt. violation of safety goals]]), 0) -> 0 | Q14: No | V14: =IF(Table2[[#This Row],[Failure mode that may lead to the violation of safety goals in combination with an independent failure of another block ?]]="Yes",(1-Table2[[#This Row],[Failure mode coverage with respect to latent failures]])*Table2[[#This Row],[Failure mode rate]], 0) -> 0 | W14: Qualitative line. The quantification is spreaded in all the lines where Power Management State machine is involved. | Y14: =IF(Table2[[#This Row],[SR]]="Yes",Table2[[#This Row],[λ]], 0) -> 0
A15: FM13 | B15: Vcore | C15: MCU core Supply | F15: =VLOOKUP(Table2[Function], Table1[], 5, FALSE) -> 8.9517883 | G15: Fuse in Power Management State Machine failure | H15: No | I15: - | J15: 0.01 | K15: =Table2[[#This Row],[λ]]*Table2[[#This Row],[Failure rate distribution]] -> 0.089517883 | L15: - | M15: =VLOOKUP(Table2[[#This Row],[Applicable Safety mechanism]],Table3[],2,FALSE) -> Not applicable | N15: =VLOOKUP(Table2[[#This Row],[Applicable Safety mechanism]], Table3[], 3,FALSE) -> - | O15: =VLOOKUP(Table2[[#This Row],[Applicable Safety mechanism]], Table3[], 6,FALSE) -> 0 | P15: =IF(Table2[[#This Row],[Failure mode that has the potential to violate the safety goal in absence of safety mechanism?]]="Yes", Table2[[#This Row],[Failure mode rate]]*(1-Table2[[#This Row],[Failure mode coverage wrt. violation of safety goals]]), 0) -> 0 | Q15: No | V15: =IF(Table2[[#This Row],[Failure mode that may lead to the violation of safety goals in combination with an independent failure of another block ?]]="Yes",(1-Table2[[#This Row],[Failure mode coverage with respect to latent failures]])*Table2[[#This Row],[Failure mode rate]], 0) -> 0 | W15: Qualitative line. The quantification is spreaded in all the lines where Power Management State machine is involved. | Y15: =IF(Table2[[#This Row],[SR]]="Yes",Table2[[#This Row],[λ]], 0) -> 0
A16: FM14 | B16: Vcore | C16: MCU core Supply | D16: - | F16: =VLOOKUP(Table2[Function], Table1[], 5, FALSE) -> 8.9517883 | G16: - | H16: - | I16: - | J16: - | K16: - | L16: - | M16: - | N16: - | O16: - | P16: - | Q16: -
A17: FM15 | B17: Vpre | C17: Pre-regulator | D17: Vsup1 Vsup2 SW_pre1 SW_pre2 Boots_pre Gates_LS Vpre DGND | E17: Analog Reference #1 Charge Pump Power Management state machine | F17: =VLOOKUP(Table2[Function], Table1[], 5, FALSE) -> 12.533196 | G17: Overvoltage | H17: Yes | I17: SC0006 | J17: =1/8 -> 0.125 | K17: =Table2[[#This Row],[λ]]*Table2[[#This Row],[Failure rate distribution]] -> 1.5666495 | L17: SM1 | M17: =VLOOKUP(Table2[[#This Row],[Applicable Safety mechanism]],Table3[],2,FALSE) -> Voltage supervisor (Monitoring of voltage) Overvoltage detection | N17: =VLOOKUP(Table2[[#This Row],[Applicable Safety mechanism]], Table3[], 3,FALSE) -> D.2.8.2 | O17: =VLOOKUP(Table2[[#This Row],[Applicable Safety mechanism]], Table3[], 6,FALSE) -> 0.99 | P17: =IF(Table2[[#This Row],[Failure mode that has the potential to violate the safety goal in absence of safety mechanism?]]="Yes", Table2[[#This Row],[Failure mode rate]]*(1-Table2[[#This Row],[Failure mode coverage wrt. violation of safety goals]]), 0) -> 0.015666495 | Q17: No | V17: =IF(Table2[[#This Row],[Failure mode that may lead to the violation of safety goals in combination with an independent failure of another block ?]]="Yes",(1-Table2[[#This Row],[Failure mode coverage with respect to latent failures]])*Table2[[#This Row],[Failure mode rate]], 0) -> 0 | X17: Yes | Y17: =IF(Table2[[#This Row],[SR]]="Yes",Table2[[#This Row],[λ]], 0) -> 12.533196
A18: FM16 | B18: Vpre | C18: Pre-regulator | F18: =VLOOKUP(Table2[Function], Table1[], 5, FALSE) -> 12.533196 | G18: Under voltage | H18: No | I18: - | J18: =1/8 -> 0.125 | K18: =Table2[[#This Row],[λ]]*Table2[[#This Row],[Failure rate distribution]] -> 1.5666495 | L18: - | M18: =VLOOKUP(Table2[[#This Row],[Applicable Safety mechanism]],Table3[],2,FALSE) -> Not applicable | N18: =VLOOKUP(Table2[[#This Row],[Applicable Safety mechanism]], Table3[], 3,FALSE) -> - | O18: =VLOOKUP(Table2[[#This Row],[Applicable Safety mechanism]], Table3[], 6,FALSE) -> 0 | P18: =IF(Table2[[#This Row],[Failure mode that has the potential to violate the safety goal in absence of safety mechanism?]]="Yes", Table2[[#This Row],[Failure mode rate]]*(1-Table2[[#This Row],[Failure mode coverage wrt. violation of safety goals]]), 0) -> 0 | Q18: No | V18: =IF(Table2[[#This Row],[Failure mode that may lead to the violation of safety goals in combination with an independent failure of another block ?]]="Yes",(1-Table2[[#This Row],[Failure mode coverage with respect to latent failures]])*Table2[[#This Row],[Failure mode rate]], 0) -> 0 | Y18: =IF(Table2[[#This Row],[SR]]="Yes",Table2[[#This Row],[λ]], 0) -> 0
A19: FM17 | B19: Vpre | C19: Pre-regulator | F19: =VLOOKUP(Table2[Function], Table1[], 5, FALSE) -> 12.533196 | G19: Drift | H19: Yes | I19: SC0006 | J19: =1/8 -> 0.125 | K19: =Table2[[#This Row],[λ]]*Table2[[#This Row],[Failure rate distribution]] -> 1.5666495 | L19: SM1 | M19: =VLOOKUP(Table2[[#This Row],[Applicable Safety mechanism]],Table3[],2,FALSE) -> Voltage supervisor (Monitoring of voltage) Overvoltage detection | N19: =VLOOKUP(Table2[[#This Row],[Applicable Safety mechanism]], Table3[], 3,FALSE) -> D.2.8.2 | O19: =VLOOKUP(Table2[[#This Row],[Applicable Safety mechanism]], Table3[], 6,FALSE) -> 0.99 | P19: =IF(Table2[[#This Row],[Failure mode that has the potential to violate the safety goal in absence of safety mechanism?]]="Yes", Table2[[#This Row],[Failure mode rate]]*(1-Table2[[#This Row],[Failure mode coverage wrt. violation of safety goals]]), 0) -> 0.015666495 | Q19: No | V19: =IF(Table2[[#This Row],[Failure mode that may lead to the violation of safety goals in combination with an independent failure of another block ?]]="Yes",(1-Table2[[#This Row],[Failure mode coverage with respect to latent failures]])*Table2[[#This Row],[Failure mode rate]], 0) -> 0 | Y19: =IF(Table2[[#This Row],[SR]]="Yes",Table2[[#This Row],[λ]], 0) -> 0
A20: FM18 | B20: Vpre | C20: Pre-regulator | F20: =VLOOKUP(Table2[Function], Table1[], 5, FALSE) -> 12.533196 | G20: Oscillation | H20: Yes | I20: SC0006 | J20: =1/8 -> 0.125 | K20: =Table2[[#This Row],[λ]]*Table2[[#This Row],[Failure rate distribution]] -> 1.5666495 | L20: SM1 | M20: =VLOOKUP(Table2[[#This Row],[Applicable Safety mechanism]],Table3[],2,FALSE) -> Voltage supervisor (Monitoring of voltage) Overvoltage detection | N20: =VLOOKUP(Table2[[#This Row],[Applicable Safety mechanism]], Table3[], 3,FALSE) -> D.2.8.2 | O20: =VLOOKUP(Table2[[#This Row],[Applicable Safety mechanism]], Table3[], 6,FALSE) -> 0.99 | P20: =IF(Table2[[#This Row],[Failure mode that has the potential to violate the safety goal in absence of safety mechanism?]]="Yes", Table2[[#This Row],[Failure mode rate]]*(1-Table2[[#This Row],[Failure mode coverage wrt. violation of safety goals]]), 0) -> 0.015666495 | Q20: No | V20: =IF(Table2[[#This Row],[Failure mode that may lead to the violation of safety goals in combination with an independent failure of another block ?]]="Yes",(1-Table2[[#This Row],[Failure mode coverage with respect to latent failures]])*Table2[[#This Row],[Failure mode rate]], 0) -> 0 | Y20: =IF(Table2[[#This Row],[SR]]="Yes",Table2[[#This Row],[λ]], 0) -> 0
A21: FM19 | B21: Vpre | C21: Pre-regulator | F21: =VLOOKUP(Table2[Function], Table1[], 5, FALSE) -> 12.533196 | G21: Spikes | H21: Yes | I21: SC0006 | J21: =1/8 -> 0.125 | K21: =Table2[[#This Row],[λ]]*Table2[[#This Row],[Failure rate distribution]] -> 1.5666495 | L21: SM1 | M21: =VLOOKUP(Table2[[#This Row],[Applicable Safety mechanism]],Table3[],2,FALSE) -> Voltage supervisor (Monitoring of voltage) Overvoltage detection | N21: =VLOOKUP(Table2[[#This Row],[Applicable Safety mechanism]], Table3[], 3,FALSE) -> D.2.8.2 | O21: =VLOOKUP(Table2[[#This Row],[Applicable Safety mechanism]], Table3[], 6,FALSE) -> 0.99 | P21: =IF(Table2[[#This Row],[Failure mode that has the potential to violate the safety goal in absence of safety mechanism?]]="Yes", Table2[[#This Row],[Failure mode rate]]*(1-Table2[[#This Row],[Failure mode coverage wrt. violation of safety goals]]), 0) -> 0.015666495 | Q21: No | V21: =IF(Table2[[#This Row],[Failure mode that may lead to the violation of safety goals in combination with an independent failure of another block ?]]="Yes",(1-Table2[[#This Row],[Failure mode coverage with respect to latent failures]])*Table2[[#This Row],[Failure mode rate]], 0) -> 0 | Y21: =IF(Table2[[#This Row],[SR]]="Yes",Table2[[#This Row],[λ]], 0) -> 0
A22: FM20 | B22: Vpre | C22: Pre-regulator | F22: =VLOOKUP(Table2[Function], Table1[], 5, FALSE) -> 12.533196 | G22: Vpre shorted to GND | H22: Yes | I22: SC0006 | J22: =1/8 -> 0.125 | K22: =Table2[[#This Row],[λ]]*Table2[[#This Row],[Failure rate distribution]] -> 1.5666495 | L22: SM2 | M22: =VLOOKUP(Table2[[#This Row],[Applicable Safety mechanism]],Table3[],2,FALSE) -> Voltage supervisor (Monitoring of voltage) Undervoltage detection | N22: =VLOOKUP(Table2[[#This Row],[Applicable Safety mechanism]], Table3[], 3,FALSE) -> D.2.8.2 | O22: =VLOOKUP(Table2[[#This Row],[Applicable Safety mechanism]], Table3[], 6,FALSE) -> 0.99 | P22: =IF(Table2[[#This Row],[Failure mode that has the potential to violate the safety goal in absence of safety mechanism?]]="Yes", Table2[[#This Row],[Failure mode rate]]*(1-Table2[[#This Row],[Failure mode coverage wrt. violation of safety goals]]), 0) -> 0.015666495 | Q22: No | V22: =IF(Table2[[#This Row],[Failure mode that may lead to the violation of safety goals in combination with an independent failure of another block ?]]="Yes",(1-Table2[[#This Row],[Failure mode coverage with respect to latent failures]])*Table2[[#This Row],[Failure mode rate]], 0) -> 0 | Y22: =IF(Table2[[#This Row],[SR]]="Yes",Table2[[#This Row],[λ]], 0) -> 0
A23: FM21 | B23: Vpre | C23: Pre-regulator | F23: =VLOOKUP(Table2[Function], Table1[], 5, FALSE) -> 12.533196 | G23: Vpre pin open | H23: Yes | I23: SC0006 | J23: =1/8 -> 0.125 | K23: =Table2[[#This Row],[λ]]*Table2[[#This Row],[Failure rate distribution]] -> 1.5666495 | L23: SM2 | M23: =VLOOKUP(Table2[[#This Row],[Applicable Safety mechanism]],Table3[],2,FALSE) -> Voltage supervisor (Monitoring of voltage) Undervoltage detection | N23: =VLOOKUP(Table2[[#This Row],[Applicable Safety mechanism]], Table3[], 3,FALSE) -> D.2.8.2 | O23: =VLOOKUP(Table2[[#This Row],[Applicable Safety mechanism]], Table3[], 6,FALSE) -> 0.99 | P23: =IF(Table2[[#This Row],[Failure mode that has the potential to violate the safety goal in absence of safety mechanism?]]="Yes", Table2[[#This Row],[Failure mode rate]]*(1-Table2[[#This Row],[Failure mode coverage wrt. violation of safety goals]]), 0) -> 0.015666495 | Q23: No | V23: =IF(Table2[[#This Row],[Failure mode that may lead to the violation of safety goals in combination with an independent failure of another block ?]]="Yes",(1-Table2[[#This Row],[Failure mode coverage with respect to latent failures]])*Table2[[#This Row],[Failure mode rate]], 0) -> 0 | Y23: =IF(Table2[[#This Row],[SR]]="Yes",Table2[[#This Row],[λ]], 0) -> 0
A24: FM22 | B24: Vpre | C24: Pre-regulator | F24: =VLOOKUP(Table2[Function], Table1[], 5, FALSE) -> 12.533196 | G24: Vpre shorted to adjacent pin "Vaux" | H24: Yes | I24: SC0006 | J24: =1/8 -> 0.125 | K24: =Table2[[#This Row],[λ]]*Table2[[#This Row],[Failure rate distribution]] -> 1.5666495 | L24: SM1 | M24: =VLOOKUP(Table2[[#This Row],[Applicable Safety mechanism]],Table3[],2,FALSE) -> Voltage supervisor (Monitoring of voltage) Overvoltage detection | N24: =VLOOKUP(Table2[[#This Row],[Applicable Safety mechanism]], Table3[], 3,FALSE) -> D.2.8.2 | O24: =VLOOKUP(Table2[[#This Row],[Applicable Safety mechanism]], Table3[], 6,FALSE) -> 0.99 | P24: =IF(Table2[[#This Row],[Failure mode that has the potential to violate the safety goal in absence of safety mechanism?]]="Yes", Table2[[#This Row],[Failure mode rate]]*(1-Table2[[#This Row],[Failure mode coverage wrt. violation of safety goals]]), 0) -> 0.015666495 | Q24: No | V24: =IF(Table2[[#This Row],[Failure mode that may lead to the violation of safety goals in combination with an independent failure of another block ?]]="Yes",(1-Table2[[#This Row],[Failure mode coverage with respect to latent failures]])*Table2[[#This Row],[Failure mode rate]], 0) -> 0 | Y24: =IF(Table2[[#This Row],[SR]]="Yes",Table2[[#This Row],[λ]], 0) -> 0
A25: FM23 | B25: Vpre | C25: Pre-regulator | D25: - | F25: =VLOOKUP(Table2[Function], Table1[], 5, FALSE) -> 12.533196 | G25: - | H25: - | I25: - | J25: - | K25: - | L25: - | M25: - | N25: - | O25: - | P25: - | Q25: -
