Workbook

Sheet Revision History
A2: Cortex-M4 Structural Core Self Test Library for S32K144
A3: Software Requirements Specification and Analysis | F3: Confidential and Proprietary
A8: History of change
A9: Document revision | B9: Date | C9: Author's name | D9: Description
A10: 1.0-D01 | B10: 03 February, 2016 | C10: David Svrcek | D10: Created initial list of software requirements. Document is ready for review with the development team.
A11: 1.0-D02 | B11: 17 February, 2016 | C11: David Svrcek | D11: Added two requirements REQ_M4_SCST_34 and REQ_M4_SCST_35 with IAR and GCC compiler versions
A12: 1.0-D03 | B12: 15 March, 2016 | C12: Roman Chovanec | D12: Updated requirements REQ_M4_SCST_19, REQ_M4_SCST_24
A13: 1 | B13: 15 March, 2016 | C13: Roman Chovanec | D13: Prepared Traceability for RTM 1.0.0 release
A14: 1.1 | B14: 12 October, 2016 | C14: Roman Chovanec | D14: Prepared Traceability for RTM 1.0.1 release, Updated requirement REQ_M4_SCST_30
A15: 1.2 | B15: 23 January, 2017 | C15: Roman Chovanec | D15: Prepared Traceability for RTM 1.0.2 release
A16: 1.3 | B16: 19 September, 2017 | C16: Roman Chovanec | D16: Prepared Traceability for RTM 1.0.3 release
A17: 1.4 | B17: 27 July, 2018 | C17: Roman Chovanec | D17: Updated compilers vesions REQ_M4_SCST_31, REQ_M4_SCST_34, REQ_M4_SCST_35 for RTM 1.0.4 release
A18: 2 | B18: 20 February, 2020 | C18: Roman Chovanec | D18: Updated REQ_M4_SCST_31. Added new Safety Analysis requirements (REW_M0_SCST_37 - REQ_M0_SCST_49) and updated Traceability Matrix for RTM 1.0.5 release
A20: Copyright 2016-2018,2020 NXP

Sheet Consist. Checks & Conventions
A1: The following conditional formatting is applied to the document:
A3: On the "Requirements_Analysis " sheet:
B5: Cells in the "Requirement ID" column can be automatically formatted as described below:
B7: << Req. ID >> | C7: - this requirement ID is already used in some of the ID in the rows above.
B8: << Req. ID >> | C8: - there is an inconsistency with the safety status of this requirement. It could be one of the following:
C9: 1) If both "Safety Concept Requirement ID" and "Safety Analysis Requirement ID" fields are empty, then "Safety Related" is set to "Yes" and/or "ASIL" field is not empty.
C10: In this case, it can not be justified why a requirement is specified as safety-related.
C11: 2) If at least one of the "Safety Concept Requirement ID" and "Safety Analysis Requirement ID" fields is not empty, then "Safety Related" is set to "No" and/or "ASIL" is empty.
C12: In this case, a safety status is not assigned to a lower-level requirement which is mapped to the higher-level safety requirement.
B13: << Req. ID >> | C13: - this requirement ID cannot be found in column B on the "Traceability Matrix" sheet.
B14: << Req. ID >> | C14: - no consistency check violation is detected for this requirement ID.
A16: On the "Traceability Matrix" sheet:
B18: << Req. ID >> | C18: - if verification method "Review" is defined for this non-obsolete requirement, then the corresponding "Review result" field is empty for this requirement; - if verification method "Test case" is defined for this non-obsolete requirements, then the corresponding "Test ID" field is empty.
B22: << Req. ID >> | C22: - one of the fields in "Software Code" or "Design Element" or both are empty for the given non-obsolete requirement ID.
B23: << Req. ID >> | C23: - no consistency check violation is detected for this requirement ID.

Sheet Requirements_Analysis
A1: Safety Concept Reference | B1: SCST Safety Concept, Rev. 1.1 | C1: SOW Reference | D1: CortexM4 SCST for S32K144 Statement of Work, Rev.1.0
A2: Safety Analysis Reference | B2: Safety Analysis, Rev. 2.0
A3: Safety Concept Requirement ID | B3: SOW Requirement ID | C3: Safety Analysis Requirement ID | D3: Requirement ID | E3: Description | F3: Status | G3: Requirement Type | H3: Safety-Related | I3: ASIL | J3: Target Release | K3: Priority | L3: Technically Feasible | M3: Testable | N3: Verification Criteria | O3: Contradicts to other requirement(s) | P3: Contains internal contradiction | Q3: Duplicates requirement(s) | R3: Remarks | T3: Lists' values definition
D4: REQ_M4_SCST_01 | E4: Core test shall achieve a diagnostic coverage of at least 90% for the relevant core modules. | F4: Reviewed | G4: Functional | H4: No | J4: BLN_SCST_M4_S32K144_RTM_1.0.3 | K4: High | L4: Yes | M4: No | N4: Review | O4: No | P4: No | Q4: No | T4: New | U4: Functional | V4: A | W4: High | X4: Yes | Y4: Review | AA4: =IF(MATCH(D4,$D$4:$D$47,0) <> (ROW() - 3), TRUE, FALSE) -> FALSE | AB4: =NOT(IF(OR(NOT(ISBLANK(A4)),NOT(ISBLANK(C4))),IF(AND(EXACT(H4,"Yes"),NOT(ISBLANK(I4))),"TRUE","FALSE"),IF(OR(EXACT(H4,"Yes"),NOT(ISBLANK(I4))),"FALSE","TRUE"))) -> FALSE | AC4: =IF(ISBLANK(D4),"FALSE",ISNA(VLOOKUP($D4,'Traceability Matrix'!D$2:D$500,1,FALSE))) -> FALSE
D5: REQ_M4_SCST_02 | E5: The SCST library shall check consistency of input parameters, through which a range of core tests to execute is specified. | F5: Reviewed | G5: Functional | H5: No | J5: BLN_SCST_M4_S32K144_RTM_1.0.3 | K5: High | L5: Yes | M5: Yes | N5: Test case | O5: No | P5: No | Q5: No | T5: Changed | U5: Interface | V5: B | W5: Medium | X5: No | Y5: Test case | AA5: =IF(MATCH(D5,$D$4:$D$47,0) <> (ROW() - 3), TRUE, FALSE) -> FALSE | AB5: =NOT(IF(OR(NOT(ISBLANK(A5)),NOT(ISBLANK(C5))),IF(AND(EXACT(H5,"Yes"),NOT(ISBLANK(I5))),"TRUE","FALSE"),IF(OR(EXACT(H5,"Yes"),NOT(ISBLANK(I5))),"FALSE","TRUE"))) -> FALSE | AC5: =IF(ISBLANK(D5),"FALSE",ISNA(VLOOKUP($D5,'Traceability Matrix'!D$2:D$500,1,FALSE))) -> FALSE
C6: M4_SCST_SA_Req08 | D6: REQ_M4_SCST_03 | E6: The SCST library shall return control and execution result of the first failed test out of the requested for execution set of tests. | F6: Reviewed | G6: Functional | H6: Yes | I6: B | J6: BLN_SCST_M4_S32K144_RTM_1.0.3 | K6: High | L6: Yes | M6: Yes | N6: Test case | O6: No | P6: No | Q6: No | T6: Reviewed | U6: Performance | V6: C | W6: Low | Y6: n/a | AA6: =IF(MATCH(D6,$D$4:$D$47,0) <> (ROW() - 3), TRUE, FALSE) -> FALSE | AB6: =NOT(IF(OR(NOT(ISBLANK(A6)),NOT(ISBLANK(C6))),IF(AND(EXACT(H6,"Yes"),NOT(ISBLANK(I6))),"TRUE","FALSE"),IF(OR(EXACT(H6,"Yes"),NOT(ISBLANK(I6))),"FALSE","TRUE"))) -> FALSE | AC6: =IF(ISBLANK(D6),"FALSE",ISNA(VLOOKUP($D6,'Traceability Matrix'!D$2:D$500,1,FALSE))) -> FALSE
D7: REQ_M4_SCST_04 | E7: Every test shall store its execution result to a global variable. This global variable is supposed to be used as a redundant path of test result propagation to application (comparing to a standard way of result returning in accordance to C / Assembly calling conventions), possibly for enabling test execution result comparison from a remote core. | F7: Reviewed | G7: Functional | H7: No | J7: BLN_SCST_M4_S32K144_RTM_1.0.3 | K7: High | L7: Yes | M7: Yes | N7: Test case | O7: No | P7: No | Q7: No | T7: Canceled | U7: Documentation | V7: D | AA7: =IF(MATCH(D7,$D$4:$D$47,0) <> (ROW() - 3), TRUE, FALSE) -> FALSE | AB7: =NOT(IF(OR(NOT(ISBLANK(A7)),NOT(ISBLANK(C7))),IF(AND(EXACT(H7,"Yes"),NOT(ISBLANK(I7))),"TRUE","FALSE"),IF(OR(EXACT(H7,"Yes"),NOT(ISBLANK(I7))),"FALSE","TRUE"))) -> FALSE | AC7: =IF(ISBLANK(D7),"FALSE",ISNA(VLOOKUP($D7,'Traceability Matrix'!D$2:D$500,1,FALSE))) -> FALSE
C8: M4_SCST_SA_Req01 | D8: REQ_M4_SCST_05 | E8: Every test shall return a unique 32-bit result which can be used for differentiating correct and erroneous test execution. | F8: Reviewed | G8: Functional | H8: Yes | I8: B | J8: BLN_SCST_M4_S32K144_RTM_1.0.3 | K8: High | L8: Yes | M8: Yes | N8: Test case | O8: No | P8: No | Q8: No | U8: Non−functional | AA8: =IF(MATCH(D8,$D$4:$D$47,0) <> (ROW() - 3), TRUE, FALSE) -> FALSE | AB8: =NOT(IF(OR(NOT(ISBLANK(A8)),NOT(ISBLANK(C8))),IF(AND(EXACT(H8,"Yes"),NOT(ISBLANK(I8))),"TRUE","FALSE"),IF(OR(EXACT(H8,"Yes"),NOT(ISBLANK(I8))),"FALSE","TRUE"))) -> FALSE | AC8: =IF(ISBLANK(D8),"FALSE",ISNA(VLOOKUP($D8,'Traceability Matrix'!D$2:D$500,1,FALSE))) -> FALSE
C9: M4_SCST_SA_Req02 | D9: REQ_M4_SCST_06 | E9: The SCST library shall return an aggregated by means of XOR operation 32-bit result of all requisted for execution tests if none of the tests failed. | F9: Reviewed | G9: Functional | H9: Yes | I9: B | J9: BLN_SCST_M4_S32K144_RTM_1.0.3 | K9: High | L9: Yes | M9: Yes | N9: Test case | O9: No | P9: No | Q9: No | U9: External | AA9: =IF(MATCH(D9,$D$4:$D$47,0) <> (ROW() - 3), TRUE, FALSE) -> FALSE | AB9: =NOT(IF(OR(NOT(ISBLANK(A9)),NOT(ISBLANK(C9))),IF(AND(EXACT(H9,"Yes"),NOT(ISBLANK(I9))),"TRUE","FALSE"),IF(OR(EXACT(H9,"Yes"),NOT(ISBLANK(I9))),"FALSE","TRUE"))) -> FALSE | AC9: =IF(ISBLANK(D9),"FALSE",ISNA(VLOOKUP($D9,'Traceability Matrix'!D$2:D$500,1,FALSE))) -> FALSE
C10: M4_SCST_SA_Req06 | D10: REQ_M4_SCST_07 | E10: The SCST library shall not store correct result of the tests in direct form. The reference test results, stored in internal array, shall be derived from a test execution result produced ina fault-free case by applying a non-trivial transformation function. | F10: Reviewed | G10: Functional | H10: Yes | I10: B | J10: BLN_SCST_M4_S32K144_RTM_1.0.3 | K10: High | L10: Yes | M10: No | N10: Review | O10: No | P10: No | Q10: No | AA10: =IF(MATCH(D10,$D$4:$D$47,0) <> (ROW() - 3), TRUE, FALSE) -> FALSE | AB10: =NOT(IF(OR(NOT(ISBLANK(A10)),NOT(ISBLANK(C10))),IF(AND(EXACT(H10,"Yes"),NOT(ISBLANK(I10))),"TRUE","FALSE"),IF(OR(EXACT(H10,"Yes"),NOT(ISBLANK(I10))),"FALSE","TRUE"))) -> FALSE | AC10: =IF(ISBLANK(D10),"FALSE",ISNA(VLOOKUP($D10,'Traceability Matrix'!D$2:D$500,1,FALSE))) -> FALSE
D11: REQ_M4_SCST_08 | E11: The SCST library shall contain a global variable m4_scst_last_executed_test_number holding an index of the last executed test. This variable shall be accessible to application. | F11: Reviewed | G11: Functional | H11: No | J11: BLN_SCST_M4_S32K144_RTM_1.0.3 | K11: High | L11: Yes | M11: Yes | N11: Test case | O11: No | P11: No | Q11: No | AA11: =IF(MATCH(D11,$D$4:$D$47,0) <> (ROW() - 3), TRUE, FALSE) -> FALSE | AB11: =NOT(IF(OR(NOT(ISBLANK(A11)),NOT(ISBLANK(C11))),IF(AND(EXACT(H11,"Yes"),NOT(ISBLANK(I11))),"TRUE","FALSE"),IF(OR(EXACT(H11,"Yes"),NOT(ISBLANK(I11))),"FALSE","TRUE"))) -> FALSE | AC11: =IF(ISBLANK(D11),"FALSE",ISNA(VLOOKUP($D11,'Traceability Matrix'!D$2:D$500,1,FALSE))) -> FALSE
D12: REQ_M4_SCST_09 | E12: The SCST library when executed shall assure that application ISRs gets execution control for all interrupts and exceptions (except for those which are intentionally triggered by the SCST library for the testing purpose) once they occur. Possible latency has to be documented. | F12: Reviewed | G12: Functional | H12: No | J12: BLN_SCST_M4_S32K144_RTM_1.0.3 | K12: High | L12: Yes | M12: Yes | N12: Test case | O12: No | P12: No | Q12: No | AA12: =IF(MATCH(D12,$D$4:$D$47,0) <> (ROW() - 3), TRUE, FALSE) -> FALSE | AB12: =NOT(IF(OR(NOT(ISBLANK(A12)),NOT(ISBLANK(C12))),IF(AND(EXACT(H12,"Yes"),NOT(ISBLANK(I12))),"TRUE","FALSE"),IF(OR(EXACT(H12,"Yes"),NOT(ISBLANK(I12))),"FALSE","TRUE"))) -> FALSE | AC12: =IF(ISBLANK(D12),"FALSE",ISNA(VLOOKUP($D12,'Traceability Matrix'!D$2:D$500,1,FALSE))) -> FALSE
D13: REQ_M4_SCST_10 | E13: The SCST library shall return control after detection of interruption of the executed test, and signal it to the application by returning a pre-defined result. | F13: Reviewed | G13: Functional | H13: No | J13: BLN_SCST_M4_S32K144_RTM_1.0.3 | K13: High | L13: Yes | M13: Yes | N13: Test case | O13: No | P13: No | Q13: No | AA13: =IF(MATCH(D13,$D$4:$D$47,0) <> (ROW() - 3), TRUE, FALSE) -> FALSE | AB13: =NOT(IF(OR(NOT(ISBLANK(A13)),NOT(ISBLANK(C13))),IF(AND(EXACT(H13,"Yes"),NOT(ISBLANK(I13))),"TRUE","FALSE"),IF(OR(EXACT(H13,"Yes"),NOT(ISBLANK(I13))),"FALSE","TRUE"))) -> FALSE | AC13: =IF(ISBLANK(D13),"FALSE",ISNA(VLOOKUP($D13,'Traceability Matrix'!D$2:D$500,1,FALSE))) -> FALSE
D14: REQ_M4_SCST_11 | E14: In case of core test execution interruption, a corresponding value should be stored to the dedicated global variable m4_scst_test_was_interrupted. This global variable is supposed to be used as a redundant path of test result propagation to application (comparing to a standard way of result returning in accordance to C / Assembly calling conventions), possibly for enabling test execution result comparison from a remote core. | F14: Reviewed | G14: Functional | H14: No | J14: BLN_SCST_M4_S32K144_RTM_1.0.3 | K14: High | L14: Yes | M14: Yes | N14: Test case | O14: No | P14: No | Q14: No | AA14: =IF(MATCH(D14,$D$4:$D$47,0) <> (ROW() - 3), TRUE, FALSE) -> FALSE | AB14: =NOT(IF(OR(NOT(ISBLANK(A14)),NOT(ISBLANK(C14))),IF(AND(EXACT(H14,"Yes"),NOT(ISBLANK(I14))),"TRUE","FALSE"),IF(OR(EXACT(H14,"Yes"),NOT(ISBLANK(I14))),"FALSE","TRUE"))) -> FALSE | AC14: =IF(ISBLANK(D14),"FALSE",ISNA(VLOOKUP($D14,'Traceability Matrix'!D$2:D$500,1,FALSE))) -> FALSE
D15: REQ_M4_SCST_12 | E15: The code of the SCST library shall store the content of non-volatile, dedicated, configuration and control registers before test execution and restore their content after completion of the test before returning control to application. This is applicable only to those regsiters which are changed by the test code. | F15: Reviewed | G15: Functional | H15: No | J15: BLN_SCST_M4_S32K144_RTM_1.0.3 | K15: High | L15: Yes | M15: Yes | N15: Test case | O15: No | P15: No | Q15: No | AA15: =IF(MATCH(D15,$D$4:$D$47,0) <> (ROW() - 3), TRUE, FALSE) -> FALSE | AB15: =NOT(IF(OR(NOT(ISBLANK(A15)),NOT(ISBLANK(C15))),IF(AND(EXACT(H15,"Yes"),NOT(ISBLANK(I15))),"TRUE","FALSE"),IF(OR(EXACT(H15,"Yes"),NOT(ISBLANK(I15))),"FALSE","TRUE"))) -> FALSE | AC15: =IF(ISBLANK(D15),"FALSE",ISNA(VLOOKUP($D15,'Traceability Matrix'!D$2:D$500,1,FALSE))) -> FALSE
D16: REQ_M4_SCST_13 | E16: The maximum runtime for all tests in the SCST library shall not exceed 400ms (Instruction and data caches enabled but invalidated before execution of every individual test). | F16: Canceled | G16: Performance | H16: No | J16: N/A | K16: High | L16: Yes | M16: Yes | N16: n/a | O16: No | P16: No | Q16: No | R16: According to the customer requirement provided in the e-mail from: Wed 3/18/2015 11:54 AM. | AA16: =IF(MATCH(D16,$D$4:$D$47,0) <> (ROW() - 3), TRUE, FALSE) -> FALSE | AB16: =NOT(IF(OR(NOT(ISBLANK(A16)),NOT(ISBLANK(C16))),IF(AND(EXACT(H16,"Yes"),NOT(ISBLANK(I16))),"TRUE","FALSE"),IF(OR(EXACT(H16,"Yes"),NOT(ISBLANK(I16))),"FALSE","TRUE"))) -> FALSE | AC16: =IF(ISBLANK(D16),"FALSE",ISNA(VLOOKUP($D16,'Traceability Matrix'!D$2:D$500,1,FALSE))) -> FALSE
D17: REQ_M4_SCST_14 | E17: When execution control is incorrectly passed to the SCST library, it shall trigger an exception by means of executing illegal opcode. | F17: Reviewed | G17: Functional | H17: No | J17: BLN_SCST_M4_S32K144_RTM_1.0.3 | K17: High | L17: Yes | M17: Yes | N17: Test case | O17: No | P17: No | Q17: No | AA17: =IF(MATCH(D17,$D$4:$D$47,0) <> (ROW() - 3), TRUE, FALSE) -> FALSE | AB17: =NOT(IF(OR(NOT(ISBLANK(A17)),NOT(ISBLANK(C17))),IF(AND(EXACT(H17,"Yes"),NOT(ISBLANK(I17))),"TRUE","FALSE"),IF(OR(EXACT(H17,"Yes"),NOT(ISBLANK(I17))),"FALSE","TRUE"))) -> FALSE | AC17: =IF(ISBLANK(D17),"FALSE",ISNA(VLOOKUP($D17,'Traceability Matrix'!D$2:D$500,1,FALSE))) -> FALSE
C18: M4_SCST_SA_Req09 | D18: REQ_M4_SCST_15 | E18: Core tests should perform explicit checking of correctness of every intermediate result as soon as resonably possible for avoiding or minimizing possible fault masking. | F18: Reviewed | G18: Functional | H18: Yes | I18: B | J18: BLN_SCST_M4_S32K144_RTM_1.0.3 | K18: High | L18: Yes | M18: No | N18: Review | O18: No | P18: No | Q18: No | AA18: =IF(MATCH(D18,$D$4:$D$47,0) <> (ROW() - 3), TRUE, FALSE) -> FALSE | AB18: =NOT(IF(OR(NOT(ISBLANK(A18)),NOT(ISBLANK(C18))),IF(AND(EXACT(H18,"Yes"),NOT(ISBLANK(I18))),"TRUE","FALSE"),IF(OR(EXACT(H18,"Yes"),NOT(ISBLANK(I18))),"FALSE","TRUE"))) -> FALSE | AC18: =IF(ISBLANK(D18),"FALSE",ISNA(VLOOKUP($D18,'Traceability Matrix'!D$2:D$500,1,FALSE))) -> FALSE
C19: M4_SCST_SA_Req09 | D19: REQ_M4_SCST_16 | E19: Every core test should progressively update a value in accordance to the process of its execution. This value is supposed to be used in final test result calculation. | F19: Reviewed | G19: Functional | H19: Yes | I19: B | J19: BLN_SCST_M4_S32K144_RTM_1.0.3 | K19: High | L19: Yes | M19: No | N19: Review | O19: No | P19: No | Q19: No | AA19: =IF(MATCH(D19,$D$4:$D$47,0) <> (ROW() - 3), TRUE, FALSE) -> FALSE | AB19: =NOT(IF(OR(NOT(ISBLANK(A19)),NOT(ISBLANK(C19))),IF(AND(EXACT(H19,"Yes"),NOT(ISBLANK(I19))),"TRUE","FALSE"),IF(OR(EXACT(H19,"Yes"),NOT(ISBLANK(I19))),"FALSE","TRUE"))) -> FALSE | AC19: =IF(ISBLANK(D19),"FALSE",ISNA(VLOOKUP($D19,'Traceability Matrix'!D$2:D$500,1,FALSE))) -> FALSE
D20: REQ_M4_SCST_17 | E20: Every core test shall limit its testing scope to well defined core logic or function. | F20: Reviewed | G20: Functional | H20: No | J20: BLN_SCST_M4_S32K144_RTM_1.0.3 | K20: High | L20: Yes | M20: No | N20: Review | O20: No | P20: No | Q20: No | AA20: =IF(MATCH(D20,$D$4:$D$47,0) <> (ROW() - 3), TRUE, FALSE) -> FALSE | AB20: =NOT(IF(OR(NOT(ISBLANK(A20)),NOT(ISBLANK(C20))),IF(AND(EXACT(H20,"Yes"),NOT(ISBLANK(I20))),"TRUE","FALSE"),IF(OR(EXACT(H20,"Yes"),NOT(ISBLANK(I20))),"FALSE","TRUE"))) -> FALSE | AC20: =IF(ISBLANK(D20),"FALSE",ISNA(VLOOKUP($D20,'Traceability Matrix'!D$2:D$500,1,FALSE))) -> FALSE
D21: REQ_M4_SCST_18 | E21: All symbol names should start with "m4_scst_" prefix for avoiding compilation conflicts when compiling and linking with other products. | F21: Reviewed | G21: Interface | H21: No | J21: BLN_SCST_M4_S32K144_RTM_1.0.3 | K21: High | L21: Yes | M21: No | N21: Review | O21: No | P21: No | Q21: No | AA21: =IF(MATCH(D21,$D$4:$D$47,0) <> (ROW() - 3), TRUE, FALSE) -> FALSE | AB21: =NOT(IF(OR(NOT(ISBLANK(A21)),NOT(ISBLANK(C21))),IF(AND(EXACT(H21,"Yes"),NOT(ISBLANK(I21))),"TRUE","FALSE"),IF(OR(EXACT(H21,"Yes"),NOT(ISBLANK(I21))),"FALSE","TRUE"))) -> FALSE | AC21: =IF(ISBLANK(D21),"FALSE",ISNA(VLOOKUP($D21,'Traceability Matrix'!D$2:D$500,1,FALSE))) -> FALSE
D22: REQ_M4_SCST_19 | E22: Latency, with which interrupt request reaches user application / OS ISR, shall not exceed 50 microseconds. Maximum chip frequency. Caches enabled but invalidated before execution of every core test. | F22: Reviewed | G22: Performance | H22: No | J22: BLN_SCST_M4_S32K144_RTM_1.0.3 | K22: High | L22: Yes | M22: Yes | N22: Test case | O22: No | P22: No | Q22: No | R22: According to the customer requirement provided in the e-mail from: Wed 3/18/2015 11:54 AM. | AA22: =IF(MATCH(D22,$D$4:$D$47,0) <> (ROW() - 3), TRUE, FALSE) -> FALSE | AB22: =NOT(IF(OR(NOT(ISBLANK(A22)),NOT(ISBLANK(C22))),IF(AND(EXACT(H22,"Yes"),NOT(ISBLANK(I22))),"TRUE","FALSE"),IF(OR(EXACT(H22,"Yes"),NOT(ISBLANK(I22))),"FALSE","TRUE"))) -> FALSE | AC22: =IF(ISBLANK(D22),"FALSE",ISNA(VLOOKUP($D22,'Traceability Matrix'!D$2:D$500,1,FALSE))) -> FALSE
D23: REQ_M4_SCST_20 | E23: SCST library shall provide mechanism for error injection into execution of core tests. | F23: Reviewed | G23: Functional | H23: No | J23: BLN_SCST_M4_S32K144_RTM_1.0.3 | K23: High | L23: Yes | M23: Yes | N23: Test case | O23: No | P23: No | Q23: No | R23: According to the customer requirement provided in the e-mail from: Fri 3/20/2015 1:51 PM. | AA23: =IF(MATCH(D23,$D$4:$D$47,0) <> (ROW() - 3), TRUE, FALSE) -> FALSE | AB23: =NOT(IF(OR(NOT(ISBLANK(A23)),NOT(ISBLANK(C23))),IF(AND(EXACT(H23,"Yes"),NOT(ISBLANK(I23))),"TRUE","FALSE"),IF(OR(EXACT(H23,"Yes"),NOT(ISBLANK(I23))),"FALSE","TRUE"))) -> FALSE | AC23: =IF(ISBLANK(D23),"FALSE",ISNA(VLOOKUP($D23,'Traceability Matrix'!D$2:D$500,1,FALSE))) -> FALSE
D24: REQ_M4_SCST_21 | E24: SCST library shall provide the function prototype "uint32_t m4_scst_execute_core_tests(uint32_t start, uint32_t end)" for invocation atomic tests. | F24: Reviewed | G24: Interface | H24: No | J24: BLN_SCST_M4_S32K144_RTM_1.0.3 | K24: High | L24: Yes | M24: No | N24: Review | O24: No | P24: No | Q24: No | R24: According to the customer requirement provided in the Excel sheet SCST_FSC_ChgF1.xlsm rev. 1.3 17th April 2015, and confirmed by Freescale. | AA24: =IF(MATCH(D24,$D$4:$D$47,0) <> (ROW() - 3), TRUE, FALSE) -> FALSE | AB24: =NOT(IF(OR(NOT(ISBLANK(A24)),NOT(ISBLANK(C24))),IF(AND(EXACT(H24,"Yes"),NOT(ISBLANK(I24))),"TRUE","FALSE"),IF(OR(EXACT(H24,"Yes"),NOT(ISBLANK(I24))),"FALSE","TRUE"))) -> FALSE | AC24: =IF(ISBLANK(D24),"FALSE",ISNA(VLOOKUP($D24,'Traceability Matrix'!D$2:D$500,1,FALSE))) -> FALSE
D25: REQ_M4_SCST_22 | E25: Descriptors of core tests will be groupped in the internal array in a way to minimise fragmentation of the test groups requiring invocation in the "kernel" mode (idealy only one group of such tests should exist to be references with a single pair of "start" and "end" parameter values). | F25: Reviewed | G25: Interface | H25: No | J25: BLN_SCST_M4_S32K144_RTM_1.0.3 | K25: High | L25: Yes | M25: Yes | N25: Test case | O25: No | P25: No | Q25: No | R25: According to the customer requirement provided in the Excel sheet SCST_FSC_ChgF1.xlsm rev. 1.3 17th April 2015, and confirmed by Freescale. | AA25: =IF(MATCH(D25,$D$4:$D$47,0) <> (ROW() - 3), TRUE, FALSE) -> FALSE | AB25: =NOT(IF(OR(NOT(ISBLANK(A25)),NOT(ISBLANK(C25))),IF(AND(EXACT(H25,"Yes"),NOT(ISBLANK(I25))),"TRUE","FALSE"),IF(OR(EXACT(H25,"Yes"),NOT(ISBLANK(I25))),"FALSE","TRUE"))) -> FALSE | AC25: =IF(ISBLANK(D25),"FALSE",ISNA(VLOOKUP($D25,'Traceability Matrix'!D$2:D$500,1,FALSE))) -> FALSE
D26: REQ_M4_SCST_23 | E26: Descriptors of core tests will be groupped in the internal array in a way to minimise fragmentation of the test groups requiring invocation in the "user" mode (idealy only one group of such tests should exist to be references with a single pair of "start" and "end" parameter values). | F26: Reviewed | G26: Interface | H26: No | J26: BLN_SCST_M4_S32K144_RTM_1.0.3 | K26: High | L26: Yes | M26: Yes | N26: Test case | O26: No | P26: No | Q26: No | R26: According to the customer requirement provided in the Excel sheet SCST_FSC_ChgF1.xlsm rev. 1.3 17th April 2015, and confirmed by Freescale. | AA26: =IF(MATCH(D26,$D$4:$D$47,0) <> (ROW() - 3), TRUE, FALSE) -> FALSE | AB26: =NOT(IF(OR(NOT(ISBLANK(A26)),NOT(ISBLANK(C26))),IF(AND(EXACT(H26,"Yes"),NOT(ISBLANK(I26))),"TRUE","FALSE"),IF(OR(EXACT(H26,"Yes"),NOT(ISBLANK(I26))),"FALSE","TRUE"))) -> FALSE | AC26: =IF(ISBLANK(D26),"FALSE",ISNA(VLOOKUP($D26,'Traceability Matrix'!D$2:D$500,1,FALSE))) -> FALSE
D27: REQ_M4_SCST_24 | E27: Execution time for one atomic coretest function shall not exceed 300 Microseconds at maximum chip frequency. Caches enabled but invalidated before execution of every core test. | F27: Reviewed | G27: Performance | H27: No | J27: BLN_SCST_M4_S32K144_RTM_1.0.3 | K27: High | L27: Yes | M27: Yes | N27: Test case | O27: No | P27: No | Q27: No | R27: According to the customer requirement provided in the Excel sheet SCST_FSC_ChgF1.xlsm rev. 1.3 17th April 2015, and confirmed by Freescale. | AA27: =IF(MATCH(D27,$D$4:$D$47,0) <> (ROW() - 3), TRUE, FALSE) -> FALSE | AB27: =NOT(IF(OR(NOT(ISBLANK(A27)),NOT(ISBLANK(C27))),IF(AND(EXACT(H27,"Yes"),NOT(ISBLANK(I27))),"TRUE","FALSE"),IF(OR(EXACT(H27,"Yes"),NOT(ISBLANK(I27))),"FALSE","TRUE"))) -> FALSE | AC27: =IF(ISBLANK(D27),"FALSE",ISNA(VLOOKUP($D27,'Traceability Matrix'!D$2:D$500,1,FALSE))) -> FALSE
D28: REQ_M4_SCST_25 | E28: Global (static) RAM consumption by load and store test should not exceed 64 Bytes. The tests must be executed in Kernel mode, to allow granularity in the range of bytes. | F28: Reviewed | G28: Performance | H28: No | J28: BLN_SCST_M4_S32K144_RTM_1.0.3 | K28: High | L28: Yes | M28: No | N28: Review | O28: No | P28: No | Q28: No | R28: According to the customer requirement provided in the Excel sheet SCST_FSC_ChgF1.xlsm rev. 1.3 17th April 2015, and confirmed by Freescale. | AA28: =IF(MATCH(D28,$D$4:$D$47,0) <> (ROW() - 3), TRUE, FALSE) -> FALSE | AB28: =NOT(IF(OR(NOT(ISBLANK(A28)),NOT(ISBLANK(C28))),IF(AND(EXACT(H28,"Yes"),NOT(ISBLANK(I28))),"TRUE","FALSE"),IF(OR(EXACT(H28,"Yes"),NOT(ISBLANK(I28))),"FALSE","TRUE"))) -> FALSE | AC28: =IF(ISBLANK(D28),"FALSE",ISNA(VLOOKUP($D28,'Traceability Matrix'!D$2:D$500,1,FALSE))) -> FALSE
D29: REQ_M4_SCST_26 | E29: SCST package has to be implemented for ARM Cortex-M4 core integrated within S32K144 device. | F29: Reviewed | G29: Functional | H29: No | J29: BLN_SCST_M4_S32K144_RTM_1.0.3 | K29: High | L29: Yes | M29: No | N29: Review | O29: No | P29: No | Q29: No | AA29: =IF(MATCH(D29,$D$4:$D$47,0) <> (ROW() - 3), TRUE, FALSE) -> FALSE | AB29: =NOT(IF(OR(NOT(ISBLANK(A29)),NOT(ISBLANK(C29))),IF(AND(EXACT(H29,"Yes"),NOT(ISBLANK(I29))),"TRUE","FALSE"),IF(OR(EXACT(H29,"Yes"),NOT(ISBLANK(I29))),"FALSE","TRUE"))) -> FALSE | AC29: =IF(ISBLANK(D29),"FALSE",ISNA(VLOOKUP($D29,'Traceability Matrix'!D$2:D$500,1,FALSE))) -> FALSE
D30: REQ_M4_SCST_27 | E30: MSG SW quality processes have to be applied to the core self test products development. | F30: Reviewed | G30: Non−functional | H30: No | J30: BLN_SCST_M4_S32K144_RTM_1.0.3 | K30: High | L30: Yes | M30: No | N30: Review | O30: No | P30: No | Q30: No | AA30: =IF(MATCH(D30,$D$4:$D$47,0) <> (ROW() - 3), TRUE, FALSE) -> FALSE | AB30: =NOT(IF(OR(NOT(ISBLANK(A30)),NOT(ISBLANK(C30))),IF(AND(EXACT(H30,"Yes"),NOT(ISBLANK(I30))),"TRUE","FALSE"),IF(OR(EXACT(H30,"Yes"),NOT(ISBLANK(I30))),"FALSE","TRUE"))) -> FALSE | AC30: =IF(ISBLANK(D30),"FALSE",ISNA(VLOOKUP($D30,'Traceability Matrix'!D$2:D$500,1,FALSE))) -> FALSE
D31: REQ_M4_SCST_28 | E31: Development of the SCST library shall be compliant to ASIL B level requirements. | F31: Reviewed | G31: Non−functional | H31: No | J31: BLN_SCST_M4_S32K144_RTM_1.0.3 | K31: High | L31: Yes | M31: No | N31: Review | O31: No | P31: No | Q31: No | AA31: =IF(MATCH(D31,$D$4:$D$47,0) <> (ROW() - 3), TRUE, FALSE) -> FALSE | AB31: =NOT(IF(OR(NOT(ISBLANK(A31)),NOT(ISBLANK(C31))),IF(AND(EXACT(H31,"Yes"),NOT(ISBLANK(I31))),"TRUE","FALSE"),IF(OR(EXACT(H31,"Yes"),NOT(ISBLANK(I31))),"FALSE","TRUE"))) -> FALSE | AC31: =IF(ISBLANK(D31),"FALSE",ISNA(VLOOKUP($D31,'Traceability Matrix'!D$2:D$500,1,FALSE))) -> FALSE
D32: REQ_M4_SCST_29 | E32: Freescale/NXP copyright text (given in Appendix A) has to be included in C and assembly source code. | F32: Reviewed | G32: Non−functional | H32: No | J32: BLN_SCST_M4_S32K144_RTM_1.0.3 | K32: High | L32: Yes | M32: No | N32: Review | O32: No | P32: No | Q32: No | AA32: =IF(MATCH(D32,$D$4:$D$47,0) <> (ROW() - 3), TRUE, FALSE) -> FALSE | AB32: =NOT(IF(OR(NOT(ISBLANK(A32)),NOT(ISBLANK(C32))),IF(AND(EXACT(H32,"Yes"),NOT(ISBLANK(I32))),"TRUE","FALSE"),IF(OR(EXACT(H32,"Yes"),NOT(ISBLANK(I32))),"FALSE","TRUE"))) -> FALSE | AC32: =IF(ISBLANK(D32),"FALSE",ISNA(VLOOKUP($D32,'Traceability Matrix'!D$2:D$500,1,FALSE))) -> FALSE
D33: REQ_M4_SCST_30 | E33: Text of the license agreement v1.6 has to be incorporated into the self-extracting archive file. Installation process should complete successfully only when a user reads and accepts terms and conditions of the provided license agreement. | F33: Reviewed | G33: Non−functional | H33: No | J33: BLN_SCST_M4_S32K144_RTM_1.0.3 | K33: High | L33: Yes | M33: No | N33: Review | O33: No | P33: No | Q33: No | AA33: =IF(MATCH(D33,$D$4:$D$47,0) <> (ROW() - 3), TRUE, FALSE) -> FALSE | AB33: =NOT(IF(OR(NOT(ISBLANK(A33)),NOT(ISBLANK(C33))),IF(AND(EXACT(H33,"Yes"),NOT(ISBLANK(I33))),"TRUE","FALSE"),IF(OR(EXACT(H33,"Yes"),NOT(ISBLANK(I33))),"FALSE","TRUE"))) -> FALSE | AC33: =IF(ISBLANK(D33),"FALSE",ISNA(VLOOKUP($D33,'Traceability Matrix'!D$2:D$500,1,FALSE))) -> FALSE
D34: REQ_M4_SCST_31 | E34: The SCST package has to be compilable with GreenHills compiler v. 2017.1.4 and v.2017.5.4 | F34: Reviewed | G34: Non−functional | H34: No | J34: BLN_SCST_M4_S32K144_RTM_1.0.5 | K34: High | L34: Yes | M34: No | N34: Review | O34: No | P34: No | Q34: No | AA34: =IF(MATCH(D34,$D$4:$D$47,0) <> (ROW() - 3), TRUE, FALSE) -> FALSE | AB34: =NOT(IF(OR(NOT(ISBLANK(A34)),NOT(ISBLANK(C34))),IF(AND(EXACT(H34,"Yes"),NOT(ISBLANK(I34))),"TRUE","FALSE"),IF(OR(EXACT(H34,"Yes"),NOT(ISBLANK(I34))),"FALSE","TRUE"))) -> FALSE | AC34: =IF(ISBLANK(D34),"FALSE",ISNA(VLOOKUP($D34,'Traceability Matrix'!D$2:D$500,1,FALSE))) -> FALSE
D35: REQ_M4_SCST_32 | E35: SCST package should be delivered in a form of source/assembly code, or object code if requested . | F35: Reviewed | G35: Non−functional | H35: No | J35: BLN_SCST_M4_S32K144_RTM_1.0.3 | K35: High | L35: Yes | M35: No | N35: Review | O35: No | P35: No | Q35: No | AA35: =IF(MATCH(D35,$D$4:$D$47,0) <> (ROW() - 3), TRUE, FALSE) -> FALSE | AB35: =NOT(IF(OR(NOT(ISBLANK(A35)),NOT(ISBLANK(C35))),IF(AND(EXACT(H35,"Yes"),NOT(ISBLANK(I35))),"TRUE","FALSE"),IF(OR(EXACT(H35,"Yes"),NOT(ISBLANK(I35))),"FALSE","TRUE"))) -> FALSE | AC35: =IF(ISBLANK(D35),"FALSE",ISNA(VLOOKUP($D35,'Traceability Matrix'!D$2:D$500,1,FALSE))) -> FALSE
D36: REQ_M4_SCST_33 | E36: Installation package should be created in a form of self-extracting archive file, generated by the “Freescale Archive Packer” utility. | F36: Reviewed | G36: Non−functional | H36: No | J36: BLN_SCST_M4_S32K144_RTM_1.0.3 | K36: High | L36: Yes | M36: No | N36: Review | O36: No | P36: No | Q36: No | AA36: =IF(MATCH(D36,$D$4:$D$47,0) <> (ROW() - 3), TRUE, FALSE) -> FALSE | AB36: =NOT(IF(OR(NOT(ISBLANK(A36)),NOT(ISBLANK(C36))),IF(AND(EXACT(H36,"Yes"),NOT(ISBLANK(I36))),"TRUE","FALSE"),IF(OR(EXACT(H36,"Yes"),NOT(ISBLANK(I36))),"FALSE","TRUE"))) -> FALSE | AC36: =IF(ISBLANK(D36),"FALSE",ISNA(VLOOKUP($D36,'Traceability Matrix'!D$2:D$500,1,FALSE))) -> FALSE
D37: REQ_M4_SCST_34 | E37: The SCST package has to be compilable with IAR compiler v. 8.11.2. | F37: Reviewed | G37: Non−functional | H37: No | J37: BLN_SCST_M4_S32K144_RTM_1.0.4 | K37: High | L37: Yes | M37: No | N37: Review | O37: No | P37: No | Q37: No | AA37: =IF(MATCH(D37,$D$4:$D$47,0) <> (ROW() - 3), TRUE, FALSE) -> FALSE | AB37: =NOT(IF(OR(NOT(ISBLANK(A37)),NOT(ISBLANK(C37))),IF(AND(EXACT(H37,"Yes"),NOT(ISBLANK(I37))),"TRUE","FALSE"),IF(OR(EXACT(H37,"Yes"),NOT(ISBLANK(I37))),"FALSE","TRUE"))) -> FALSE | AC37: =IF(ISBLANK(D37),"FALSE",ISNA(VLOOKUP($D37,'Traceability Matrix'!D$2:D$500,1,FALSE))) -> FALSE
D38: REQ_M4_SCST_35 | E38: The SCST package has to be compilable with GCC compiler for ARM v. 6.3.1 20170509. | F38: Reviewed | G38: Non−functional | H38: No | J38: BLN_SCST_M4_S32K144_RTM_1.0.4 | K38: High | L38: Yes | M38: No | N38: Review | O38: No | P38: No | Q38: No | AA38: =IF(MATCH(D38,$D$4:$D$47,0) <> (ROW() - 3), TRUE, FALSE) -> FALSE | AB38: =NOT(IF(OR(NOT(ISBLANK(A38)),NOT(ISBLANK(C38))),IF(AND(EXACT(H38,"Yes"),NOT(ISBLANK(I38))),"TRUE","FALSE"),IF(OR(EXACT(H38,"Yes"),NOT(ISBLANK(I38))),"FALSE","TRUE"))) -> FALSE | AC38: =IF(ISBLANK(D38),"FALSE",ISNA(VLOOKUP($D38,'Traceability Matrix'!D$2:D$500,1,FALSE))) -> FALSE
D39: REQ_M4_SCST_36 | E39: The SCST Library shall be able to exetute core tests either for SP_main (MSP) active cofiguration or SP_process (PSP) active configuration. | F39: Reviewed | G39: Functional | H39: No | J39: BLN_SCST_M4_S32K144_RTM_1.0.3 | K39: High | L39: Yes | M39: Yes | N39: Test case | O39: No | P39: No | Q39: No | AA39: =IF(MATCH(D39,$D$4:$D$47,0) <> (ROW() - 3), TRUE, FALSE) -> FALSE | AB39: =NOT(IF(OR(NOT(ISBLANK(A39)),NOT(ISBLANK(C39))),IF(AND(EXACT(H39,"Yes"),NOT(ISBLANK(I39))),"TRUE","FALSE"),IF(OR(EXACT(H39,"Yes"),NOT(ISBLANK(I39))),"FALSE","TRUE"))) -> FALSE | AC39: =IF(ISBLANK(D39),"FALSE",ISNA(VLOOKUP($D39,'Traceability Matrix'!D$2:D$500,1,FALSE))) -> FALSE
C40: M4_SCST_SA_Req03 | D40: REQ_M4_SCST_37 | E40: Application should use aggregated test result for making test completion and test passed/test failed decision. Safety measure is expected to be implemented on application side. | F40: Reviewed | G40: External | H40: Yes | I40: B | J40: BLN_SCST_M4_S32K144_RTM_1.0.5 | K40: High | L40: Yes | M40: Yes | N40: Review | O40: No | P40: No | Q40: No | AA40: =IF(MATCH(D40,$D$4:$D$47,0) <> (ROW() - 3), TRUE, FALSE) -> FALSE | AB40: =NOT(IF(OR(NOT(ISBLANK(A40)),NOT(ISBLANK(C40))),IF(AND(EXACT(H40,"Yes"),NOT(ISBLANK(I40))),"TRUE","FALSE"),IF(OR(EXACT(H40,"Yes"),NOT(ISBLANK(I40))),"FALSE","TRUE"))) -> FALSE | AC40: =IF(ISBLANK(D40),"FALSE",ISNA(VLOOKUP($D40,'Traceability Matrix'!D$2:D$500,1,FALSE))) -> FALSE
...

Sheet Traceability Matrix
A1: Software Code | B1: Design Element | C1: Requirement status | D1: Requirement ID | E1: Verification Criteria | F1: Test ID | G1: Review result
A2: All code | B2: All elements | C2: =Requirements_Analysis!F4 -> Reviewed | D2: =Requirements_Analysis!D4 -> REQ_M4_SCST_01 | E2: =Requirements_Analysis!N4 -> Review | F2: n/a | G2: Reviewed | I2: =IF(AND(NOT(ISBLANK(D2)),NOT(EXACT(C2,"Canceled"))),IF(EXACT(E2,"Review"),NOT(ISBLANK(G2)),"Not relevant"),"Not relevant") -> TRUE | J2: =IF(AND(NOT(ISBLANK(D2)),NOT(EXACT(C2,"Canceled"))),IF(EXACT(E2,"Test case"),NOT(ISBLANK(F2)),"Not relevant"),"Not relevant") -> Not relevant | K2: =OR(EXACT(I2,"FALSE"),EXACT(J2,"FALSE")) -> FALSE | L2: =IF(OR(NOT(ISBLANK(D2)),NOT(EXACT(C2,"Canceled"))),OR(ISBLANK(B2),ISBLANK(A2)),"FALSE") -> FALSE
A3: m4_scst_test_shell.c | B3: "SCST execution" diagram | C3: =Requirements_Analysis!F5 -> Reviewed | D3: =Requirements_Analysis!D5 -> REQ_M4_SCST_02 | E3: =Requirements_Analysis!N5 -> Test case | F3: M4_SCST_UT_T10 | I3: =IF(AND(NOT(ISBLANK(D3)),NOT(EXACT(C3,"Canceled"))),IF(EXACT(E3,"Review"),NOT(ISBLANK(G3)),"Not relevant"),"Not relevant") -> Not relevant | J3: =IF(AND(NOT(ISBLANK(D3)),NOT(EXACT(C3,"Canceled"))),IF(EXACT(E3,"Test case"),NOT(ISBLANK(F3)),"Not relevant"),"Not relevant") -> TRUE | K3: =OR(EXACT(I3,"FALSE"),EXACT(J3,"FALSE")) -> FALSE | L3: =IF(OR(NOT(ISBLANK(D3)),NOT(EXACT(C3,"Canceled"))),OR(ISBLANK(B3),ISBLANK(A3)),"FALSE") -> FALSE
A4: m4_scst_test_shell.c | B4: n/a | C4: =Requirements_Analysis!F6 -> Reviewed | D4: =Requirements_Analysis!D6 -> REQ_M4_SCST_03 | E4: =Requirements_Analysis!N6 -> Test case | F4: M4_SCST_UT_T13 | I4: =IF(AND(NOT(ISBLANK(D4)),NOT(EXACT(C4,"Canceled"))),IF(EXACT(E4,"Review"),NOT(ISBLANK(G4)),"Not relevant"),"Not relevant") -> Not relevant | J4: =IF(AND(NOT(ISBLANK(D4)),NOT(EXACT(C4,"Canceled"))),IF(EXACT(E4,"Test case"),NOT(ISBLANK(F4)),"Not relevant"),"Not relevant") -> TRUE | K4: =OR(EXACT(I4,"FALSE"),EXACT(J4,"FALSE")) -> FALSE | L4: =IF(OR(NOT(ISBLANK(D4)),NOT(EXACT(C4,"Canceled"))),OR(ISBLANK(B4),ISBLANK(A4)),"FALSE") -> FALSE
A5: m4_scst_lib.s | B5: n/a | C5: =Requirements_Analysis!F7 -> Reviewed | D5: =Requirements_Analysis!D7 -> REQ_M4_SCST_04 | E5: =Requirements_Analysis!N7 -> Test case | F5: M4_SCST_UT_T01 | I5: =IF(AND(NOT(ISBLANK(D5)),NOT(EXACT(C5,"Canceled"))),IF(EXACT(E5,"Review"),NOT(ISBLANK(G5)),"Not relevant"),"Not relevant") -> Not relevant | J5: =IF(AND(NOT(ISBLANK(D5)),NOT(EXACT(C5,"Canceled"))),IF(EXACT(E5,"Test case"),NOT(ISBLANK(F5)),"Not relevant"),"Not relevant") -> TRUE | K5: =OR(EXACT(I5,"FALSE"),EXACT(J5,"FALSE")) -> FALSE | L5: =IF(OR(NOT(ISBLANK(D5)),NOT(EXACT(C5,"Canceled"))),OR(ISBLANK(B5),ISBLANK(A5)),"FALSE") -> FALSE
A6: m4_scst_test_shell.c | B6: n/a | C6: =Requirements_Analysis!F8 -> Reviewed | D6: =Requirements_Analysis!D8 -> REQ_M4_SCST_05 | E6: =Requirements_Analysis!N8 -> Test case | F6: M4_SCST_UT_T01 | I6: =IF(AND(NOT(ISBLANK(D6)),NOT(EXACT(C6,"Canceled"))),IF(EXACT(E6,"Review"),NOT(ISBLANK(G6)),"Not relevant"),"Not relevant") -> Not relevant | J6: =IF(AND(NOT(ISBLANK(D6)),NOT(EXACT(C6,"Canceled"))),IF(EXACT(E6,"Test case"),NOT(ISBLANK(F6)),"Not relevant"),"Not relevant") -> TRUE | K6: =OR(EXACT(I6,"FALSE"),EXACT(J6,"FALSE")) -> FALSE | L6: =IF(OR(NOT(ISBLANK(D6)),NOT(EXACT(C6,"Canceled"))),OR(ISBLANK(B6),ISBLANK(A6)),"FALSE") -> FALSE
A7: m4_scst_test_shell.c | B7: n/a | C7: =Requirements_Analysis!F9 -> Reviewed | D7: =Requirements_Analysis!D9 -> REQ_M4_SCST_06 | E7: =Requirements_Analysis!N9 -> Test case | F7: M4_SCST_UT_T12 | I7: =IF(AND(NOT(ISBLANK(D7)),NOT(EXACT(C7,"Canceled"))),IF(EXACT(E7,"Review"),NOT(ISBLANK(G7)),"Not relevant"),"Not relevant") -> Not relevant | J7: =IF(AND(NOT(ISBLANK(D7)),NOT(EXACT(C7,"Canceled"))),IF(EXACT(E7,"Test case"),NOT(ISBLANK(F7)),"Not relevant"),"Not relevant") -> TRUE | K7: =OR(EXACT(I7,"FALSE"),EXACT(J7,"FALSE")) -> FALSE | L7: =IF(OR(NOT(ISBLANK(D7)),NOT(EXACT(C7,"Canceled"))),OR(ISBLANK(B7),ISBLANK(A7)),"FALSE") -> FALSE
A8: m4_scst_test_shell.c m4_scst_data.c | B8: n/a | C8: =Requirements_Analysis!F10 -> Reviewed | D8: =Requirements_Analysis!D10 -> REQ_M4_SCST_07 | E8: =Requirements_Analysis!N10 -> Review | F8: n/a | G8: Reviewed | I8: =IF(AND(NOT(ISBLANK(D8)),NOT(EXACT(C8,"Canceled"))),IF(EXACT(E8,"Review"),NOT(ISBLANK(G8)),"Not relevant"),"Not relevant") -> TRUE | J8: =IF(AND(NOT(ISBLANK(D8)),NOT(EXACT(C8,"Canceled"))),IF(EXACT(E8,"Test case"),NOT(ISBLANK(F8)),"Not relevant"),"Not relevant") -> Not relevant | K8: =OR(EXACT(I8,"FALSE"),EXACT(J8,"FALSE")) -> FALSE | L8: =IF(OR(NOT(ISBLANK(D8)),NOT(EXACT(C8,"Canceled"))),OR(ISBLANK(B8),ISBLANK(A8)),"FALSE") -> FALSE
A9: m4_scst_test_shell.c m4_scst_test_shell.h | B9: n/a | C9: =Requirements_Analysis!F11 -> Reviewed | D9: =Requirements_Analysis!D11 -> REQ_M4_SCST_08 | E9: =Requirements_Analysis!N11 -> Test case | F9: M4_SCST_UT_T09 M4_SCST_UT_T11 M4_SCST_UT_T12 M4_SCST_UT_T13 | I9: =IF(AND(NOT(ISBLANK(D9)),NOT(EXACT(C9,"Canceled"))),IF(EXACT(E9,"Review"),NOT(ISBLANK(G9)),"Not relevant"),"Not relevant") -> Not relevant | J9: =IF(AND(NOT(ISBLANK(D9)),NOT(EXACT(C9,"Canceled"))),IF(EXACT(E9,"Test case"),NOT(ISBLANK(F9)),"Not relevant"),"Not relevant") -> TRUE | K9: =OR(EXACT(I9,"FALSE"),EXACT(J9,"FALSE")) -> FALSE | L9: =IF(OR(NOT(ISBLANK(D9)),NOT(EXACT(C9,"Canceled"))),OR(ISBLANK(B9),ISBLANK(A9)),"FALSE") -> FALSE
A10: m4_scst_exception_wrappers.s | B10: "SCST_unexpected_interrupt_handling" diagram | C10: =Requirements_Analysis!F12 -> Reviewed | D10: =Requirements_Analysis!D12 -> REQ_M4_SCST_09 | E10: =Requirements_Analysis!N12 -> Test case | F10: M4_SCST_UT_T16 M4_SCST_UT_T17 | I10: =IF(AND(NOT(ISBLANK(D10)),NOT(EXACT(C10,"Canceled"))),IF(EXACT(E10,"Review"),NOT(ISBLANK(G10)),"Not relevant"),"Not relevant") -> Not relevant | J10: =IF(AND(NOT(ISBLANK(D10)),NOT(EXACT(C10,"Canceled"))),IF(EXACT(E10,"Test case"),NOT(ISBLANK(F10)),"Not relevant"),"Not relevant") -> TRUE | K10: =OR(EXACT(I10,"FALSE"),EXACT(J10,"FALSE")) -> FALSE | L10: =IF(OR(NOT(ISBLANK(D10)),NOT(EXACT(C10,"Canceled"))),OR(ISBLANK(B10),ISBLANK(A10)),"FALSE") -> FALSE
A11: m4_scst_test_shell.c m4_scst_exception_wrappers.s | B11: n/a | C11: =Requirements_Analysis!F13 -> Reviewed | D11: =Requirements_Analysis!D13 -> REQ_M4_SCST_10 | E11: =Requirements_Analysis!N13 -> Test case | F11: M4_SCST_UT_T07 M4_SCST_UT_T16 | I11: =IF(AND(NOT(ISBLANK(D11)),NOT(EXACT(C11,"Canceled"))),IF(EXACT(E11,"Review"),NOT(ISBLANK(G11)),"Not relevant"),"Not relevant") -> Not relevant | J11: =IF(AND(NOT(ISBLANK(D11)),NOT(EXACT(C11,"Canceled"))),IF(EXACT(E11,"Test case"),NOT(ISBLANK(F11)),"Not relevant"),"Not relevant") -> TRUE | K11: =OR(EXACT(I11,"FALSE"),EXACT(J11,"FALSE")) -> FALSE | L11: =IF(OR(NOT(ISBLANK(D11)),NOT(EXACT(C11,"Canceled"))),OR(ISBLANK(B11),ISBLANK(A11)),"FALSE") -> FALSE
A12: m4_scst_test_shell.c m4_scst_exception_wrappers.s | B12: n/a | C12: =Requirements_Analysis!F14 -> Reviewed | D12: =Requirements_Analysis!D14 -> REQ_M4_SCST_11 | E12: =Requirements_Analysis!N14 -> Test case | F12: M4_SCST_UT_T07 M4_SCST_UT_T09 M4_SCST_UT_T16 | I12: =IF(AND(NOT(ISBLANK(D12)),NOT(EXACT(C12,"Canceled"))),IF(EXACT(E12,"Review"),NOT(ISBLANK(G12)),"Not relevant"),"Not relevant") -> Not relevant | J12: =IF(AND(NOT(ISBLANK(D12)),NOT(EXACT(C12,"Canceled"))),IF(EXACT(E12,"Test case"),NOT(ISBLANK(F12)),"Not relevant"),"Not relevant") -> TRUE | K12: =OR(EXACT(I12,"FALSE"),EXACT(J12,"FALSE")) -> FALSE | L12: =IF(OR(NOT(ISBLANK(D12)),NOT(EXACT(C12,"Canceled"))),OR(ISBLANK(B12),ISBLANK(A12)),"FALSE") -> FALSE
A13: m4_scst_lib.s | B13: "SCST_registers_storing_restoring" diagram | C13: =Requirements_Analysis!F15 -> Reviewed | D13: =Requirements_Analysis!D15 -> REQ_M4_SCST_12 | E13: =Requirements_Analysis!N15 -> Test case | F13: M4_SCST_UT_T02 M4_SCST_UT_T15 | I13: =IF(AND(NOT(ISBLANK(D13)),NOT(EXACT(C13,"Canceled"))),IF(EXACT(E13,"Review"),NOT(ISBLANK(G13)),"Not relevant"),"Not relevant") -> Not relevant | J13: =IF(AND(NOT(ISBLANK(D13)),NOT(EXACT(C13,"Canceled"))),IF(EXACT(E13,"Test case"),NOT(ISBLANK(F13)),"Not relevant"),"Not relevant") -> TRUE | K13: =OR(EXACT(I13,"FALSE"),EXACT(J13,"FALSE")) -> FALSE | L13: =IF(OR(NOT(ISBLANK(D13)),NOT(EXACT(C13,"Canceled"))),OR(ISBLANK(B13),ISBLANK(A13)),"FALSE") -> FALSE
A14: All code | B14: All elements | C14: =Requirements_Analysis!F16 -> Canceled | D14: =Requirements_Analysis!D16 -> REQ_M4_SCST_13 | E14: =Requirements_Analysis!N16 -> n/a | F14: M4_SCST_EXECUTION_TIME_REPORT_FLASH | I14: =IF(AND(NOT(ISBLANK(D14)),NOT(EXACT(C14,"Canceled"))),IF(EXACT(E14,"Review"),NOT(ISBLANK(G14)),"Not relevant"),"Not relevant") -> Not relevant | J14: =IF(AND(NOT(ISBLANK(D14)),NOT(EXACT(C14,"Canceled"))),IF(EXACT(E14,"Test case"),NOT(ISBLANK(F14)),"Not relevant"),"Not relevant") -> Not relevant | K14: =OR(EXACT(I14,"FALSE"),EXACT(J14,"FALSE")) -> FALSE | L14: =IF(OR(NOT(ISBLANK(D14)),NOT(EXACT(C14,"Canceled"))),OR(ISBLANK(B14),ISBLANK(A14)),"FALSE") -> FALSE
A15: m4_scst_test_shell.c | B15: n/a | C15: =Requirements_Analysis!F17 -> Reviewed | D15: =Requirements_Analysis!D17 -> REQ_M4_SCST_14 | E15: =Requirements_Analysis!N17 -> Test case | F15: M4_SCST_UT_T05 | I15: =IF(AND(NOT(ISBLANK(D15)),NOT(EXACT(C15,"Canceled"))),IF(EXACT(E15,"Review"),NOT(ISBLANK(G15)),"Not relevant"),"Not relevant") -> Not relevant | J15: =IF(AND(NOT(ISBLANK(D15)),NOT(EXACT(C15,"Canceled"))),IF(EXACT(E15,"Test case"),NOT(ISBLANK(F15)),"Not relevant"),"Not relevant") -> TRUE | K15: =OR(EXACT(I15,"FALSE"),EXACT(J15,"FALSE")) -> FALSE | L15: =IF(OR(NOT(ISBLANK(D15)),NOT(EXACT(C15,"Canceled"))),OR(ISBLANK(B15),ISBLANK(A15)),"FALSE") -> FALSE
A16: All code | B16: All elements | C16: =Requirements_Analysis!F18 -> Reviewed | D16: =Requirements_Analysis!D18 -> REQ_M4_SCST_15 | E16: =Requirements_Analysis!N18 -> Review | F16: n/a | G16: Reviewed | I16: =IF(AND(NOT(ISBLANK(D16)),NOT(EXACT(C16,"Canceled"))),IF(EXACT(E16,"Review"),NOT(ISBLANK(G16)),"Not relevant"),"Not relevant") -> TRUE | J16: =IF(AND(NOT(ISBLANK(D16)),NOT(EXACT(C16,"Canceled"))),IF(EXACT(E16,"Test case"),NOT(ISBLANK(F16)),"Not relevant"),"Not relevant") -> Not relevant | K16: =OR(EXACT(I16,"FALSE"),EXACT(J16,"FALSE")) -> FALSE | L16: =IF(OR(NOT(ISBLANK(D16)),NOT(EXACT(C16,"Canceled"))),OR(ISBLANK(B16),ISBLANK(A16)),"FALSE") -> FALSE
A17: All code | B17: All elements | C17: =Requirements_Analysis!F19 -> Reviewed | D17: =Requirements_Analysis!D19 -> REQ_M4_SCST_16 | E17: =Requirements_Analysis!N19 -> Review | F17: n/a | G17: Reviewed | I17: =IF(AND(NOT(ISBLANK(D17)),NOT(EXACT(C17,"Canceled"))),IF(EXACT(E17,"Review"),NOT(ISBLANK(G17)),"Not relevant"),"Not relevant") -> TRUE | J17: =IF(AND(NOT(ISBLANK(D17)),NOT(EXACT(C17,"Canceled"))),IF(EXACT(E17,"Test case"),NOT(ISBLANK(F17)),"Not relevant"),"Not relevant") -> Not relevant | K17: =OR(EXACT(I17,"FALSE"),EXACT(J17,"FALSE")) -> FALSE | L17: =IF(OR(NOT(ISBLANK(D17)),NOT(EXACT(C17,"Canceled"))),OR(ISBLANK(B17),ISBLANK(A17)),"FALSE") -> FALSE
A18: All code | B18: All elements | C18: =Requirements_Analysis!F20 -> Reviewed | D18: =Requirements_Analysis!D20 -> REQ_M4_SCST_17 | E18: =Requirements_Analysis!N20 -> Review | F18: n/a | G18: Reviewed | I18: =IF(AND(NOT(ISBLANK(D18)),NOT(EXACT(C18,"Canceled"))),IF(EXACT(E18,"Review"),NOT(ISBLANK(G18)),"Not relevant"),"Not relevant") -> TRUE | J18: =IF(AND(NOT(ISBLANK(D18)),NOT(EXACT(C18,"Canceled"))),IF(EXACT(E18,"Test case"),NOT(ISBLANK(F18)),"Not relevant"),"Not relevant") -> Not relevant | K18: =OR(EXACT(I18,"FALSE"),EXACT(J18,"FALSE")) -> FALSE | L18: =IF(OR(NOT(ISBLANK(D18)),NOT(EXACT(C18,"Canceled"))),OR(ISBLANK(B18),ISBLANK(A18)),"FALSE") -> FALSE
A19: All code | B19: All elements | C19: =Requirements_Analysis!F21 -> Reviewed | D19: =Requirements_Analysis!D21 -> REQ_M4_SCST_18 | E19: =Requirements_Analysis!N21 -> Review | F19: n/a | G19: Reviewed | I19: =IF(AND(NOT(ISBLANK(D19)),NOT(EXACT(C19,"Canceled"))),IF(EXACT(E19,"Review"),NOT(ISBLANK(G19)),"Not relevant"),"Not relevant") -> TRUE | J19: =IF(AND(NOT(ISBLANK(D19)),NOT(EXACT(C19,"Canceled"))),IF(EXACT(E19,"Test case"),NOT(ISBLANK(F19)),"Not relevant"),"Not relevant") -> Not relevant | K19: =OR(EXACT(I19,"FALSE"),EXACT(J19,"FALSE")) -> FALSE | L19: =IF(OR(NOT(ISBLANK(D19)),NOT(EXACT(C19,"Canceled"))),OR(ISBLANK(B19),ISBLANK(A19)),"FALSE") -> FALSE
A20: All code | B20: All elements | C20: =Requirements_Analysis!F22 -> Reviewed | D20: =Requirements_Analysis!D22 -> REQ_M4_SCST_19 | E20: =Requirements_Analysis!N22 -> Test case | F20: M4_SCST_ATOMIC_LATENCY_TIME_REPORT_FLASH | I20: =IF(AND(NOT(ISBLANK(D20)),NOT(EXACT(C20,"Canceled"))),IF(EXACT(E20,"Review"),NOT(ISBLANK(G20)),"Not relevant"),"Not relevant") -> Not relevant | J20: =IF(AND(NOT(ISBLANK(D20)),NOT(EXACT(C20,"Canceled"))),IF(EXACT(E20,"Test case"),NOT(ISBLANK(F20)),"Not relevant"),"Not relevant") -> TRUE | K20: =OR(EXACT(I20,"FALSE"),EXACT(J20,"FALSE")) -> FALSE | L20: =IF(OR(NOT(ISBLANK(D20)),NOT(EXACT(C20,"Canceled"))),OR(ISBLANK(B20),ISBLANK(A20)),"FALSE") -> FALSE
A21: m4_scst_test_shell.c m4_scst_lib.s | B21: n/a | C21: =Requirements_Analysis!F23 -> Reviewed | D21: =Requirements_Analysis!D23 -> REQ_M4_SCST_20 | E21: =Requirements_Analysis!N23 -> Test case | F21: M4_SCST_UT_T06 | I21: =IF(AND(NOT(ISBLANK(D21)),NOT(EXACT(C21,"Canceled"))),IF(EXACT(E21,"Review"),NOT(ISBLANK(G21)),"Not relevant"),"Not relevant") -> Not relevant | J21: =IF(AND(NOT(ISBLANK(D21)),NOT(EXACT(C21,"Canceled"))),IF(EXACT(E21,"Test case"),NOT(ISBLANK(F21)),"Not relevant"),"Not relevant") -> TRUE | K21: =OR(EXACT(I21,"FALSE"),EXACT(J21,"FALSE")) -> FALSE | L21: =IF(OR(NOT(ISBLANK(D21)),NOT(EXACT(C21,"Canceled"))),OR(ISBLANK(B21),ISBLANK(A21)),"FALSE") -> FALSE
A22: m4_scst_test_shell.c m4_scst_data.c | B22: n/a | C22: =Requirements_Analysis!F24 -> Reviewed | D22: =Requirements_Analysis!D24 -> REQ_M4_SCST_21 | E22: =Requirements_Analysis!N24 -> Review | F22: n/a | G22: Reviewed | I22: =IF(AND(NOT(ISBLANK(D22)),NOT(EXACT(C22,"Canceled"))),IF(EXACT(E22,"Review"),NOT(ISBLANK(G22)),"Not relevant"),"Not relevant") -> TRUE | J22: =IF(AND(NOT(ISBLANK(D22)),NOT(EXACT(C22,"Canceled"))),IF(EXACT(E22,"Test case"),NOT(ISBLANK(F22)),"Not relevant"),"Not relevant") -> Not relevant | K22: =OR(EXACT(I22,"FALSE"),EXACT(J22,"FALSE")) -> FALSE | L22: =IF(OR(NOT(ISBLANK(D22)),NOT(EXACT(C22,"Canceled"))),OR(ISBLANK(B22),ISBLANK(A22)),"FALSE") -> FALSE
A23: m4_scst_test_shell.c m4_scst_data.c | B23: n/a | C23: =Requirements_Analysis!F25 -> Reviewed | D23: =Requirements_Analysis!D25 -> REQ_M4_SCST_22 | E23: =Requirements_Analysis!N25 -> Test case | F23: M4_SCST_UT_T14 | I23: =IF(AND(NOT(ISBLANK(D23)),NOT(EXACT(C23,"Canceled"))),IF(EXACT(E23,"Review"),NOT(ISBLANK(G23)),"Not relevant"),"Not relevant") -> Not relevant | J23: =IF(AND(NOT(ISBLANK(D23)),NOT(EXACT(C23,"Canceled"))),IF(EXACT(E23,"Test case"),NOT(ISBLANK(F23)),"Not relevant"),"Not relevant") -> TRUE | K23: =OR(EXACT(I23,"FALSE"),EXACT(J23,"FALSE")) -> FALSE | L23: =IF(OR(NOT(ISBLANK(D23)),NOT(EXACT(C23,"Canceled"))),OR(ISBLANK(B23),ISBLANK(A23)),"FALSE") -> FALSE
A24: m4_scst_test_shell.c m4_scst_data.c | B24: n/a | C24: =Requirements_Analysis!F26 -> Reviewed | D24: =Requirements_Analysis!D26 -> REQ_M4_SCST_23 | E24: =Requirements_Analysis!N26 -> Test case | F24: M4_SCST_UT_T14 | I24: =IF(AND(NOT(ISBLANK(D24)),NOT(EXACT(C24,"Canceled"))),IF(EXACT(E24,"Review"),NOT(ISBLANK(G24)),"Not relevant"),"Not relevant") -> Not relevant | J24: =IF(AND(NOT(ISBLANK(D24)),NOT(EXACT(C24,"Canceled"))),IF(EXACT(E24,"Test case"),NOT(ISBLANK(F24)),"Not relevant"),"Not relevant") -> TRUE | K24: =OR(EXACT(I24,"FALSE"),EXACT(J24,"FALSE")) -> FALSE | L24: =IF(OR(NOT(ISBLANK(D24)),NOT(EXACT(C24,"Canceled"))),OR(ISBLANK(B24),ISBLANK(A24)),"FALSE") -> FALSE
A25: All code | B25: All elements | C25: =Requirements_Analysis!F27 -> Reviewed | D25: =Requirements_Analysis!D27 -> REQ_M4_SCST_24 | E25: =Requirements_Analysis!N27 -> Test case | F25: M4_SCST_EXECUTION_TIME_REPORT_FLASH | I25: =IF(AND(NOT(ISBLANK(D25)),NOT(EXACT(C25,"Canceled"))),IF(EXACT(E25,"Review"),NOT(ISBLANK(G25)),"Not relevant"),"Not relevant") -> Not relevant | J25: =IF(AND(NOT(ISBLANK(D25)),NOT(EXACT(C25,"Canceled"))),IF(EXACT(E25,"Test case"),NOT(ISBLANK(F25)),"Not relevant"),"Not relevant") -> TRUE | K25: =OR(EXACT(I25,"FALSE"),EXACT(J25,"FALSE")) -> FALSE | L25: =IF(OR(NOT(ISBLANK(D25)),NOT(EXACT(C25,"Canceled"))),OR(ISBLANK(B25),ISBLANK(A25)),"FALSE") -> FALSE
A26: m4_scst_loadstore_test1 m4_scst_loadstore_test2 m4_scst_loadstore_test3 m4_scst_loadstore_test4 m4_scst_loadstore_test5 m4_scst_loadstore_test6 | B26: n/a | C26: =Requirements_Analysis!F28 -> Reviewed | D26: =Requirements_Analysis!D28 -> REQ_M4_SCST_25 | E26: =Requirements_Analysis!N28 -> Review | F26: n/a | G26: Reviewed | I26: =IF(AND(NOT(ISBLANK(D26)),NOT(EXACT(C26,"Canceled"))),IF(EXACT(E26,"Review"),NOT(ISBLANK(G26)),"Not relevant"),"Not relevant") -> TRUE | J26: =IF(AND(NOT(ISBLANK(D26)),NOT(EXACT(C26,"Canceled"))),IF(EXACT(E26,"Test case"),NOT(ISBLANK(F26)),"Not relevant"),"Not relevant") -> Not relevant | K26: =OR(EXACT(I26,"FALSE"),EXACT(J26,"FALSE")) -> FALSE | L26: =IF(OR(NOT(ISBLANK(D26)),NOT(EXACT(C26,"Canceled"))),OR(ISBLANK(B26),ISBLANK(A26)),"FALSE") -> FALSE
A27: All code | B27: All elements | C27: =Requirements_Analysis!F29 -> Reviewed | D27: =Requirements_Analysis!D29 -> REQ_M4_SCST_26 | E27: =Requirements_Analysis!N29 -> Review | F27: n/a | G27: Reviewed | I27: =IF(AND(NOT(ISBLANK(D27)),NOT(EXACT(C27,"Canceled"))),IF(EXACT(E27,"Review"),NOT(ISBLANK(G27)),"Not relevant"),"Not relevant") -> TRUE | J27: =IF(AND(NOT(ISBLANK(D27)),NOT(EXACT(C27,"Canceled"))),IF(EXACT(E27,"Test case"),NOT(ISBLANK(F27)),"Not relevant"),"Not relevant") -> Not relevant | K27: =OR(EXACT(I27,"FALSE"),EXACT(J27,"FALSE")) -> FALSE | L27: =IF(OR(NOT(ISBLANK(D27)),NOT(EXACT(C27,"Canceled"))),OR(ISBLANK(B27),ISBLANK(A27)),"FALSE") -> FALSE
A28: n/a | B28: n/a | C28: =Requirements_Analysis!F30 -> Reviewed | D28: =Requirements_Analysis!D30 -> REQ_M4_SCST_27 | E28: =Requirements_Analysis!N30 -> Review | F28: n/a | G28: Reviewed | I28: =IF(AND(NOT(ISBLANK(D28)),NOT(EXACT(C28,"Canceled"))),IF(EXACT(E28,"Review"),NOT(ISBLANK(G28)),"Not relevant"),"Not relevant") -> TRUE | J28: =IF(AND(NOT(ISBLANK(D28)),NOT(EXACT(C28,"Canceled"))),IF(EXACT(E28,"Test case"),NOT(ISBLANK(F28)),"Not relevant"),"Not relevant") -> Not relevant | K28: =OR(EXACT(I28,"FALSE"),EXACT(J28,"FALSE")) -> FALSE | L28: =IF(OR(NOT(ISBLANK(D28)),NOT(EXACT(C28,"Canceled"))),OR(ISBLANK(B28),ISBLANK(A28)),"FALSE") -> FALSE
A29: n/a | B29: n/a | C29: =Requirements_Analysis!F31 -> Reviewed | D29: =Requirements_Analysis!D31 -> REQ_M4_SCST_28 | E29: =Requirements_Analysis!N31 -> Review | F29: n/a | G29: Reviewed | I29: =IF(AND(NOT(ISBLANK(D29)),NOT(EXACT(C29,"Canceled"))),IF(EXACT(E29,"Review"),NOT(ISBLANK(G29)),"Not relevant"),"Not relevant") -> TRUE | J29: =IF(AND(NOT(ISBLANK(D29)),NOT(EXACT(C29,"Canceled"))),IF(EXACT(E29,"Test case"),NOT(ISBLANK(F29)),"Not relevant"),"Not relevant") -> Not relevant | K29: =OR(EXACT(I29,"FALSE"),EXACT(J29,"FALSE")) -> FALSE | L29: =IF(OR(NOT(ISBLANK(D29)),NOT(EXACT(C29,"Canceled"))),OR(ISBLANK(B29),ISBLANK(A29)),"FALSE") -> FALSE
A30: All code | B30: n/a | C30: =Requirements_Analysis!F32 -> Reviewed | D30: =Requirements_Analysis!D32 -> REQ_M4_SCST_29 | E30: =Requirements_Analysis!N32 -> Review | F30: n/a | G30: Reviewed | I30: =IF(AND(NOT(ISBLANK(D30)),NOT(EXACT(C30,"Canceled"))),IF(EXACT(E30,"Review"),NOT(ISBLANK(G30)),"Not relevant"),"Not relevant") -> TRUE | J30: =IF(AND(NOT(ISBLANK(D30)),NOT(EXACT(C30,"Canceled"))),IF(EXACT(E30,"Test case"),NOT(ISBLANK(F30)),"Not relevant"),"Not relevant") -> Not relevant | K30: =OR(EXACT(I30,"FALSE"),EXACT(J30,"FALSE")) -> FALSE | L30: =IF(OR(NOT(ISBLANK(D30)),NOT(EXACT(C30,"Canceled"))),OR(ISBLANK(B30),ISBLANK(A30)),"FALSE") -> FALSE
A31: All code | B31: n/a | C31: =Requirements_Analysis!F33 -> Reviewed | D31: =Requirements_Analysis!D33 -> REQ_M4_SCST_30 | E31: =Requirements_Analysis!N33 -> Review | F31: n/a | G31: Reviewed | I31: =IF(AND(NOT(ISBLANK(D31)),NOT(EXACT(C31,"Canceled"))),IF(EXACT(E31,"Review"),NOT(ISBLANK(G31)),"Not relevant"),"Not relevant") -> TRUE | J31: =IF(AND(NOT(ISBLANK(D31)),NOT(EXACT(C31,"Canceled"))),IF(EXACT(E31,"Test case"),NOT(ISBLANK(F31)),"Not relevant"),"Not relevant") -> Not relevant | K31: =OR(EXACT(I31,"FALSE"),EXACT(J31,"FALSE")) -> FALSE | L31: =IF(OR(NOT(ISBLANK(D31)),NOT(EXACT(C31,"Canceled"))),OR(ISBLANK(B31),ISBLANK(A31)),"FALSE") -> FALSE
A32: All code | B32: n/a | C32: =Requirements_Analysis!F34 -> Reviewed | D32: =Requirements_Analysis!D34 -> REQ_M4_SCST_31 | E32: =Requirements_Analysis!N34 -> Review | F32: n/a | G32: Reviewed | I32: =IF(AND(NOT(ISBLANK(D32)),NOT(EXACT(C32,"Canceled"))),IF(EXACT(E32,"Review"),NOT(ISBLANK(G32)),"Not relevant"),"Not relevant") -> TRUE | J32: =IF(AND(NOT(ISBLANK(D32)),NOT(EXACT(C32,"Canceled"))),IF(EXACT(E32,"Test case"),NOT(ISBLANK(F32)),"Not relevant"),"Not relevant") -> Not relevant | K32: =OR(EXACT(I32,"FALSE"),EXACT(J32,"FALSE")) -> FALSE | L32: =IF(OR(NOT(ISBLANK(D32)),NOT(EXACT(C32,"Canceled"))),OR(ISBLANK(B32),ISBLANK(A32)),"FALSE") -> FALSE
A33: All code | B33: n/a | C33: =Requirements_Analysis!F35 -> Reviewed | D33: =Requirements_Analysis!D35 -> REQ_M4_SCST_32 | E33: =Requirements_Analysis!N35 -> Review | F33: n/a | G33: Reviewed | I33: =IF(AND(NOT(ISBLANK(D33)),NOT(EXACT(C33,"Canceled"))),IF(EXACT(E33,"Review"),NOT(ISBLANK(G33)),"Not relevant"),"Not relevant") -> TRUE | J33: =IF(AND(NOT(ISBLANK(D33)),NOT(EXACT(C33,"Canceled"))),IF(EXACT(E33,"Test case"),NOT(ISBLANK(F33)),"Not relevant"),"Not relevant") -> Not relevant | K33: =OR(EXACT(I33,"FALSE"),EXACT(J33,"FALSE")) -> FALSE | L33: =IF(OR(NOT(ISBLANK(D33)),NOT(EXACT(C33,"Canceled"))),OR(ISBLANK(B33),ISBLANK(A33)),"FALSE") -> FALSE
A34: All code | B34: n/a | C34: =Requirements_Analysis!F36 -> Reviewed | D34: =Requirements_Analysis!D36 -> REQ_M4_SCST_33 | E34: =Requirements_Analysis!N36 -> Review | F34: n/a | G34: Reviewed | I34: =IF(AND(NOT(ISBLANK(D34)),NOT(EXACT(C34,"Canceled"))),IF(EXACT(E34,"Review"),NOT(ISBLANK(G34)),"Not relevant"),"Not relevant") -> TRUE | J34: =IF(AND(NOT(ISBLANK(D34)),NOT(EXACT(C34,"Canceled"))),IF(EXACT(E34,"Test case"),NOT(ISBLANK(F34)),"Not relevant"),"Not relevant") -> Not relevant | K34: =OR(EXACT(I34,"FALSE"),EXACT(J34,"FALSE")) -> FALSE | L34: =IF(OR(NOT(ISBLANK(D34)),NOT(EXACT(C34,"Canceled"))),OR(ISBLANK(B34),ISBLANK(A34)),"FALSE") -> FALSE
A35: All code | B35: n/a | C35: =Requirements_Analysis!F37 -> Reviewed | D35: =Requirements_Analysis!D37 -> REQ_M4_SCST_34 | E35: =Requirements_Analysis!N37 -> Review | F35: n/a | G35: Reviewed | I35: =IF(AND(NOT(ISBLANK(D35)),NOT(EXACT(C35,"Canceled"))),IF(EXACT(E35,"Review"),NOT(ISBLANK(G35)),"Not relevant"),"Not relevant") -> TRUE | J35: =IF(AND(NOT(ISBLANK(D35)),NOT(EXACT(C35,"Canceled"))),IF(EXACT(E35,"Test case"),NOT(ISBLANK(F35)),"Not relevant"),"Not relevant") -> Not relevant | K35: =OR(EXACT(I35,"FALSE"),EXACT(J35,"FALSE")) -> FALSE | L35: =IF(OR(NOT(ISBLANK(D35)),NOT(EXACT(C35,"Canceled"))),OR(ISBLANK(B35),ISBLANK(A35)),"FALSE") -> FALSE
A36: All code | B36: n/a | C36: =Requirements_Analysis!F38 -> Reviewed | D36: =Requirements_Analysis!D38 -> REQ_M4_SCST_35 | E36: =Requirements_Analysis!N38 -> Review | F36: n/a | G36: Reviewed | I36: =IF(AND(NOT(ISBLANK(D36)),NOT(EXACT(C36,"Canceled"))),IF(EXACT(E36,"Review"),NOT(ISBLANK(G36)),"Not relevant"),"Not relevant") -> TRUE | J36: =IF(AND(NOT(ISBLANK(D36)),NOT(EXACT(C36,"Canceled"))),IF(EXACT(E36,"Test case"),NOT(ISBLANK(F36)),"Not relevant"),"Not relevant") -> Not relevant | K36: =OR(EXACT(I36,"FALSE"),EXACT(J36,"FALSE")) -> FALSE | L36: =IF(OR(NOT(ISBLANK(D36)),NOT(EXACT(C36,"Canceled"))),OR(ISBLANK(B36),ISBLANK(A36)),"FALSE") -> FALSE
A37: All code | B37: "SCST_Invocation" diagram | C37: =Requirements_Analysis!F39 -> Reviewed | D37: =Requirements_Analysis!D39 -> REQ_M4_SCST_36 | E37: =Requirements_Analysis!N39 -> Test case | F37: M4_SCST_UT_T01 M4_SCST_UT_T02 M4_SCST_UT_T15 M4_SCST_UT_T16 M4_SCST_UT_T17 | I37: =IF(AND(NOT(ISBLANK(D37)),NOT(EXACT(C37,"Canceled"))),IF(EXACT(E37,"Review"),NOT(ISBLANK(G37)),"Not relevant"),"Not relevant") -> Not relevant | J37: =IF(AND(NOT(ISBLANK(D37)),NOT(EXACT(C37,"Canceled"))),IF(EXACT(E37,"Test case"),NOT(ISBLANK(F37)),"Not relevant"),"Not relevant") -> TRUE | K37: =OR(EXACT(I37,"FALSE"),EXACT(J37,"FALSE")) -> FALSE | L37: =IF(OR(NOT(ISBLANK(D37)),NOT(EXACT(C37,"Canceled"))),OR(ISBLANK(B37),ISBLANK(A37)),"FALSE") -> FALSE
A38: n/a | B38: n/a | C38: =Requirements_Analysis!F40 -> Reviewed | D38: =Requirements_Analysis!D40 -> REQ_M4_SCST_37 | E38: =Requirements_Analysis!N40 -> Review | F38: n/a | G38: Reviewed | I38: =IF(AND(NOT(ISBLANK(D38)),NOT(EXACT(C38,"Canceled"))),IF(EXACT(E38,"Review"),NOT(ISBLANK(G38)),"Not relevant"),"Not relevant") -> TRUE | J38: =IF(AND(NOT(ISBLANK(D38)),NOT(EXACT(C38,"Canceled"))),IF(EXACT(E38,"Test case"),NOT(ISBLANK(F38)),"Not relevant"),"Not relevant") -> Not relevant | K38: =OR(EXACT(I38,"FALSE"),EXACT(J38,"FALSE")) -> FALSE | L38: =IF(OR(NOT(ISBLANK(D38)),NOT(EXACT(C38,"Canceled"))),OR(ISBLANK(B38),ISBLANK(A38)),"FALSE") -> FALSE
A39: n/a | B39: n/a | C39: =Requirements_Analysis!F41 -> Reviewed | D39: =Requirements_Analysis!D41 -> REQ_M4_SCST_38 | E39: =Requirements_Analysis!N41 -> Review | F39: n/a | G39: Reviewed | I39: =IF(AND(NOT(ISBLANK(D39)),NOT(EXACT(C39,"Canceled"))),IF(EXACT(E39,"Review"),NOT(ISBLANK(G39)),"Not relevant"),"Not relevant") -> TRUE | J39: =IF(AND(NOT(ISBLANK(D39)),NOT(EXACT(C39,"Canceled"))),IF(EXACT(E39,"Test case"),NOT(ISBLANK(F39)),"Not relevant"),"Not relevant") -> Not relevant | K39: =OR(EXACT(I39,"FALSE"),EXACT(J39,"FALSE")) -> FALSE | L39: =IF(OR(NOT(ISBLANK(D39)),NOT(EXACT(C39,"Canceled"))),OR(ISBLANK(B39),ISBLANK(A39)),"FALSE") -> FALSE
A40: n/a | B40: n/a | C40: =Requirements_Analysis!F42 -> Reviewed | D40: =Requirements_Analysis!D42 -> REQ_M4_SCST_39 | E40: =Requirements_Analysis!N42 -> Review | F40: n/a | G40: Reviewed | I40: =IF(AND(NOT(ISBLANK(D40)),NOT(EXACT(C40,"Canceled"))),IF(EXACT(E40,"Review"),NOT(ISBLANK(G40)),"Not relevant"),"Not relevant") -> TRUE | J40: =IF(AND(NOT(ISBLANK(D40)),NOT(EXACT(C40,"Canceled"))),IF(EXACT(E40,"Test case"),NOT(ISBLANK(F40)),"Not relevant"),"Not relevant") -> Not relevant | K40: =OR(EXACT(I40,"FALSE"),EXACT(J40,"FALSE")) -> FALSE | L40: =IF(OR(NOT(ISBLANK(D40)),NOT(EXACT(C40,"Canceled"))),OR(ISBLANK(B40),ISBLANK(A40)),"FALSE") -> FALSE
...
