Workbook

Sheet Revision History
A3: Cortex-M4 Structural Core Self Test Library
A4: Fault Coverage Estimation Report
A6: Date: 12-Oct-2016 | F6: Confidential Proprietary
A8: The document was prepared using best effort. The authors make no warranty of any kind and shall not be liable in any event for incidental or consequential damages in connection with the application of the document.
A11: History of change
A12: Document revision | B12: Date | C12: Created by | D12: Description
A13: 1.0-D01 | B13: 42115 | C13: Oleksandr Sakada | D13: Initial version.
A14: 1.0-D02 | B14: 42255 | C14: Oleksandr Sakada | D14: Reviewed intermediate version. Handed-over to Roman Chovanec and Martin Vlk.
A15: 1 | B15: 42411 | C15: Roman Chovanec | D15: Added core sub-modules relative sizes for the final final fault coverage computation.
A16: 1.1 | B16: 42655 | C16: Roman Chovanec | D16: Updated logo and copyright
A18: © 2016 Freescale Semiconductor, Inc., NXP Semiconductors. All rights reserved. Presence of a copyright notice is not an acknowledgement of publication.

Sheet DC, z4204n3 Block Diagram
A1: DC for relevant core modules according to the diagram below is estimated to be (%): | I1: =SUM('DC Estimation'!#REF!)*100 -> #REF!
K5: - modules considered as irrelevant for Structural Core Self Test library,
K6: they are not included into estimation of DC achieved by Structural Core Self Test library.

Sheet Cortex M4 Block Diagram
B42: In-scope of SCST except of FPU unit

Sheet DC Estimation
A1: Core module name / Core sub-module name | C1: Description of logic related to core sub-module | D1: Core sub-module relative size, % | E1: Fault Type | F1: Relative size of the part of the core sub-module relevant to the Fault Type, % (estimated) | G1: Description of logic related to the Fault Type | H1: Fault Type Coverage, % (Σ L*M) | I1: D * F (coverage specified here shall be Σ-ed for all listed sub-modules but separately for each Fault Type to calculate 100%-base for each Fault Type) | J1: D * F * H (coverage specified here shall be Σ-ed for all listed sub-modules but separately for each Fault Type to calculate final coverage achieved invididually for each Fault Type) | K1: Fault Model | L1: Fault model coverage, % (estimated) | M1: Portion of Fault Model in Fault Type, % | N1: Argument to estimated achieved fault coverage per Fault Model | O1: Description of the applied test patterns (to the whole core sub-module) | P1: Related core self test(s)
A2: cm4_dpu | B2: cm4_dpu_alu | C2: Logic implementing the following operations according to ALU control bus: - use carry - flag write control - ALU operation type (see below) - shift operation is of the form RRX - shifter input 2 valid/select - shifter input 1 valid/select - shifter control - inline shift carry control - adder input 2 valid - adder input 1 valid - invert ALU input 2 - invert ALU input 1 ALU operation type: - Bitwise AND - Bitwise OR - BitWise EOR - Shift (regular) - separate ctrl for immediate vs reg for timing - Shift (BFX) - use sign info to distinguish - Shift (BFI/BFC) - Shift (saturation) - use sign info to distinguish - MOV (MSR flag/GE write depending on size register) - MOV (MRS unpred) - MOV (MRS control) - MOV (MRS nvic_basepri_i) - MOV (MRS no nvic_pmask_i or nvic_fmask_i) - MOV (MRS nvic_pmask_i) - MOV (MRS nvic_fmask_i) - MOV (MRS nvic_pmask_i & nvic_fmask_i) - MOV (MRS none) - MOV (MRS PSR) - MOV (MRS control) - MOV (MRS both) - MOV (normal) - MOV (RBIT) - MOV (REV) - MOV (MOVT) - DIV - use sign info to distinguish - MUL (*MLAL) - use sign info to distinguish - MUL (*MULL) - use sign info to distinguish - MUL (MUL) - MUL (MLA) - MUL (MLS) - CLZ | D2: 0.17343957 | E2: SPF | F2: 1 | H2: =L2*M2+L27*M27+L31*M31+L43*M43 -> 0.96371225 | I2: =D2*F2 -> 0.17343957 | J2: =D2*F2*H2 -> 0.16714584 | K2: Stuck-at | L2: =lookup!B101 -> 0.99407947 | M2: 0.7 | N2: Logic of the ALU module is covered completely: - All bits in input and output operands are forced to '0' and '1'. - Every operation realized within ALU sub-module and listed in column C is explicitly executed and checked for multiple sets of operands. - 5x test patterns are taken for divider array based on "proxy-fault-simulation" method. - For shift operation: all possible number of shift count, shift of '0' and '1' bit from every source position to every target position. - All possible number of leading zero-value bits for "count leading zero" command is tested. In total, 100x test patterns are applied for detecting stuck-at faults within different areas of the ALU logic. It is estimated, a single test pattern achieves 5% of the overall ALU stuck-at fault coverage (according to the experience gained during fault-graded core self test development for other cores of comparable complexity). Probability of fault detection by multiple test patterns are calculated as for independent events (in contrast to mutually-exclusive). | O2: All bits in input and output operands are forced to '0' and '1'. Every operation realized within ALU sub-module and listed in column C is explicitly executed. Multiple data patterns are applied to every ALU sub-module. | P2: m4_scst_alu_test1 m4_scst_alu_test2 m4_scst_alu_test3 m4_scst_alu_test4 m4_scst_alu_test5 m4_scst_alu_test6 m4_scst_alu_test7
K27: Open | L27: =(1-POWER(0.5,6))*L2 -> 0.97854698 | M27: 0.2 | N27: Probability of detecting one "open" fault with a single test pattern is 0.5. In average, 6x test patters are applied across ALU sub-modules. Result of application of every pattern is explicitly checked.
K31: Stuck-open | L31: ='d.c. fault estimation'!O18*L2 -> 0.68342964 | M31: 0.05 | N31: It is estimated that 6x test patterns are applied to corresponding possible faulty location on avarage. Probability of causing at least one 0 -> 1 -> 0 transition is calculated on "d.c. fault estimation" sheet.
K43: Short | L43: =('d.c. fault estimation'!C7)*L2 -> 0.7595148 | M43: 0.05 | N43: It is estimated 300x test patterns are applied for detecting short-faults. Assumption: probability of constitution of "short"-fault according to scenario 1 (sheet d.c. fault estimation) is 50%, and probability of constitution of "short"-fault according to scenario 2 is remaining 50%.
B50: cm4_dpu_dec | C50: Thumb 16bit instruction decode unit Thumb 32bit instruction decode unit Branch decode unit | D50: 0.046242954 | E50: SPF | F50: 1 | G50: Logic decoding legal opcodes | H50: =L50*M50+L73*M73+L76*M76+L79*M79 -> 0.95232301 | I50: =D50*F50 -> 0.046242954 | J50: =D50*F50*H50 -> 0.044038229 | K50: Stuck-at | L50: =lookup!D356*'d.c. fault estimation'!C13+lookup!D356*'d.c. fault estimation'!C14*(1-POWER(1-'d.c. fault estimation'!C15,6)) -> 0.98623438 | M50: 0.7 | N50: Stuck-at fault in the decoder may lead either to: 1) an instruction is not decoded as valid and intended instruction, or 2) decoder signals decoding of multiple instructions (including the intended one) simultaneously resulting in multiple execution units to produce a result that is to be stored to target registers creating a race-condition, or different results to multiple registers. In both cases, coverage estimated proportionally to the number of tested instructions. In 2nd case, number of testing of each instruction in avarage is taken into account in addition. It is estimated, case 1 occures in 50% of all possible faulty cases, and case 2 - in the remaining 50%. It is estimated, probability of detecting a race-condition in 2nd case with a one-time executed instruction is 50%. Decoder logic supports decoding of 357 instructions and instruction related data. It is estimated, a single test pattern (a single executed instruction, result of which is explicitly verified) achieves 0.28% (1 / 357) of the overall decoder stuck-at fault coverage. It is estimated, 99% of all valid instructions are executed in total. It is estimated, every instruction is executed 6x times in avarage. Probability of fault detection by multiple test patterns are calculated as for mutually-exclusive events (in contrast to independent). | O50: All executed instructions across all core tests, result of which is explicitly tested. Only very limited number of illegal opcodes are tested, mainly within testing illegal opcode exception and not the logic decoding illegal opcodes themselves. | P50: m4_scst_loadstore_test1 m4_scst_loadstore_test2 m4_scst_loadstore_test3 m4_scst_loadstore_test4 m4_scst_loadstore_test5 m4_scst_loadstore_test6 m4_scst_mac_test1 m4_scst_mac_test2 m4_scst_alu_test1 m4_scst_alu_test2 m4_scst_alu_test3 m4_scst_alu_test4 m4_scst_alu_test5 m4_scst_alu_test6 m4_scst_alu_test7 m4_scst_simdsat_test1 m4_scst_simdsat_test2 m4_scst_simdsat_test3 m4_scst_simdsat_test4 m4_scst_branch_test1 m4_scst_branch_test2 m4_scst_branch_test3 m4_scst_status_test1 m4_scst_status_test2 m4_scst_status_test3
K73: Open | L73: =('d.c. fault estimation'!E16+'d.c. fault estimation'!F23)*(lookup!D356*'d.c. fault estimation'!C13+lookup!D356*'d.c. fault estimation'!C14) -> 0.89239238 | M73: 0.2 | N73: Probability of detecting one "open" fault with a single test pattern is 0.5. It is estimated that every instruction is executed 6x times on avarage.
K76: Stuck-open | L76: =('d.c. fault estimation'!O18)*(lookup!D356*'d.c. fault estimation'!C13+lookup!D356*'d.c. fault estimation'!C14) -> 0.683375 | M76: 0.05 | N76: It is assumed, every location of stuck-open fault is set in accordance to application of 6x test patterns (it is estimated , every instruction is executed 6x times).
K79: Short | L79: =L50 -> 0.98623438 | M79: 0.05 | N79: Logic of the decoder is completely initialized by a single opcode of a decoded instruction meaning that not only the group of gates recognizing the given instruction as valid are initialized, but also all other groups of gates are initialized as well. The related to the decoded instruction dangerous short faults can be claimed as detected in the same manner as stuck-at faults. This claim is possible mainly due to a gate structure of the decoder logic allowing claiming detected by each instruction faults as mutually exclusive sets.
B97: cm4_dpu_e.cm4_dpu_e_dec | C97: E extension decode unit (SIMD & MAC) | D97: 0.008962616 | E97: SPF | F97: 1 | G97: Logic decoding legal E-extention opcodes | H97: =L97*M97+L119*M119+L122*M122+L125*M125 -> 0.9581296 | I97: =D97*F97 -> 0.008962616 | J97: =D97*F97*H97 -> 0.0085873478 | K97: Stuck-at | L97: =lookup!F98*'d.c. fault estimation'!C38+lookup!F98*'d.c. fault estimation'!C39*(1-POWER(1-'d.c. fault estimation'!C40,6)) -> 0.99129453 | M97: 0.7 | N97: Stuck-at fault in the decoder may lead either to: 1) an instruction is not decoded as valid and intended instruction, or 2) decoder signals decoding of multiple instructions (including the intended one) simultaneously resulting in multiple execution units to produce a result that is to be stored to target registers creating a race-condition. In both cases, coverage estimated proportionally to the number of tested instructions. In 2nd case, number of testing of each instruction in avarage is taken into account in addition. It is estimated, case 1 occures in 50% of all possible faulty cases, and case 2 - in the remaining 50%. It is estimated, probability of detecting a race-condition in 2nd case with a one-time executed instruction is 50%. Decoder logic supports decoding of 97 instructions and instruction related data. It is estimated, a single test pattern (a single executed instruction, result of which is explicitly verified) achieves 1.03% (1 / 97) of the overall decoder stuck-at fault coverage. It is estimated, 100% (97) of all valid instructions are executed in total. It is estimated, every instruction is executed 6x times in avarage. Probability of fault detection by multiple test patterns are calculated as for mutually-exclusive events (in contrast to independent). | O97: All executed E extention instructions, result of which is explicitly tested. | P97: m4_scst_simdsat_test1 m4_scst_simdsat_test2 m4_scst_simdsat_test3 m4_scst_simdsat_test4
K119: Open | L119: =('d.c. fault estimation'!E41+'d.c. fault estimation'!F48)*(lookup!F98*'d.c. fault estimation'!C38+lookup!F98*'d.c. fault estimation'!C39) -> 0.90157322 | M119: 0.2 | N119: Probability of detecting one "open" fault with a single test pattern is 0.5. It is estimated that every instruction is executed 6x times on avarage.
K122: Stuck-open | L122: =('d.c. fault estimation'!O43)*(lookup!F98*'d.c. fault estimation'!C38+lookup!F98*'d.c. fault estimation'!C39) -> 0.68688125 | M122: 0.05 | N122: It is assumed, every location of stuck-open fault is set in accordance to application of 6x test patterns (it is estimated , every instruction is executed 4x times).
K125: Short | L125: =L97 -> 0.99129453 | M125: 0.05 | N125: Logic of the decoder is completely initialized by a single opcode of a decoded instruction meaning that not only the group of gates recognizing the given instruction as valid are initialized, but also all other groups of gates are initialized as well. The related to the decoded instruction dangerous short faults can be claimed as detected in the same manner as stuck-at faults. This claim is possible mainly due to a gate structure of the decoder logic allowing claiming a detected by each instruction set of faults as mutually exclusive sets.
B133: cm4_dpu_e.cm4_dpu_e_ctl | C133: Control logic for E extensions (SIMD & MAC) | D133: 0.0043207062 | E133: SPF | F133: 1 | H133: =L133*M133+L138*M138+L143*M143+L147*M147 -> 0.90090611 | I133: =D133*F133 -> 0.0043207062 | J133: =D133*F133*H133 -> 0.0038925507 | K133: Stuck-at | L133: =MIN(L97,L152,L177) -> 0.93 | M133: 0.7 | N133: Coverage for this module is estimated concervatively: a minimal achived coverage of two modules - E extention decode unit (cm4_dpu_e.cm4_dpu_e_dec) and E extention execution unit (cm4_dpu_e.cm4_dpu_e_mac and cm4_dpu_e.cm4_dpu_e_simdsat) - is taken for the current one. | O133: All executed E extention instructions with multiple sets of operands, result of which is explicitly tested. See argument description for cm4_dpu_e.cm4_dpu_e_dec, cm4_dpu_e.cm4_dpu_e_mac, and cm4_dpu_e.cm4_dpu_e_simdsat modules. | P133: m4_scst_simdsat_test1 m4_scst_simdsat_test2 m4_scst_simdsat_test3 m4_scst_simdsat_test4
K138: Open | L138: =(1-POWER(0.5,6))*L133 -> 0.91546875 | M138: 0.2 | N138: Probability of detecting one "open" fault with a single test pattern is 0.5. It is estimated that 6x test patterns are applied to corresponding possible faulty location on avarage.
K143: Stuck-open | L143: ='d.c. fault estimation'!O43*L133 -> 0.639375 | M143: 0.05 | N143: It is estimated that 6x test patterns are applied to corresponding possible faulty location on avarage. Probability of causing at least one 0 -> 1 -> 0 transition is calculated on "d.c. fault estimation" sheet.
K147: Short | L147: =lookup!G98*L133 -> 0.69687225 | M147: 0.05 | N147: It is estimated, 100% (97) of all valid instructions are executed in total. Assumption: probability of constitution of "short"-fault according to scenario 1 (sheet "short"-fault estimation) is 50%, and probability of constitution of "short"-fault according to scenario 2 (sheet "short"-fault estimation) is 50%.
B152: cm4_dpu_e.cm4_dpu_e_mac | C152: Multiply and accumulate module | D152: 0.22809599 | E152: SPF | F152: 1 | H152: =L152*M152+L161*M161+L164*M164+L170*M170 -> 0.93 | I152: =D152*F152 -> 0.22809599 | J152: =D152*F152*H152 -> 0.21212927 | K152: Stuck-at | L152: 0.93 | M152: 0.7 | N152: 1. Input arguments and the generated result deterministically defined for detecting most of the possible stuck-at faults on input and output ports. 2. 35x test patterns applied for 32x32->64bit multiplier array. The coverage estimated by means of "proxy-fault-simulation" method for the worst-case assumption on multiplier array implementation in regards to testability. | O152: 1. UMLAL/SMLAL instruction takes input from 4 read ports and writes result to 2 write ports.It uses all the available data input and data output ports of the E_MAC module. 2. "Proxy-fault-simulation" method for stuck-at faults coverage estimation within multiplier array. 3. Different types of MAC commands: use 32 bits into 32x32 multiplier for rd_a use higher 16 bits into 32x32 multiplier for rd_a use 32 bits into 32x32 multiplier for rd_b use lower 16 bits into 32x32 multiplier for rd_b use higher 16 bits into 32x32 multiplier for rd_b use lower 16 bits into 16x16 multiplier for rd_ a use higher 16 bits into 16x16 multiplier for rd_a use lower 16 bits into 16x16 multiplier for rd_b use higher 16 bits into 16x16 multiplier for rd_b Negate 32 bit multiply multiply result rd_x into lower word of accumulator rd_y into lower word of accumulator rd_y into higher word of accumulator Sign extend rd_x in lower accumulator word Fix32 into higher word of accumulator Rounding 16 bit rotation on accumulator for 32x16 shifts 16 bit rotation on result for 32x16 shifts USAD | P152: m4_scst_regbank_test1 m4_scst_regbank_test2 m4_scst_regbank_test3 m4_scst_mac_test1 m4_scst_mac_test2
K161: Open | L161: 0.93 | M161: 0.2 | N161: Amount of applied test patterns (35x) and probability of detecting a fault by a single test pattern (0.5) is sufficient enough for claiming the same coverage as for stuck-at faults.
K164: Stuck-open | L164: 0.93 | M164: 0.05 | N164: 1. Multiple sets of Input arguments and the generated result deterministically defined for detecting short faults on input and output ports. 2. 35x test patterns applied for 32x32->64bit multiplier array. The coverage estimated by means of "proxy-fault-simulation" method for the worst-case assumption on multiplier array implementation in regards to testability and several possible scenarious on short-fault combinations.
K170: Short | L170: 0.93 | M170: 0.05 | N170: 1. Multiple sets of Input arguments and the generated result deterministically defined for detecting short faults on input and output ports. 2. 35x test patterns applied for 32x32->64bit multiplier array. The coverage estimated by means of "proxy-fault-simulation" method for the worst-case assumption on multiplier array implementation in regards to testability and several possible scenarious on short-fault combinations.
B177: cm4_dpu_e.cm4_dpu_e_simdsat | C177: Logic which provides the SIMD addition and saturation | D177: 0.036648292 | E177: SPF | F177: 1 | H177: =L177*M177+L190*M190+L194*M194+L206*M206 -> 0.96371225 | I177: =D177*F177 -> 0.036648292 | J177: =D177*F177*H177 -> 0.035318408 | K177: Stuck-at | L177: =lookup!B101 -> 0.99407947 | M177: 0.7 | N177: Logic of the simdsat module is covered completely: - All bits in input and output operands are forced to '0' and '1'. - Every operation realized within this sub-module and listed in column D on INSTR_SET sheet is explicitly executed and checked for multiple sets of operands. In total, 100x test patterns are applied for detecting stuck-at faults within different areas of the simdsat logic. It is estimated, a single test pattern achieves 5% of the overall simdsat stuck-at fault coverage (according to the experience gained during fault-graded core self test development for other cores of comparable complexity). Probability of fault detection by multiple test patterns are calculated as for independent events (in contrast to mutually-exclusive). | O177: All bits in input and output operands are forced to '0' and '1'. Every operation realized within simdsat sub-module and listed in column D on INSTR_SET sheet is explicitly executed. Multiple data patterns are used with every simdsat operation. Application of every possible mask value used for SSAT16 and USAT16 commands is explicitly checked. Explicit toggling of wires listed in column E on INSTR_SET sheet and checking the impact is explicitly performed by executing the corresponding simdsat instruction. | P177: m4_scst_simdsat_test1 m4_scst_simdsat_test2 m4_scst_simdsat_test3 m4_scst_simdsat_test4
K190: Open | L190: =(1-POWER(0.5,6))*L177 -> 0.97854698 | M190: 0.2 | N190: Probability of detecting one "open" fault with a single test pattern is 0.5. In average, 6x test patterns are applied across cm4_dpu_e_simdsat sub-modules. Result of application of every pattern is explicitly checked.
K194: Stuck-open | L194: ='d.c. fault estimation'!O18*L177 -> 0.68342964 | M194: 0.05 | N194: It is estimated that 6x test patterns are applied to corresponding possible faulty location on avarage. Probability of causing at least one 0 -> 1 -> 0 transition is calculated on "d.c. fault estimation" sheet.
K206: Short | L206: ='d.c. fault estimation'!C7*L177 -> 0.7595148 | M206: 0.05 | N206: It is estimated 300x test patterns are applied for detecting short-faults. Assumption: probability of constitution of "short"-fault according to scenario 1 (sheet "short"-fault estimation) is 50%, and probability of constitution of "short"-fault according to scenario 2 (sheet "short"-fault estimation) is 50%.
B211: cm4_dpu_etmintf | C211: ETM interface | E211: Safety-irrelevant | K211: Stuck-at | L211: n/a | M211: 0.7
K213: Open | L213: n/a | M213: 0.2
K216: Stuck-open | L216: n/a | M216: 0.05
K218: Short | L218: n/a | M218: 0.05
B221: cm4_dpu_exec | C221: Shared execute control and status. Selects between and controls the various blocks results. | D221: 0.026266164 | F221: 1 | H221: =L221*M221+L226*M226+L234*M234+L240*M240 -> 0.64114575 | I221: =D221*F221 -> 0.026266164 | J221: =D221*F221*H221 -> 0.016840439 | K221: Stuck-at | L221: =2/3*exec_estimation!B177+1/3*NVIC_DPU!B50 -> 0.67002899 | M221: 0.7 | N221: Coverage of stuck-at faults is estimated for 1/3 of the logic size based on analysis of the wires coverage, listed on sheet "NVIC_DPU", remaining 2/3 is estimated based on coverage estimation done for "decode" and E-extension decode modules. Detected sets of faults (corresponding to each of the analysed wire) by multiple test patterns are calculated as for mutually exclusive sets (in contrast to independent). | O221: 1) Based on the analysis of the Exec module logic, as well as NVIC_DPU interface signals, it is estimated 30% of the Exec logic relates to processing of interrupts and exceptions. This 1 / 3 of the logic coverage can be estimated based on detection status of the ports listed on NVIC_PDU sheet. 2) Coverage of remaining 2 / 3 of the Exec module can be done based on the coverage estimated for "decode" and E-extension decode modules, also taking into consideration wires listed on sheet "exec_estimation". | P221: Covered mainly by the exception tests.
K226: Open | L226: =(1-POWER(0.5,6))*L221 -> 0.65955978 | M226: 0.2 | N226: Probability of detecting one "open" fault with a single test pattern is 0.5. We estimated that 6 test patterns in avarage are applied to each of the wire which is claimed as tested within stuck-at fault coverage estimation for the 1 / 3 of the part related to exception logic, and for the remaining 2/3 of the logic (in this case coverage is estimates based on the coverage for for "decode" and E-extension decode modules). And then multiply by the relative size of the area challenged by the test patterns targeting stuck-at faults.
K234: Stuck-open | L234: ='d.c. fault estimation'!O18*L221 -> 0.46064493 | M234: 0.05 | N234: We assume that at least 6x test patterns are applied, then estimation can be done probabilistically as shown in cells H12:M28 on "d.c. fault estimation sheet. And then multiply by the relative size of the area challenged by the test patterns targeting stuck-at faults.
K240: Short | L240: =(1/3*lookup!L11+2/3*(0.5*lookup!J101+0.5*lookup!K101))*L221 -> 0.34362511 | M240: 0.05 | N240: Short fault coverage within part 1) can be estimated proportionally to the number of tested wires (as for mutually exclusive sets of faults). Short fault coverage for part 2) is done as for independed sets of faults detected by multiple test patterns. It is estimated a probability of constitution of "short"-fault according to scenario 1 (sheet d.c. fault estimation) is 50%, and probability of constitution of "short"-fault according to scenario 2 is remaining 50%. Coverage is dettermined based on the estimated number of applied test patterns and corresponding values are taken from columns J and K on "lookup" sheet.
B250: cm4_dpu_fetch | C250: Fetch unit with 3 entry prefetcher and branch forwarding behaviour. Vector table load in parallel to the ISR stacking - Fetch unit AHB interface & fetch buffer - Fetch unit state machine & RF control | D250: 0.078943551 | F250: 1 | H250: =L250*M250+L253*M253+L261*M261+L267*M267 -> 0.66830591 | I250: =D250*F250 -> 0.078943551 | J250: =D250*F250*H250 -> 0.052758442 | K250: Stuck-at | L250: =2/3*fetch_estimation!B30+1/3*NVIC_DPU!B49 -> 0.6984127 | M250: 0.7 | N250: Coverage of stuck-at faults is estimated for 1/3 of the logic size based on analysis of the wires coverage, listed on sheet "NVIC_DPU", remaining 2/3 is estimated based on coverage estimation done for "fetch" module. | O250: 1) Based on the analysis of the Fetch module logic, as well as NVIC_DPU interface signals, it is estimated 30% of the Fetch logic relates to processing of interrupts and exceptions. This 1 / 3 of the logic coverage can be estimated based on detection status of the ports listed on NVIC_PDU sheet. 2) Coverage of remaining 2 / 3 of the Fetch module can be done based on the coverage estimated for "decode" and E-extension decode modules also taking into consideration wires listed on sheet "fetch_estimation". | P250: m4_scst_branch_test1 m4_scst_branch_test2 m4_scst_branch_test3 m4_scst_fetch_test
K253: Open | L253: =(1-POWER(0.5,6))*L250 -> 0.6875 | M253: 0.2 | N253: Probability of detecting one "open" fault with a single test pattern is 0.5. We estimated that 6 test patterns in avarage are applied to each of the wire which is claimed as tested within stuck-at fault coverage estimation for the 1 / 3 of the part related to exception logic, and for the remaining 2/3 of the logic (in this case coverage is estimates based on the coverage for for "decode" and E-extension decode modules). And then multiply by the relative size of the area challenged by the test patterns targeting stuck-at faults.
K261: Stuck-open | L261: ='d.c. fault estimation'!O18*L250 -> 0.48015873 | M261: 0.05 | N261: Similarly to "open" faults, estimation should be done for the probability of causing a 0 -1 - 0 transition for each of the wire separately for each of the part. If at least 6x test patterns are applied, then estimation can be done probabilistically as shown in cells H12:M28 on "d.c. fault estimation sheet. And then multiply by the relative size of the area challenged by the test patterns targeting stuck-at faults.
K267: Short | L267: =(1/3*lookup!L11+2/3*(0.5*lookup!J101+0.5*lookup!K101))*L250 -> 0.35818173 | M267: 0.05 | N267: Short fault coverage within part 1) can be estimated proportionally to the number of tested wires (as for mutually exclusive sets of faults). Short fault coverage for part 2) is done as for independed sets of faults detected by multiple test patterns. It is estimated a probability of constitution of "short"-fault according to scenario 1 (sheet d.c. fault estimation) is 50%, and probability of constitution of "short"-fault according to scenario 2 is remaining 50%. Coverage is dettermined based on the estimated number of applied test patterns and corresponding values are taken from columns J and K on "lookup" sheet.
B277: cm4_dpu_lsu | C277: Load / store unit - LSU AHB interface and associated control - Main LSU control | D277: 0.21281291 | F277: 1 | H277: =L277*M277+L282*M282+L287*M287+L293*M293 -> 0.87991708 | I277: =D277*F277 -> 0.21281291 | J277: =D277*F277*H277 -> 0.18725772 | K277: Stuck-at | L277: =2/3*lsu_estimation!B96+1/3*NVIC_DPU!B48 -> 0.88267544 | M277: 0.7 | N277: Coverage of stuck-at faults is estimated for 1/3 of the logic size based on analysis of the wires coverage, listed on sheet "NVIC_DPU", remaining 2/3 is estimated based on coverage estimation done for "LSU" module. | O277: 1) Based on the analysis of the LSU module logic, as well as NVIC_DPU interface signals, it is estimated 1/3 of the LSU logic relates to processing of interrupts and exceptions. This 1 / 3 of the logic coverage can be estimated based on detection status of the ports listed on NVIC_PDU sheet. 2) Coverage of remaining 2 / 3 of the LSU module logic can be based on estimation of the wires coverage, listed on the "lsu_estimation" sheet. This includes load / store of different data patterns of different size to at least 2x different target locations using all implemented load / store instructions, including conditional execution of instructions. | P277: m4_scst_loadstore_test1 m4_scst_loadstore_test2 m4_scst_loadstore_test3 m4_scst_loadstore_test4 m4_scst_loadstore_test5 m4_scst_loadstore_test6
K282: Open | L282: =(1-POWER(0.5,6))*L277 -> 0.86888363 | M282: 0.2 | N282: Probability of detecting one "open" fault with a single test pattern is 0.5. We estimated that 6 test patterns in avarage are applied to each of the wire which is claimed as tested within stuck-at fault coverage estimation. And then multiply by the relative size of the area challenged by the test patterns targeting stuck-at faults.
K287: Stuck-open | L287: =L277 -> 0.88267544 | M287: 0.05 | N287: Propbability of Stuck-Open fault detection is very high because at least 9 tests vectors with inverted values were applied. We can claim the same coverage as for stuck-at faults.
...

Sheet d.c. fault estimation
A1: "short"-fault scenarios: | B1: "short"-fault coverage estimation for "cm4_dpu_alu" and "cm4_dpu_e.cm4_dpu_e_simdsat" sub-modules:
A3: Scenario 1: | B3: Portion of short-faults constituted according to scenario 1: | C3: 0.5 | E3: 0.5
A4: 'Inputs of the AND gate: | B4: Portion of short-faults constituted according to scenario 2: | C4: 0.5 | E4: 0.5
A5: '(correct values) --> (result of a "short" fault) | B5: Estimated number of detected short fault achieved by all applied short-fault test pattern in scenario 1: | C5: =C3*lookup!B301 -> 0.4999999 | D5: (1) | E5: =C3*lookup!B201 -> 0.49998247 | F5: (1)
A6: '(0,1)-->(1,1) : dangerous, detection status is determined by a status of stuck-at-1 at port 1 | B6: Estimated number of detected short fault achieved by all applied short-fault test pattern in scenario 2: | C6: =C4*lookup!C301 -> 0.26403841 | D6: (2) | E6: =C4*lookup!C201 -> 0.19692447 | F6: (2)
A7: '(1,0)-->(1,1) : dangerous, detection status is determined by a status of stuck-at-1 at port 2 | C7: =C5+C6 -> 0.76403831 | D7: (1) + (2) | E7: =E5+E6 -> 0.69690694 | F7: (1) + (2)
A8: '(1,0)-->(0,0) : safe
A9: '(0,1)-->(0,0) : safe
B10: "short"-fault coverage estimation for "cm4_dpu_dec" sub-module: | E10: Hints to "open" fault coverage estimation for "cm4_dpu_dec" sub-module: | H10: Hints to "stuck-open" fault coverage estimation for "cm4_dpu_dec" sub-module:
A11: 'Inputs of the OR gate:
A12: '(correct values) --> (result of a "short" fault) | B12: Relative number of tested instructions: | C12: 0.99 | E12: Case 1: | H12: TP1 | I12: TP2 | J12: TP3 | K12: TP4 | L12: TP5 | M12: TP6
A13: '(1,0)-->(1,1) : safe | B13: Portion of faults leading to case 1 (no race condition): | C13: 0.5 | E13: POWER(0.5,6) | G13: probability of not detection an open fault by 6x test patterns | H13: 0 | I13: 0 | J13: 0 | K13: 0 | L13: 0 | M13: 1 | O13: With 6x test patterns, it is possible to
A14: '(0,1)-->(1,1) : safe | B14: Portion of faults leading to case 2 (race condition possible): | C14: 0.5 | E14: 1-POWER(0.5,6) | G14: probability of detection an open fault by 6x test patterns | H14: 0 | I14: 0 | J14: 0 | K14: 0 | L14: 1 | M14: 1 | O14: get 11x 0 -> 1 -> 0 transitions out of 16
A15: '(1,0)-->(0,0) : dangerous, detection status is determined by a status of stuck-at-0 at port 1 | B15: Probability of fault (race-condition) detection by a single test pattern in case 2: | C15: 0.5 | E15: 0.99*0.5*(1-POWER(0.5,6)) | G15: the same as in row above, but taking into account 50% portion of faults in case 1 and 99% of tested instructions | H15: 0 | I15: 0 | J15: 0 | K15: 1 | L15: 0 | M15: 1 | O15: possible combinations.
A16: '(0,1)-->(0,0) : dangerous, detection status is determined by a status of stuck-at-0 at port 2 | E16: =lookup!D356*C13*(1-POWER(0.5,6)) -> 0.48923438 | G16: the same as in row above but as formula | H16: 0 | I16: 0 | J16: 0 | K16: 1 | L16: 1 | M16: 1
H17: 0 | I17: 0 | J17: 1 | K17: 0 | L17: 0 | M17: 1 | O17: In this case, stuck-open fault coverage is:
A18: 'Port 1 being an input of NOT (having output to the AND gate) and port 2 being another input of AND: | E18: Case 2: | H18: 0 | I18: 0 | J18: 1 | K18: 0 | L18: 1 | M18: 1 | O18: =11/16 -> 0.6875
A19: '(correct values) --> (result of a "short" fault) | E19: 0.5*0.5=0.25 | F19: =C15*0.5 -> 0.25 | G19: probability of detection a race-condition in combination with an open fault by 1x test pattern | H19: 0 | I19: 0 | J19: 1 | K19: 1 | L19: 0 | M19: 1
A20: '(1,0)-->(1,1) : safe | E20: 1-0.25=0.75 | F20: =1-F19 -> 0.75 | G20: probability of not detection a race-condition in combination with an open fault by 1x test pattern | H20: 0 | I20: 0 | J20: 1 | K20: 1 | L20: 1 | M20: 1 | O20: Coverage of stuck-open faults is not done separately for case 1 and case 2 for making the estimation simpler. On one side, possible race-condition in case 2 may lead to decreased coverage of these faults because some expected value and some time is not set as expected within 0 -> 1 - > 0 transition. On the other side, possible race condition may cause more than currently accounted 11x 0 -> 1 - > 0 transisions leading to higher coverage.
A21: '(1,0)-->(0,0) : safe | E21: POWER(0.75,6) | F21: =POWER(F20,6) -> 0.17797852 | G21: probability of not detection a race-condition in combination with an open fault by 6x test patterns | H21: 0 | I21: 1 | J21: 0 | K21: 0 | L21: 0 | M21: 1
A22: '(0,1)-->(0,0) : dangerous, detection status is determined by a status of stuck-at-1 at input of NOT | E22: 1-POWER(0.75,6) | F22: =1-F21 -> 0.82202148 | G22: probability of detection a race-condition in combination with an open fault by 6x test patterns | H22: 0 | I22: 1 | J22: 0 | K22: 0 | L22: 1 | M22: 1
A23: '(0,1)-->(1,1) : dangerous, detection status is determined by a status of stuck-at-1 at input of NOT | E23: 0.99*0.5*(1-POWER(0.75,6)) | F23: =lookup!D356*C14*F22 -> 0.40854468 | G23: the same as in row above, but taking into account 50% portion of faults in case 2 and 98% of tested instructions | H23: 0 | I23: 1 | J23: 0 | K23: 1 | L23: 0 | M23: 1
H24: 0 | I24: 1 | J24: 0 | K24: 1 | L24: 1 | M24: 1
A25: Scenario 2: | H25: 0 | I25: 1 | J25: 1 | K25: 0 | L25: 0 | M25: 1
A26: "short"-fault ocures between any two wires within the sub-module logic | H26: 0 | I26: 1 | J26: 1 | K26: 0 | L26: 1 | M26: 1
H27: 0 | I27: 1 | J27: 1 | K27: 1 | L27: 0 | M27: 1
A28: 'A "short" fault between given wires is considered as detected, if within the _same_ test pattern | H28: 0 | I28: 1 | J28: 1 | K28: 1 | L28: 1 | M28: 1
A29: 'either stuck-at-0 on wire 1 is detected and stuck-at-1 on wire 2 is detected, or vise-versa.
B35: "short"-fault coverage estimation for "cm4_dpu_e.cm4_dpu_e_dec" sub-module: | E35: Hints to "open" fault coverage estimation for "cm4_dpu_e.cm4_dpu_e_dec" sub-module: | H35: Hints to "stuck-open" fault coverage estimation for "cm4_dpu_e.cm4_dpu_e_dec" sub-module:
B37: Relative number of tested instructions: | C37: 1 | E37: Case 1: | H37: TP1 | I37: TP2 | J37: TP3 | K37: TP4 | L37: TP5 | M37: TP6
B38: Portion of faults leading to case 1 (no race condition): | C38: 0.5 | E38: POWER(0.5,6) | G38: probability of not detection an open fault by 6x test patterns | H38: 0 | I38: 0 | J38: 0 | K38: 0 | L38: 0 | M38: 1 | O38: With 6x test patterns, it is possible to
B39: Portion of faults leading to case 2 (race condition possible): | C39: 0.5 | E39: 1-POWER(0.5,6) | G39: probability of detection an open fault by 6x test patterns | H39: 0 | I39: 0 | J39: 0 | K39: 0 | L39: 1 | M39: 1 | O39: get 11x 0 -> 1 -> 0 transitions out of 16
B40: Probability of fault (race-condition) detection by a single test pattern in case 2: | C40: 0.5 | E40: 0.999*0.5*(1-POWER(0.5,6)) | G40: the same as in row above, but taking into account 50% portion of faults in case 1 and 99% of tested instructions | H40: 0 | I40: 0 | J40: 0 | K40: 1 | L40: 0 | M40: 1 | O40: possible combinations.
E41: =lookup!F98*C38*(1-POWER(0.5,6)) -> 0.49174453 | G41: the same as in row above but as formula | H41: 0 | I41: 0 | J41: 0 | K41: 1 | L41: 1 | M41: 1
H42: 0 | I42: 0 | J42: 1 | K42: 0 | L42: 0 | M42: 1 | O42: In this case, stuck-open fault coverage is:
E43: Case 2: | H43: 0 | I43: 0 | J43: 1 | K43: 0 | L43: 1 | M43: 1 | O43: =11/16 -> 0.6875
E44: 0.5*0.5=0.25 | F44: =C40*0.5 -> 0.25 | G44: probability of detection a race-condition in combination with an open fault by 1x test pattern | H44: 0 | I44: 0 | J44: 1 | K44: 1 | L44: 0 | M44: 1
E45: 1-0.25=0.75 | F45: =1-F44 -> 0.75 | G45: probability of not detection a race-condition in combination with an open fault by 1x test pattern | H45: 0 | I45: 0 | J45: 1 | K45: 1 | L45: 1 | M45: 1
E46: POWER(0.75,6) | F46: =POWER(F45,6) -> 0.17797852 | G46: probability of not detection a race-condition in combination with an open fault by 6x test patterns | H46: 0 | I46: 1 | J46: 0 | K46: 0 | L46: 0 | M46: 1
E47: 1-POWER(0.75,6) | F47: =1-F46 -> 0.82202148 | G47: probability of detection a race-condition in combination with an open fault by 6x test patterns | H47: 0 | I47: 1 | J47: 0 | K47: 0 | L47: 1 | M47: 1
...

Sheet lookup
A1: TP# | B1: Probabilities are sum-up-ed as for indpendent events | D1: Probabilities are sum-up-ed as for mutually-exclusive events | F1: Probabilities are sum-up-ed as for mutually-exclusive events | J1: Probabilities are sum-up-ed as for indpendent events
A2: 1 | B2: 0.05 | C2: =B2*B2 -> 0.0025 | D2: 0.0028 | E2: =D2*0.5+D2*0.5*0.5 -> 0.0021 | F2: 0.0103 | G2: =F2*0.5+F2*0.5*0.5 -> 0.007725 | H2: =1/(18*2) -> 0.027777778 | I2: =H2*H2 -> 0.00077160494 | J2: 0.03 | K2: =J2*J2 -> 0.0009 | L2: =1/20 -> 0.05
A3: 2 | B3: =B2+B$2-B2*B$2 -> 0.0975 | C3: =C2+C$2-C2*C$2 -> 0.00499375 | D3: =D2+D$2 -> 0.0056 | E3: =E2+E$2 -> 0.0042 | F3: =F2+F$2 -> 0.0206 | G3: =G2+G$2 -> 0.01545 | H3: =H2+H$2 -> 0.055555556 | I3: =I2+I$2 -> 0.0015432099 | J3: =J2+J$2-J2*J$2 -> 0.0591 | K3: =K2+K$2-K2*K$2 -> 0.00179919 | L3: =L2+L$2 -> 0.1
A4: 3 | B4: =B3+B$2-B3*B$2 -> 0.142625 | C4: =C3+C$2-C3*C$2 -> 0.0074812656 | D4: =D3+D$2 -> 0.0084 | E4: =E3+E$2 -> 0.0063 | F4: =F3+F$2 -> 0.0309 | G4: =G3+G$2 -> 0.023175 | H4: =H3+H$2 -> 0.083333333 | I4: =I3+I$2 -> 0.0023148148 | J4: =J3+J$2-J3*J$2 -> 0.087327 | K4: =K3+K$2-K3*K$2 -> 0.0026975707 | L4: =L3+L$2 -> 0.15
A5: 4 | B5: =B4+B$2-B4*B$2 -> 0.18549375 | C5: =C4+C$2-C4*C$2 -> 0.0099625625 | D5: =D4+D$2 -> 0.0112 | E5: =E4+E$2 -> 0.0084 | F5: =F4+F$2 -> 0.0412 | G5: =G4+G$2 -> 0.0309 | H5: =H4+H$2 -> 0.11111111 | I5: =I4+I$2 -> 0.0030864198 | J5: =J4+J$2-J4*J$2 -> 0.11470719 | K5: =K4+K$2-K4*K$2 -> 0.0035951429 | L5: =L4+L$2 -> 0.2
A6: 5 | B6: =B5+B$2-B5*B$2 -> 0.22621906 | C6: =C5+C$2-C5*C$2 -> 0.012437656 | D6: =D5+D$2 -> 0.014 | E6: =E5+E$2 -> 0.0105 | F6: =F5+F$2 -> 0.0515 | G6: =G5+G$2 -> 0.038625 | H6: =H5+H$2 -> 0.13888889 | I6: =I5+I$2 -> 0.0038580247 | J6: =J5+J$2-J5*J$2 -> 0.14126597 | K6: =K5+K$2-K5*K$2 -> 0.0044919073 | L6: =L5+L$2 -> 0.25
A7: 6 | B7: =B6+B$2-B6*B$2 -> 0.26490811 | C7: =C6+C$2-C6*C$2 -> 0.014906562 | D7: =D6+D$2 -> 0.0168 | E7: =E6+E$2 -> 0.0126 | F7: =F6+F$2 -> 0.0618 | G7: =G6+G$2 -> 0.04635 | H7: =H6+H$2 -> 0.16666667 | I7: =I6+I$2 -> 0.0046296296 | J7: =J6+J$2-J6*J$2 -> 0.167028 | K7: =K6+K$2-K6*K$2 -> 0.0053878646 | L7: =L6+L$2 -> 0.3
A8: 7 | B8: =B7+B$2-B7*B$2 -> 0.3016627 | C8: =C7+C$2-C7*C$2 -> 0.017369296 | D8: =D7+D$2 -> 0.0196 | E8: =E7+E$2 -> 0.0147 | F8: =F7+F$2 -> 0.0721 | G8: =G7+G$2 -> 0.054075 | H8: =H7+H$2 -> 0.19444444 | I8: =I7+I$2 -> 0.0054012346 | J8: =J7+J$2-J7*J$2 -> 0.19201716 | K8: =K7+K$2-K7*K$2 -> 0.0062830155 | L8: =L7+L$2 -> 0.35
A9: 8 | B9: =B8+B$2-B8*B$2 -> 0.33657957 | C9: =C8+C$2-C8*C$2 -> 0.019825872 | D9: =D8+D$2 -> 0.0224 | E9: =E8+E$2 -> 0.0168 | F9: =F8+F$2 -> 0.0824 | G9: =G8+G$2 -> 0.0618 | H9: =H8+H$2 -> 0.22222222 | I9: =I8+I$2 -> 0.0061728395 | J9: =J8+J$2-J8*J$2 -> 0.21625664 | K9: =K8+K$2-K8*K$2 -> 0.0071773608 | L9: =L8+L$2 -> 0.4
A10: 9 | B10: =B9+B$2-B9*B$2 -> 0.36975059 | C10: =C9+C$2-C9*C$2 -> 0.022276308 | D10: =D9+D$2 -> 0.0252 | E10: =E9+E$2 -> 0.0189 | F10: =F9+F$2 -> 0.0927 | G10: =G9+G$2 -> 0.069525 | H10: =H9+H$2 -> 0.25 | I10: =I9+I$2 -> 0.0069444444 | J10: =J9+J$2-J9*J$2 -> 0.23976894 | K10: =K9+K$2-K9*K$2 -> 0.0080709012 | L10: =L9+L$2 -> 0.45
A11: 10 | B11: =B10+B$2-B10*B$2 -> 0.40126306 | C11: =C10+C$2-C10*C$2 -> 0.024720617 | D11: =D10+D$2 -> 0.028 | E11: =E10+E$2 -> 0.021 | F11: =F10+F$2 -> 0.103 | G11: =G10+G$2 -> 0.07725 | H11: =H10+H$2 -> 0.27777778 | I11: =I10+I$2 -> 0.0077160494 | J11: =J10+J$2-J10*J$2 -> 0.26257587 | K11: =K10+K$2-K10*K$2 -> 0.0089636373 | L11: =L10+L$2 -> 0.5
A12: 11 | B12: =B11+B$2-B11*B$2 -> 0.43119991 | C12: =C11+C$2-C11*C$2 -> 0.027158815 | D12: =D11+D$2 -> 0.0308 | E12: =E11+E$2 -> 0.0231 | F12: =F11+F$2 -> 0.1133 | G12: =G11+G$2 -> 0.084975 | H12: =H11+H$2 -> 0.30555556 | I12: =I11+I$2 -> 0.0084876543 | J12: =J11+J$2-J11*J$2 -> 0.2846986 | K12: =K11+K$2-K11*K$2 -> 0.0098555701 | L12: =L11+L$2 -> 0.55
A13: 12 | B13: =B12+B$2-B12*B$2 -> 0.45963991 | C13: =C12+C$2-C12*C$2 -> 0.029590918 | D13: =D12+D$2 -> 0.0336 | E13: =E12+E$2 -> 0.0252 | F13: =F12+F$2 -> 0.1236 | G13: =G12+G$2 -> 0.0927 | H13: =H12+H$2 -> 0.33333333 | I13: =I12+I$2 -> 0.0092592593 | J13: =J12+J$2-J12*J$2 -> 0.30615764 | K13: =K12+K$2-K12*K$2 -> 0.0107467 | L13: =L12+L$2 -> 0.6
A14: 13 | B14: =B13+B$2-B13*B$2 -> 0.48665792 | C14: =C13+C$2-C13*C$2 -> 0.032016941 | D14: =D13+D$2 -> 0.0364 | E14: =E13+E$2 -> 0.0273 | F14: =F13+F$2 -> 0.1339 | G14: =G13+G$2 -> 0.100425 | H14: =H13+H$2 -> 0.36111111 | I14: =I13+I$2 -> 0.010030864 | J14: =J13+J$2-J13*J$2 -> 0.32697291 | K14: =K13+K$2-K13*K$2 -> 0.011637028 | L14: =L13+L$2 -> 0.65
... A20: 19 | B20: =B19+B$2-B19*B$2 -> 0.6226464 | C20: =C19+C$2-C19*C$2 -> 0.04644624 | D20: =D19+D$2 -> 0.0532 | E20: =E19+E$2 -> 0.0399 | F20: =F19+F$2 -> 0.1957 | G20: =G19+G$2 -> 0.146775 | H20: =H19+H$2 -> 0.52777778 | I20: =I19+I$2 -> 0.014660494 | J20: =J19+J$2-J19*J$2 -> 0.43938728 | K20: =K19+K$2-K19*K$2 -> 0.016962194 | L20: =L19+L$2 -> 0.95
A21: 20 | B21: =B20+B$2-B20*B$2 -> 0.64151408 | C21: =C20+C$2-C20*C$2 -> 0.048830125 | D21: =D20+D$2 -> 0.056 | E21: =E20+E$2 -> 0.042 | F21: =F20+F$2 -> 0.206 | G21: =G20+G$2 -> 0.1545 | H21: =H20+H$2 -> 0.55555556 | I21: =I20+I$2 -> 0.015432099 | J21: =J20+J$2-J20*J$2 -> 0.45620566 | K21: =K20+K$2-K20*K$2 -> 0.017846928
A22: 21 | B22: =B21+B$2-B21*B$2 -> 0.65943837 | C22: =C21+C$2-C21*C$2 -> 0.051208049 | D22: =D21+D$2 -> 0.0588 | E22: =E21+E$2 -> 0.0441 | F22: =F21+F$2 -> 0.2163 | G22: =G21+G$2 -> 0.162225 | H22: =H21+H$2 -> 0.58333333 | I22: =I21+I$2 -> 0.016203704 | J22: =J21+J$2-J21*J$2 -> 0.47251949 | K22: =K21+K$2-K21*K$2 -> 0.018730866
A23: 22 | B23: =B22+B$2-B22*B$2 -> 0.67646646 | C23: =C22+C$2-C22*C$2 -> 0.053580029 | D23: =D22+D$2 -> 0.0616 | E23: =E22+E$2 -> 0.0462 | F23: =F22+F$2 -> 0.2266 | G23: =G22+G$2 -> 0.16995 | H23: =H22+H$2 -> 0.61111111 | I23: =I22+I$2 -> 0.016975309 | J23: =J22+J$2-J22*J$2 -> 0.4883439 | K23: =K22+K$2-K22*K$2 -> 0.019614008
A24: 23 | B24: =B23+B$2-B23*B$2 -> 0.69264313 | C24: =C23+C$2-C23*C$2 -> 0.055946079 | D24: =D23+D$2 -> 0.0644 | E24: =E23+E$2 -> 0.0483 | F24: =F23+F$2 -> 0.2369 | G24: =G23+G$2 -> 0.177675 | H24: =H23+H$2 -> 0.63888889 | I24: =I23+I$2 -> 0.017746914 | J24: =J23+J$2-J23*J$2 -> 0.50369359 | K24: =K23+K$2-K23*K$2 -> 0.020496355
A25: 24 | B25: =B24+B$2-B24*B$2 -> 0.70801098 | C25: =C24+C$2-C24*C$2 -> 0.058306214 | D25: =D24+D$2 -> 0.0672 | E25: =E24+E$2 -> 0.0504 | F25: =F24+F$2 -> 0.2472 | G25: =G24+G$2 -> 0.1854 | H25: =H24+H$2 -> 0.66666667 | I25: =I24+I$2 -> 0.018518519 | J25: =J24+J$2-J24*J$2 -> 0.51858278 | K25: =K24+K$2-K24*K$2 -> 0.021377909
A26: 25 | B26: =B25+B$2-B25*B$2 -> 0.72261043 | C26: =C25+C$2-C25*C$2 -> 0.060660449 | D26: =D25+D$2 -> 0.07 | E26: =E25+E$2 -> 0.0525 | F26: =F25+F$2 -> 0.2575 | G26: =G25+G$2 -> 0.193125 | H26: =H25+H$2 -> 0.69444444 | I26: =I25+I$2 -> 0.019290123 | J26: =J25+J$2-J25*J$2 -> 0.53302529 | K26: =K25+K$2-K25*K$2 -> 0.022258668
A27: 26 | B27: =B26+B$2-B26*B$2 -> 0.73647991 | C27: =C26+C$2-C26*C$2 -> 0.063008797 | D27: =D26+D$2 -> 0.0728 | E27: =E26+E$2 -> 0.0546 | F27: =F26+F$2 -> 0.2678 | G27: =G26+G$2 -> 0.20085 | H27: =H26+H$2 -> 0.72222222 | I27: =I26+I$2 -> 0.020061728 | J27: =J26+J$2-J26*J$2 -> 0.54703454 | K27: =K26+K$2-K26*K$2 -> 0.023138636
A28: 27 | B28: =B27+B$2-B27*B$2 -> 0.74965591 | C28: =C27+C$2-C27*C$2 -> 0.065351275 | D28: =D27+D$2 -> 0.0756 | E28: =E27+E$2 -> 0.0567 | F28: =F27+F$2 -> 0.2781 | G28: =G27+G$2 -> 0.208575 | H28: =H27+H$2 -> 0.75 | I28: =I27+I$2 -> 0.020833333 | J28: =J27+J$2-J27*J$2 -> 0.5606235 | K28: =K27+K$2-K27*K$2 -> 0.024017811
A29: 28 | B29: =B28+B$2-B28*B$2 -> 0.76217311 | C29: =C28+C$2-C28*C$2 -> 0.067687897 | D29: =D28+D$2 -> 0.0784 | E29: =E28+E$2 -> 0.0588 | F29: =F28+F$2 -> 0.2884 | G29: =G28+G$2 -> 0.2163 | H29: =H28+H$2 -> 0.77777778 | I29: =I28+I$2 -> 0.021604938 | J29: =J28+J$2-J28*J$2 -> 0.57380479 | K29: =K28+K$2-K28*K$2 -> 0.024896195
A30: 29 | B30: =B29+B$2-B29*B$2 -> 0.77406446 | C30: =C29+C$2-C29*C$2 -> 0.070018677 | D30: =D29+D$2 -> 0.0812 | E30: =E29+E$2 -> 0.0609 | F30: =F29+F$2 -> 0.2987 | G30: =G29+G$2 -> 0.224025 | H30: =H29+H$2 -> 0.80555556 | I30: =I29+I$2 -> 0.022376543 | J30: =J29+J$2-J29*J$2 -> 0.58659065 | K30: =K29+K$2-K29*K$2 -> 0.025773788
A31: 30 | B31: =B30+B$2-B30*B$2 -> 0.78536124 | C31: =C30+C$2-C30*C$2 -> 0.072343631 | D31: =D30+D$2 -> 0.084 | E31: =E30+E$2 -> 0.063 | F31: =F30+F$2 -> 0.309 | G31: =G30+G$2 -> 0.23175 | H31: =H30+H$2 -> 0.83333333 | I31: =I30+I$2 -> 0.023148148 | J31: =J30+J$2-J30*J$2 -> 0.59899293 | K31: =K30+K$2-K30*K$2 -> 0.026650592
A32: 31 | B32: =B31+B$2-B31*B$2 -> 0.79609317 | C32: =C31+C$2-C31*C$2 -> 0.074662772 | D32: =D31+D$2 -> 0.0868 | E32: =E31+E$2 -> 0.0651 | F32: =F31+F$2 -> 0.3193 | G32: =G31+G$2 -> 0.239475 | H32: =H31+H$2 -> 0.86111111 | I32: =I31+I$2 -> 0.023919753 | J32: =J31+J$2-J31*J$2 -> 0.61102314 | K32: =K31+K$2-K31*K$2 -> 0.027526606
... A37: 36 | B37: =B36+B$2-B36*B$2 -> 0.84222079 | C37: =C36+C$2-C36*C$2 -> 0.086171798 | D37: =D36+D$2 -> 0.1008 | E37: =E36+E$2 -> 0.0756 | F37: =F36+F$2 -> 0.3708 | G37: =G36+G$2 -> 0.2781 | H37: =H36+H$2 -> 1 | I37: =I36+I$2 -> 0.027777778 | J37: =J36+J$2-J36*J$2 -> 0.66597234 | K37: =K36+K$2-K36*K$2 -> 0.031894867
A38: 37 | B38: =B37+B$2-B37*B$2 -> 0.85010975 | C38: =C37+C$2-C37*C$2 -> 0.088456368 | D38: =D37+D$2 -> 0.1036 | E38: =E37+E$2 -> 0.0777 | F38: =F37+F$2 -> 0.3811 | G38: =G37+G$2 -> 0.285825 | I38: =I37+I$2 -> 0.028549383 | J38: =J37+J$2-J37*J$2 -> 0.67599317 | K38: =K37+K$2-K37*K$2 -> 0.032766161
A39: 38 | B39: =B38+B$2-B38*B$2 -> 0.85760426 | C39: =C38+C$2-C38*C$2 -> 0.090735227 | D39: =D38+D$2 -> 0.1064 | E39: =E38+E$2 -> 0.0798 | F39: =F38+F$2 -> 0.3914 | G39: =G38+G$2 -> 0.29355 | I39: =I38+I$2 -> 0.029320988 | J39: =J38+J$2-J38*J$2 -> 0.68571337 | K39: =K38+K$2-K38*K$2 -> 0.033636672
A40: 39 | B40: =B39+B$2-B39*B$2 -> 0.86472405 | C40: =C39+C$2-C39*C$2 -> 0.093008389 | D40: =D39+D$2 -> 0.1092 | E40: =E39+E$2 -> 0.0819 | F40: =F39+F$2 -> 0.4017 | G40: =G39+G$2 -> 0.301275 | I40: =I39+I$2 -> 0.030092593 | J40: =J39+J$2-J39*J$2 -> 0.69514197 | K40: =K39+K$2-K39*K$2 -> 0.034506399
A41: 40 | B41: =B40+B$2-B40*B$2 -> 0.87148784 | C41: =C40+C$2-C40*C$2 -> 0.095275868 | D41: =D40+D$2 -> 0.112 | E41: =E40+E$2 -> 0.084 | F41: =F40+F$2 -> 0.412 | G41: =G40+G$2 -> 0.309 | I41: =I40+I$2 -> 0.030864198 | J41: =J40+J$2-J40*J$2 -> 0.70428771 | K41: =K40+K$2-K40*K$2 -> 0.035375343
A42: 41 | B42: =B41+B$2-B41*B$2 -> 0.87791345 | C42: =C41+C$2-C41*C$2 -> 0.097537679 | D42: =D41+D$2 -> 0.1148 | E42: =E41+E$2 -> 0.0861 | F42: =F41+F$2 -> 0.4223 | G42: =G41+G$2 -> 0.316725 | I42: =I41+I$2 -> 0.031635802 | J42: =J41+J$2-J41*J$2 -> 0.71315908 | K42: =K41+K$2-K41*K$2 -> 0.036243505
A43: 42 | B43: =B42+B$2-B42*B$2 -> 0.88401778 | C43: =C42+C$2-C42*C$2 -> 0.099793835 | D43: =D42+D$2 -> 0.1176 | E43: =E42+E$2 -> 0.0882 | F43: =F42+F$2 -> 0.4326 | G43: =G42+G$2 -> 0.32445 | I43: =I42+I$2 -> 0.032407407 | J43: =J42+J$2-J42*J$2 -> 0.72176431 | K43: =K42+K$2-K42*K$2 -> 0.037110886
A44: 43 | B44: =B43+B$2-B43*B$2 -> 0.88981689 | C44: =C43+C$2-C43*C$2 -> 0.10204435 | D44: =D43+D$2 -> 0.1204 | E44: =E43+E$2 -> 0.0903 | F44: =F43+F$2 -> 0.4429 | G44: =G43+G$2 -> 0.332175 | I44: =I43+I$2 -> 0.033179012 | J44: =J43+J$2-J43*J$2 -> 0.73011138 | K44: =K43+K$2-K43*K$2 -> 0.037977486
A45: 44 | B45: =B44+B$2-B44*B$2 -> 0.89532605 | C45: =C44+C$2-C44*C$2 -> 0.10428924 | D45: =D44+D$2 -> 0.1232 | E45: =E44+E$2 -> 0.0924 | F45: =F44+F$2 -> 0.4532 | G45: =G44+G$2 -> 0.3399 | I45: =I44+I$2 -> 0.033950617 | J45: =J44+J$2-J44*J$2 -> 0.73820804 | K45: =K44+K$2-K44*K$2 -> 0.038843306
A46: 45 | B46: =B45+B$2-B45*B$2 -> 0.90055974 | C46: =C45+C$2-C45*C$2 -> 0.10652852 | D46: =D45+D$2 -> 0.126 | E46: =E45+E$2 -> 0.0945 | F46: =F45+F$2 -> 0.4635 | G46: =G45+G$2 -> 0.347625 | I46: =I45+I$2 -> 0.034722222 | J46: =J45+J$2-J45*J$2 -> 0.7460618 | K46: =K45+K$2-K45*K$2 -> 0.039708347
A47: 46 | B47: =B46+B$2-B46*B$2 -> 0.90553176 | C47: =C46+C$2-C46*C$2 -> 0.10876219 | D47: =D46+D$2 -> 0.1288 | E47: =E46+E$2 -> 0.0966 | F47: =F46+F$2 -> 0.4738 | G47: =G46+G$2 -> 0.35535 | I47: =I46+I$2 -> 0.035493827 | J47: =J46+J$2-J46*J$2 -> 0.75367994 | K47: =K46+K$2-K46*K$2 -> 0.04057261
A48: 47 | B48: =B47+B$2-B47*B$2 -> 0.91025517 | C48: =C47+C$2-C47*C$2 -> 0.11099029 | D48: =D47+D$2 -> 0.1316 | E48: =E47+E$2 -> 0.0987 | F48: =F47+F$2 -> 0.4841 | G48: =G47+G$2 -> 0.363075 | I48: =I47+I$2 -> 0.036265432 | J48: =J47+J$2-J47*J$2 -> 0.76106954 | K48: =K47+K$2-K47*K$2 -> 0.041436095
A49: 48 | B49: =B48+B$2-B48*B$2 -> 0.91474241 | C49: =C48+C$2-C48*C$2 -> 0.11321281 | D49: =D48+D$2 -> 0.1344 | E49: =E48+E$2 -> 0.1008 | F49: =F48+F$2 -> 0.4944 | G49: =G48+G$2 -> 0.3708 | I49: =I48+I$2 -> 0.037037037 | J49: =J48+J$2-J48*J$2 -> 0.76823746 | K49: =K48+K$2-K48*K$2 -> 0.042298802
...

Sheet NVIC_DPU
A1: Output ports of NVIC connected to corresponding input ports of DPU (column B) | B1: Input ports of DPU connected to the corresponding output ports of NVIC (column A) | C1: Core sub-module the port signal propagated to | D1: Covered by test | F1: Input ports of NVIC that are connected to corresponding output ports of DPU module | G1: Core sub-module the port propagated from | H1: Covered by test
A2: output nvic_data_be8_o; // Endian BE8 | B2: input nvic_data_be8_i; | C2: cm4_dpu_fetch cm4_fpu cm4_dpu_lsu | D2: m4_scst_exception_test_svc | F2: input dpu_rst_pc_valid_i; // DPU has been reset | G2: cm4_dpu_exec | H2: N/A
A3: output [3:0] nvic_cpacr_o; // CPACR | B3: input [3:0] nvic_cpacr_i; | C3: cm4_fpu | D3: TBD | F3: input dpu_ahb_htransi_iss_i; // In data phase of I-AHB trans | G3: cm4_dpu_fetch | H3: Non testable
A4: output nvic_bfhfnmign_o; // Bus fault ignored in NMI/HF | B4: input nvic_bfhfnmign_i; | C4: cm4_dpu_exec cm5_dpu_lsu cm4_fpu | D4: m4_scst_exception_test_nmihf | F4: input [31:0] dpu_ahb_haddrd_i; // Data address | G4: cm4_dpu_lsu | H4: m4_scst_exception_test_bus_fault, m4_scst_exception_test_hard_fault
A5: output nvic_int_stk_algn_o; // Align stack to double word boundary | B5: input nvic_int_stk_algn_i; | C5: cm4_dpu_lsu | D5: m4_scst_exception_test_nmihf | F5: input dpu_ahb_haddrd_valid_i; // D addr valid to sample for FAR | G5: cm4_dpu_lsu | H5: m4_scst_exception_test_bus_fault, m4_scst_exception_test_hard_fault
A6: output nvic_div_0_trp_o; // Divide by zero fault enabled | B6: input nvic_div_0_trp_i; | C6: cm4_dpu_alu | D6: m4_scst_exception_usage_fault, m4_scst_exception_test_hard_fault | F6: input dpu_privileged_i; // DPU in privileged mode | G6: cm4_dpu_exec | H6: TBD
A7: output nvic_unalign_trp_o; // Unaligned fault enable | B7: input nvic_unalign_trp_i; | C7: cm4_dpu_lsu | D7: m4_scst_exception_usage_fault, m4_scst_exception_test_hard_fault | F7: input dpu_thread_i; // DPU in thread | G7: cm4_dpu_exec | H7: TBD
A8: output nvic_nonbasethrden_o; // Handler can be thread | B8: input nvic_nonbasethrden_i; | C8: cm4_dpu_exec | D8: m4_scst_exception_test_handler_thread | F8: input dpu_ivalid_i; // Decode enable | G8: cm4_dpu_dec | H8: Non testable
A9: output nvic_disfold_o; // Disable IT folding | B9: input nvic_disfold_i; | C9: cm4_dpu_dec | D9: Non testable | F9: input dpu_retire_i; // Opcode retire | G9: cm4_dpu_exec | H9: Non testable
A10: output nvic_dismcycint_o; // Disable int of multi-cycle ops | B10: input nvic_dismcycint_i; | C10: cm4_dpu_exec | D10: Non testable | F10: input [1:0] dpu_fpccr_we_i; // LSPACT write enable | G10: cm4_fpu | H10: TBD
A11: output nvic_no_lazy_stk_o; // Disable lazy stacking | B11: input nvic_no_lazy_stk_i; | C11: cm4_dpu_exec | D11: TBD | F11: input [31:0] dpu_fpcar_nxt_i; // FPCAR write value | G11: cm4_dpu_lsu | H11: TBD
A12: output nvic_no_ooo_o; // Disable out-of-order | B12: input nvic_no_ooo_i; | C12: cm4_fpu | D12: TBD | F12: input dpu_lazy_stk_i; // Lazy stack in progress | G12: cm4_fpu | H12: TBD
... A36: output [4:0] nvic_fpdscr_o; // FPDSCR register | B36: input [4:0] nvic_fpdscr_i; | C36: cm4_fpu | D36: TBD | F36: input dpu_dbg_wr_isr_i; // Debug over-ride of ISR number | G36: cm4_dpu_lsu | H36: N/A
C38: LSU - covered by tests | D38: =COUNTIFS(D2:D36,"m4_scst_*",C2:C36,"*cm4_dpu_lsu*") -> 9 | G38: LSU - covered by tests | H38: =COUNTIFS(H2:H36,"m4_scst_*",G2:G36,"*cm4_dpu_lsu*") -> 6
A39: Non-testable (safety-irrelevant) | C39: LSU - all | D39: =COUNTIF(C2:C36,"*cm4_dpu_lsu*")-COUNTIFS(C2:C36,"*cm4_dpu_lsu*",D2:D36,"*N/A*")-COUNTIFS(C2:C36,"*cm4_dpu_lsu*",D2:D36,"*TBD*") -> 9 | G39: LSU - all | H39: =COUNTIF(G2:G36,"*cm4_dpu_lsu*")-COUNTIFS(G2:G36,"*cm4_dpu_lsu*",H2:H36,"*N/A*")-COUNTIFS(G2:G36,"*cm4_dpu_lsu*",H2:H36,"*TBD*") -> 7
A40: Non-testable (safety-relevant) | C40: Fetch - covered by tests | D40: =COUNTIFS(D2:D36,"m4_scst_*",C2:C36,"*cm4_dpu_fetch*") -> 4 | G40: Fetch - covered by tests | H40: =COUNTIFS(H2:H36,"m4_scst_*",G2:G36,"*cm4_dpu_fetch*") -> 0
A41: Testable - in progress of development | C41: Fetch - all | D41: =COUNTIF(C2:C36,"*cm4_dpu_fetch*")-COUNTIFS(C2:C36,"*cm4_dpu_fetch*",D2:D36,"*N/A*")-COUNTIFS(C2:C36,"*cm4_dpu_fetch*",D2:D36,"*TBD*") -> 6 | G41: Fetch - all | H41: =COUNTIF(G2:G36,"*cm4_dpu_fetch*")-COUNTIFS(G2:G36,"*cm4_dpu_fetch*",H2:H36,"*N/A*")-COUNTIFS(G2:G36,"*cm4_dpu_fetch*",H2:H36,"*TBD*") -> 1
A42: Covered | C42: Exec - covered by tests | D42: =COUNTIFS(D2:D36,"m4_scst_*",C2:C36,"*cm4_dpu_exec*") -> 8 | G42: Exec - covered by tests | H42: =COUNTIFS(H2:H36,"m4_scst_*",G2:G36,"*cm4_dpu_exec*") -> 11
A43: FPU related (postponed) | C43: Exec - all | D43: =COUNTIF(C2:C36,"*cm4_dpu_exec*")-COUNTIFS(C2:C36,"*cm4_dpu_exec*",D2:D36,"*N/A*")-COUNTIFS(C2:C36,"*cm4_dpu_exec*",D2:D36,"*TBD*") -> 9 | G43: Exec - all | H43: =COUNTIF(G2:G36,"*cm4_dpu_exec*")-COUNTIFS(G2:G36,"*cm4_dpu_exec*",H2:H36,"*N/A*")-COUNTIFS(G2:G36,"*cm4_dpu_exec*",H2:H36,"*TBD*") -> 14
C44: Status - covered by tests | D44: =COUNTIFS(D2:D36,"m4_scst_*",C2:C36,"*cm4_dpu_status*") -> 1 | G44: Status - covered by tests | H44: =COUNTIFS(H2:H36,"m4_scst_*",G2:G36,"*cm4_dpu_status*") -> 0
C45: Status - all | D45: =COUNTIF(C2:C36,"*cm4_dpu_status*")-COUNTIFS(C2:C36,"*cm4_dpu_status*",D2:D36,"*N/A*")-COUNTIFS(C2:C36,"*cm4_dpu_status*",D2:D36,"*TBD*") -> 1 | G45: Status - all | H45: =COUNTIF(G2:G36,"*cm4_dpu_status*")-COUNTIFS(G2:G36,"*cm4_dpu_status*",H2:H36,"*N/A*")-COUNTIFS(G2:G36,"*cm4_dpu_status*",H2:H36,"*TBD*") -> 0
A48: NVIC_DPU - LSU coverage: | B48: =(D38+H38)/(D39+H39) -> 0.9375
A49: NVIC_DPU - Fetch coverage: | B49: =(D40+H40)/(D41+H41) -> 0.57142857
A50: NVIC_DPU - Exec coverage: | B50: =(D42+H42)/(D43+H43) -> 0.82608696
A51: NVIC_DPU - Status coverage: | B51: =(D44+H44)/(D45+H45) -> 1

Sheet INSTR_SET
A1: 16-bit decoder | B1: 32-bit decoder | C1: br decoder | D1: E instruction decoder | E1: simdsat signals
A2: // --------------------------------------------------------------------------- | B2: // --------------------------------------------------------------------------- | C2: wire i16_b1_de; // 16 bit B (1) | D2: // SIMD instruction formats
A3: // Signal declarations | B3: // Signal declarations | C3: wire i16_b2_de; // 16 bit B (2) | D3: wire i32_fmt3_de; // SIMD format 3 | E3: wire true_simd_valid_ex; // Multiple data operation
A4: // --------------------------------------------------------------------------- | B4: // --------------------------------------------------------------------------- | C4: wire i16_mov3_de; // 16 bit MOV | D4: wire i32_xsat16_de; // SIMD format 3 SAT | E4: wire [31:0] simd_op_a_ex; // SIMD unit operand A
A5: wire opt_ext_en; // Logic removal for extensions | B5: wire opt_ext_en; // Optimisation of extensions | C5: wire i32_bl_de; // 32 bit BL | D5: wire i32_fmt_t0_de; // SIMD format T0 | E5: wire [31:0] simd_op_b_ex; // SIMD unit operand B
A6: wire i16_adc_de; // ADC | B6: wire i32_spec_de; // Special case | C6: wire i32_b0_de; // 32 bit B (0) | D6: wire i32_fmt_t2_de; // SIMD format T2 | E6: wire normal_op_b_ex; // Select unmodified operand B
A7: wire i16_add1_de; // ADD (1) | B7: wire i32_sp_wr_de; // SP write | C7: wire instr_br_de_valid_de; // Branch decode enable | D7: wire i32_fmt_t2_0_de; // SIMD format 2, part 0 | E7: wire sign_op_b_ex; // Sign bit of operand B
A8: wire i16_add2_de; // ADD (2) | B8: wire i32_pc_wr_de; // PC write | C8: wire instr_de_br_b0_de; // Accepted B (0) | D8: wire i32_fmt_t2_1_de; // SIMD format 2, part 1 | E8: wire [31:0] data_b_op_ex; // B data before possible inversion
A9: wire i16_add3_de; // ADD (3) | B9: wire i32_pc_op_de; // Op1 = 0xF | C9: wire instr_de_br_b1_de; // Accepted B (1) | D9: wire i32_fmt_t2_1_0_de; // SIMD format 2, part 1.0 | E9: wire [31:0] fmt_data_a_ex; // Formatted A data
A10: wire i16_add4_de; // ADD (4) | B10: wire i32_fmt_0_de; // Format 0 | C10: wire instr_de_br_blx_de; // Accepted BLX | D10: wire i32_fmt_t2_1_1_de; // SIMD format 2, part 1.1 | E10: wire [31:0] fmt_data_b_ex; // Formatted B data
A11: wire i16_addpc_de; // ADD PC | B11: wire i32_adc1_de; // ADC (1) | C11: wire instr_de_br_mov_de; // Accepted MOV | D11: wire i32_fmt_t2_1_2_de; // SIMD format 2, part 1.2 | E11: wire [3:0] sign_data_a_ex; // Sign bits extracted from A data
A12: wire i16_add5_de; // ADD (5) | B12: wire i32_add1_de; // ADD (1) | C12: wire instr_de_br_de; // Decode time branch | D12: wire i32_fmt_t2_2_de; // SIMD format 2, part 2 | E12: wire [3:0] sign_data_b_ex; // Sign bits extracted from B data
A13: wire i16_add6_de; // ADD (6) | B13: wire i32_and1_de; // AND (1) | C13: wire instr_de_br_det_de; // Branch detected | D13: wire i32_fmt_t2_2_0_de; // SIMD format 2, part 2.0 | E13: wire data_size16_ex; // 1 = 16 bits, 0 = 8 bits
A14: wire i16_add7_de; // ADD (7) | B14: wire i32_bic1_de; // BIC (1) | C14: wire [3:0] instr_br_cond_de; // Branch condition code | D14: wire i32_fmt_t2_2_1_de; // SIMD format 2, part 2.1 | E14: wire signed_arith_ex; // Signed arithmetic operation
... A17: wire i16_asr2_de; // ASR (2) | B17: wire i32_eor1_de; // EOR (1) | C17: wire instr_det_erly_br_trk_we; // Track B write enable | D17: wire i32_fmt_t4_0_de; // SIMD format 4, part 0 | E17: wire invert_b_high_ex; // Invert upper half of B port data
A18: wire i16_b1_de; // B (1) | B18: wire i32_mov1_de; // MOV (1) | C18: wire instr_det_erly_br_trk_clr; // Track B write clear | E18: wire invert_b_low_ex; // Invert lower half of B port data
A19: wire i16_b2_de; // B (2) | B19: wire i32_mvn1_de; // MVN (1) | C19: reg instr_det_erly_br_trk; // Early branch detected | D19: // SIMD instructions | E19: wire addsub_op_ex; // ADDSUB, 0 = SUB/ADD, 1 = ADD/SUB
